Workbook

Sheet Sheet1
A1: Company Name: | D1: ㈜사이냅소프트
A2: Update: | D2: 46154
J5: 계정과목 등의 금액을 결정하는데 필요한 판단의 정도 | K5: 부정 발생의 가능성 | L5: 회계 처리의 복잡성 | M5: 계정과목 등을 구성하는 거래의 성격 또는 규모의 변화 정도 | N5: 기술적, 경제적 발전과 같은 환경적 변화에 대한 민감도 | T5: 승인 | U5: 검증 | V5: 물리적통제 | W5: 기준정보관리통제 | X5: 대사 | Y5: 감독통제 | Z5: 예방(P) VS 적발(D) | AA5: Automated VS Manual | AB5: 실재성 | AC5: 완전성 | AD5: 권리와의무 | AE5: 평가 | AF5: 재무제표표시와 공시 | AG5: 발생사실 | AH5: 측정 | AJ5: O : 수시, D : 일, W : 주, M : 월, Q : 분기, A : 년 | AN5: 통제의 복잡성 | AO5: 경영진의 통제무시위험 | AP5: 통제를 수행하기 위하여 필요한 판단의 정도 | AQ5: 통제를 수행하거나 통제 운영을 모니터링하는 인원의 역량 | AR5: 통제를 수행하거나 통제운영의 적정성을 모니터링하는 주요 인원의 변동 여부 | AS5: 통제가 예방 또는 적발하고자 하는 왜곡표시의 성격과 중요성 | AT5: 통제가 다른 통제활동의 효과성에 의존하는 정도 | AU5: 과거연도 통제 운영의 효과성 평가결과 | AY5: 질문(Inquiry) | AZ5: 관찰(Observation) | BA5: 문서검사(Examination) | BB5: 재수행(Reperformance) | BD5: 평가주기(O/D/W/M/Q/A) | BP5: 상시모니터링 | BQ5: 독립적인 평가 | BR5: 통제운영자 | BS5: 동일부서의 다른인원 | BT5: 다른 부서 | BU5: 내부 통제 부서(전담조직) | BV5: 외부인원
A6: 샘플수 | B6: 프로세스번호 | C6: 프로세스이름 | D6: 하위프로세스번호 | E6: 하위프로세스이름 | F6: 위험번호 | G6: 통제활동번호 | H6: 담당자 | I6: 위험내용 | J6: Risk Assessment(모범규준) | O6: 위험평가 | P6: 통제목적 | Q6: 통제활동이름 | R6: 통제활동설명 | S6: Key Control | T6: Control Type | Z6: 통제유형 | AB6: 경영자주장 | AI6: 관련 계정과목 및 주석사항 | AJ6: 통제주기 | AK6: IPE(IUC) 식별 | AL6: 관련 시스템 | AM6: EUC 식별 | AN6: RAWC (Risk Associated With Control) | AV6: RAWC | AW6: 통제현황(WTT의 summary 수준) | AX6: 통제현황(기존프로세스) | AY6: 테스트절차 | BG6: Control Owner | BH6: 설계평가 | BP6: 평가방법(모범규준 60) | BR6: 통제수행자(모범규준 60) | BW6: 개선업무
AY7: 테스트방법 | BC7: 모집단 | BD7: 평가주기 | BE7: 표본수 | BF7: 테스트절차 | BH7: 통제활동이 정책과 연계되었는가 | BI7: 관련 통제위험을 명확하게 감소시킬 수 있을 정도로 정교한지 | BJ7: 예외사항의 정의와 적시 대응 방안이 포함되는지 | BK7: 통제를 수행하는데 사용된 정보의 신뢰성 확보 방안이 적절한지 | BL7: 통제가 설계되어 수행된 기간은 충분한지 | BM7: 통제 수행자의 적격성이 정의되었는지 | BN7: 통제 수행 빈도는 위험을 적시에 예방하거나 적발할 수 있는지 | BO7: 유의한 계정과목의 중요한 왜곡표시 원천이 완전하게 고려되었는지 | BW7: 개선업무명 | BX7: 설명 | BY7: 개선계획
A8: 1 | B8: EL | C8: 전사 | D8: EL-010 | E8: 통제환경 | F8: EL-010-10 | G8: EL-010-10-10 | H8: 유헌종 | I8: 이사회 및 경영진이 추구하는 윤리경영에 대한 준수사항이 정책화 되어 있지 않아 모든 임직원을 포함하여 외부 이해관계자에 의해 준수되지 못할 위험. | J8: Low | K8: Low | L8: Low | M8: Low | N8: Low | O8: LR | P8: 이사회 및 경영진이 추구하는 윤리경영에 대한 준수사항이 정책화 되어 있어 모든 임직원을 포함하여 외부 이해관계자에 의해 준수된다. | Q8: 윤리경영의 정책 수립 | R8: 이사회 및 경영진이 추구하는 윤리경영에 대한 준수사항은 회사의 규정 및 정책에 명문화 되어 있다. | S8: Yes | Y8: O | Z8: P | AA8: M | AB8: O | AC8: O | AD8: O | AE8: O | AF8: O | AG8: O | AH8: O | AI8: N/A | AJ8: A | AK8: N/A | AL8: N/A | AM8: N/A | AN8: L | AO8: L | AP8: L | AQ8: L | AR8: L | AS8: L | AT8: L | AU8: L | AV8: Not Higher | AW8: 1. 윤리헌장을 제정하여 홈페이지에 게시하고 있다. 2. 윤리헌장의 내용은 다음과 같다. - 우리는 인공지능, 디지털 문서, SaaS 소프트웨어를 선도하는 사이냅소프트의 일원으로서 긍지와 자부심을 가지고 높은 윤리적 가치관을 바탕으로 정직하고 공정한 자세로 업무를 처리한다. - 우리는 일체의 부정청탁 및 금품 등의 수수를 배격하고, 정직하고 공정한 자세로 업무를 처리하며 깨끗한 기업윤리를 준수한다. - 우리는 고객에게 최고 품질의 소프트웨어를 제공하여 고객만족 경영을 실천한다. - 우리는 국내외 제반 법규를 준수하고 자유경쟁의 시장 질서를 존중하며 모든 이해관계자와 공동의 발전을 추구한다. - 우리는 지역사회의 일부분으로서 공헌활동에 적극적으로 참여하고 끊임없이 새로운 가치를 창조하여 국가와 사회의 발전에 기여한다. - 우리는 임직원 개개인의 인격을 존중하고 차별 대우를 하지 않으며 공평한 기회와 공정한 평가를 받도록 하는 한편 임직원의 건강과 삶의 질 향상을 위해 노력한다. - 우리는 생명을 존중하고 환경경영에 힘써서 깨끗한 자연환경과 생활환경을 만드는데 노력한다. | AX8: 1. 윤리헌장을 제정하여 홈페이지에 게시하고 있다. 2. 윤리헌장의 내용은 다음과 같다. - 우리는 인공지능, 디지털 문서, SaaS 소프트웨어를 선도하는 사이냅소프트의 일원으로서 긍지와 자부심을 가지고 높은 윤리적 가치관을 바탕으로 정직하고 공정한 자세로 업무를 처리한다. - 우리는 일체의 부정청탁 및 금품 등의 수수를 배격하고, 정직하고 공정한 자세로 업무를 처리하며 깨끗한 기업윤리를 준수한다. - 우리는 고객에게 최고 품질의 소프트웨어를 제공하여 고객만족 경영을 실천한다. - 우리는 국내외 제반 법규를 준수하고 자유경쟁의 시장 질서를 존중하며 모든 이해관계자와 공동의 발전을 추구한다. - 우리는 지역사회의 일부분으로서 공헌활동에 적극적으로 참여하고 끊임없이 새로운 가치를 창조하여 국가와 사회의 발전에 기여한다. - 우리는 임직원 개개인의 인격을 존중하고 차별 대우를 하지 않으며 공평한 기회와 공정한 평가를 받도록 하는 한편 임직원의 건강과 삶의 질 향상을 위해 노력한다. - 우리는 생명을 존중하고 환경경영에 힘써서 깨끗한 자연환경과 생활환경을 만드는데 노력한다. | BA8: O | BC8: 윤리헌장 | BD8: A | BE8: 1 | BF8: 【문서검사】 1. 다음 항목들이 포함된 '윤리헌장'이 문서화되어 있는지 확인하고, 임직원 및 외부관계자들에게 홈페이지를 통해 공유되는지 확인한다. - 우리는 인공지능, 디지털 문서, SaaS 소프트웨어를 선도하는 사이냅소프트의 일원으로서 긍지와 자부심을 가지고 높은 윤리적 가치관을 바탕으로 정직하고 공정한 자세로 업무를 처리한다. - 우리는 일체의 부정청탁 및 금품 등의 수수를 배격하고, 정직하고 공정한 자세로 업무를 처리하며 깨끗한 기업윤리를 준수한다. - 우리는 고객에게 최고 품질의 소프트웨어를 제공하여 고객만족 경영을 실천한다. - 우리는 국내외 제반 법규를 준수하고 자유경쟁의 시장 질서를 존중하며 모든 이해관계자와 공동의 발전을 추구한다. - 우리는 지역사회의 일부분으로서 공헌활동에 적극적으로 참여하고 끊임없이 새로운 가치를 창조하여 국가와 사회의 발전에 기여한다. - 우리는 임직원 개개인의 인격을 존중하고 차별 대우를 하지 않으며 공평한 기회와 공정한 평가를 받도록 하는 한편 임직원의 건강과 삶의 질 향상을 위해 노력한다. - 우리는 생명을 존중하고 환경경영에 힘써서 깨끗한 자연환경과 생활환경을 만드는데 노력한다. | BG8: 경영지원팀 전결권자 | BH8: RCM상 '관련 정책 및 문서'를 확인한 결과 통제활동은 해당 정책과 연계되어 있음을 확인함. | BI8: RCM상 기재된 관련 통제위험을 감소시킬수 있도록 통제가 효과적으로 설계 되었음 | BJ8: 예외사항은 해당 통제의 수행시 오류가 발생할 경우로 정의하며, 추가절차를 위해 별도로 설정한 threshold는 없으며, 예외사항 발생시 즉시 추가적인 절차를 취하도록 설계됨. | BK8: 통제를 수행하는데 사용된 정보에 대한 컨트롤이 적절히 수행되고 있음. | BL8: 해당 사업연도 초에 통제가 설계되었으며, 설계이후 해당 통제의 수행기간은 충분하다고 판단됨. | BM8: 업무경험과 교육이수 등을 고려할 때 통제 수행자의 적격성은 충분함 | BN8: 본 통제활동에서 다루는 윤리경영의 정책 수립는 거래의 연간 발생 빈도 및 중요도를 고려하여 주기를 A로 설정하였으며 통제 수행빈도는 해당 위험의 적시 예방 적발을 위해 적절하다고 판단됨. | BO8: 해당 통제와 관련한 중요한 위험인 [이사회 및 경영진이 추구하는 윤리경영에 대한 준수사항이 정책화 되어 있지 않아 모든 임직원을 포함하여 외부 이해관계자에 의해 준수되지 못할 위험. ]에 대해 완전히 고려되고 있음. | BQ8: O | BS8: O
A9: 1 | B9: EL | C9: 전사 | D9: EL-010 | E9: 통제환경 | F9: EL-010-20 | G9: EL-010-20-10 | H9: 유헌종 | I9: 이사회 및 경영진이 추구하는 도덕성 및 윤리적 가치가 모든 임직원을 포함하여 외부 이해관계자에게 전달되지 못할 위험. | J9: Low | K9: Low | L9: Low | M9: Low | N9: Low | O9: LR | P9: 이사회 및 경영진이 추구하는 도덕성 및 윤리적 가치가 모든 임직원을 포함하여 외부 이해관계자에게 전달된다. | Q9: 윤리경영에 대한 이사회와 경영진 의지 강조 | R9: 이사회 및 경영진은 도덕성과 윤리적 가치를 다양한 형태로 모든 임직원을 포함한 외부 이해관계자에게 지속적으로 강조하고 있다. | S9: Yes | Y9: O | Z9: P | AA9: M | AB9: O | AC9: O | AD9: O | AE9: O | AF9: O | AG9: O | AH9: O | AI9: N/A | AJ9: A | AK9: N/A | AL9: N/A | AM9: N/A | AN9: L | AO9: L | AP9: L | AQ9: L | AR9: L | AS9: L | AT9: L | AU9: L | AV9: Not Higher | AW9: 1. 윤리헌장 실천지침에서는 윤리헌장에 포함된 제반 사항을 이행하지 않은 경우에 인사규정에 따른 징계를 할 수 있도록 규정하고 있다. 2. 윤리헌장을 포함한 제반 규정에 대해서 각 사원의 입사시에 교육이 이루어지고 있으며, 회사의 사규는 각 부서별로 각 사원이 상시열람이 가능할 수 있도록 그룹웨어(문서관리대장)에 등록되어 있다. 3. 리프레시 교육 시 전 임직원으로부터 윤리경영실천서약서를 징구한다. | AX9: 기재된 내용대로 실행 가능한 지, 어렵다면 수정해주십시오. | BA9: O | BC9: 윤리헌장 및 실천지침, 임직원리스트 | BD9: A | BE9: 1 | BF9: 【문서검사】 1. 다음의 방법을 통해 윤리경영의 중요성을 강조하는 경영진의 커뮤니케이션 여부를 확인한다. - 사이냅소프트 홈페이지를 통해 임직원 및 외부 이해관계자에게 윤리경영을 강조한 내용 2. 전 임직원으로부터 윤리경영실천서약서를 징구하고 있는지 확인한다. | BG9: 경영지원팀 전결권자 | BH9: RCM상 '관련 정책 및 문서'를 확인한 결과 통제활동은 해당 정책과 연계되어 있음을 확인함. | BI9: RCM상 기재된 관련 통제위험을 감소시킬수 있도록 통제가 효과적으로 설계 되었음 | BJ9: 예외사항은 해당 통제의 수행시 오류가 발생할 경우로 정의하며, 추가절차를 위해 별도로 설정한 threshold는 없으며, 예외사항 발생시 즉시 추가적인 절차를 취하도록 설계됨. | BK9: 통제를 수행하는데 사용된 정보에 대한 컨트롤이 적절히 수행되고 있음. | BL9: 해당 사업연도 초에 통제가 설계되었으며, 설계이후 해당 통제의 수행기간은 충분하다고 판단됨. | BM9: 업무경험과 교육이수 등을 고려할 때 통제 수행자의 적격성은 충분함 | BN9: 본 통제활동에서 다루는 윤리경영에 대한 이사회와 경영진 의지 강조는 거래의 연간 발생 빈도 및 중요도를 고려하여 주기를 A로 설정하였으며 통제 수행빈도는 해당 위험의 적시 예방 적발을 위해 적절하다고 판단됨. | BO9: 해당 통제와 관련한 중요한 위험인 [이사회 및 경영진이 추구하는 도덕성 및 윤리적 가치가 모든 임직원을 포함하여 외부 이해관계자에게 전달되지 못할 위험. ]에 대해 완전히 고려되고 있음. | BQ9: O | BS9: O | BW9: 도덕성과 윤리적 가치에 대한 책임 | BX9: [현황] 윤리헌장이 제정되어 있고, 경영진이 윤리경영에 대한 강조를 하고 있으나, 도덕성과 윤리적 가치에 대한 책임을 강조하기 위한 윤리교육, 윤리경영실천서약서 징구, 사이버신문고 제도 및 윤리헌장 위반에 대한 인사조치 규정이 구비되어 있지 아니함. [잠재적위험] 윤리교육 및 관련 제도가 구비되지 않아 윤리의식 부족으로 인해 회사 내부에서의 정보보안, 인권존중, 자산의 보호 등과 관련한 부정 뿐만 아니라, 고객과의 관계에 있어서 책임의식 부재, 불공정거래 등이 발생할 수 있고, 대외적으로 법률규정 미준수 등과 관련한 문제가 발생할 위험이 존재함. | BY9: 도덕성과 윤리적 가치에 대한 책임 강조를 보다 명확하게 하기 위해 주기적으로 교육을 실시하고, 관련 규정 및 제도를 정비해야 함.
A10: 1 | B10: EL | C10: 전사 | D10: EL-010 | E10: 통제환경 | F10: EL-010-30 | G10: EL-010-30-10 | H10: 유헌종 | I10: 윤리경영 준수에 대한 평가가 이루어지지 않아 임직원 및 외부 이해관계자에 의해 윤리경영이 실천되지 않을 위험. | J10: Low | K10: Low | L10: Low | M10: Low | N10: Low | O10: LR | P10: 윤리경영 준수에 대한 평가가 임직원 및 외부 이해관계자를 대상으로 실시되어 윤리경영이 실천되고 있다. | Q10: 윤리경영 프로그램 평가 | R10: 임직원 및 외부 이해관계자의 윤리규범 준수를 위해 윤리경영 준수에 대한 평가가 실시되고 있다. | S10: Yes | Y10: O | Z10: P | AA10: M | AB10: O | AC10: O | AD10: O | AE10: O | AF10: O | AG10: O | AH10: O | AI10: N/A | AJ10: A | AK10: N/A | AL10: N/A | AM10: N/A | AN10: L | AO10: L | AP10: L | AQ10: L | AR10: L | AS10: L | AT10: L | AU10: L | AV10: Not Higher | AW10: 1. 홈페이지에 윤리헌장을 게재하여 임직원 및 외부 이해관계자에게 윤리헌장 준수를 강조하고 있다. 2. 홈페이지의 사이버신문고를 통해 임직원 및 외부 이해관계자가 익명으로 고발할 수 있도록 하여 윤리경영 강화 제도를 수립하고 있다. | AX10: 기재된 내용대로 실행 가능한 지, 어렵다면 수정해주십시오. | BA10: O | BC10: 윤리헌장, 사이버신문고 | BD10: A | BE10: 1 | BF10: 【문서검사】 1. 홈페이지에 윤리헌장이 게재되어 있고, 사이버신문고 제도를 익명으로 운영하여 윤리경영을 강조하고 있는지 확인한다. | BG10: 경영지원팀 전결권자 | BH10: RCM상 '관련 정책 및 문서'를 확인한 결과 통제활동은 해당 정책과 연계되어 있음을 확인함. | BI10: RCM상 기재된 관련 통제위험을 감소시킬수 있도록 통제가 효과적으로 설계 되었음 | BJ10: 예외사항은 해당 통제의 수행시 오류가 발생할 경우로 정의하며, 추가절차를 위해 별도로 설정한 threshold는 없으며, 예외사항 발생시 즉시 추가적인 절차를 취하도록 설계됨. | BK10: 통제를 수행하는데 사용된 정보에 대한 컨트롤이 적절히 수행되고 있음. | BL10: 해당 사업연도 초에 통제가 설계되었으며, 설계이후 해당 통제의 수행기간은 충분하다고 판단됨. | BM10: 업무경험과 교육이수 등을 고려할 때 통제 수행자의 적격성은 충분함 | BN10: 본 통제활동에서 다루는 윤리경영 프로그램 평가는 거래의 연간 발생 빈도 및 중요도를 고려하여 주기를 A로 설정하였으며 통제 수행빈도는 해당 위험의 적시 예방 적발을 위해 적절하다고 판단됨. | BO10: 해당 통제와 관련한 중요한 위험인 [윤리경영 준수에 대한 평가가 이루어지지 않아 임직원 및 외부 이해관계자에 의해 윤리경영이 실천되지 않을 위험. ]에 대해 완전히 고려되고 있음. | BQ10: O | BS10: O | BW10: 도덕성과 윤리적 가치에 대한 책임 | BX10: [현황] 윤리헌장이 제정되어 있고, 경영진이 윤리경영에 대한 강조를 하고 있으나, 도덕성과 윤리적 가치에 대한 책임을 강조하기 위한 윤리교육, 윤리경영실천서약서 징구, 사이버신문고 제도 및 윤리헌장 위반에 대한 인사조치 규정이 구비되어 있지 아니함. [잠재적위험] 윤리교육 및 관련 제도가 구비되지 않아 윤리의식 부족으로 인해 회사 내부에서의 정보보안, 인권존중, 자산의 보호 등과 관련한 부정 뿐만 아니라, 고객과의 관계에 있어서 책임의식 부재, 불공정거래 등이 발생할 수 있고, 대외적으로 법률규정 미준수 등과 관련한 문제가 발생할 위험이 존재함. | BY10: 도덕성과 윤리적 가치에 대한 책임 강조를 보다 명확하게 하기 위해 주기적으로 교육을 실시하고, 관련 규정 및 제도를 정비해야 함.
A11: 1 | B11: EL | C11: 전사 | D11: EL-010 | E11: 통제환경 | F11: EL-010-40 | G11: EL-010-40-10 | H11: 유헌종 | I11: 윤리강령의 위반사항은 적시에 일관된 방식으로 식별되고 개선되지 않아 회사의 내·외부 이해관계자가 윤리적 가치를 준수하지 않을 위험 | J11: Low | K11: Low | L11: Low | M11: Low | N11: Low | O11: LR | P11: 윤리 위반사항이 적절히 시정조치되며 회사 윤리규범에 대한 임직원과 외부관계자들의 준수의지를 제고한다. | Q11: 윤리강령 위반사항의 적시 조사 및 처리 | R11: 윤리 위반사항의 식별, 조사, 보고 및 조치결과(대응방안)의 공표 등 일관된 절차에 의해 업무가 처리되도록 문서화하고 운영한다. | S11: Yes | Y11: O | Z11: P | AA11: M | AB11: O | AC11: O | AD11: O | AE11: O | AF11: O | AG11: O | AH11: O | AI11: N/A | AJ11: A | AK11: N/A | AL11: N/A | AM11: N/A | AN11: L | AO11: L | AP11: L | AQ11: L | AR11: L | AS11: L | AT11: L | AU11: L | AV11: Not Higher | AW11: 1. 홈페이지에서 사이버신문고(익명)를 운영하고 있으며, 접수된 내용은 OOOO팀 및 대표이사에게 이메일이 발송된다. 2. OOOO팀에서는 접수된 내용에 대해 조사를 실시하고, 그 결과를 대표이사에게 보고한다. 3. 사안에 따라 징계위원회를 개최하고, 그 결과에 따라 조치를 취하며, 유사 사례 발생 방지를 위해 관련 교육을 실시한다. 4. "취업규칙 및 징계운영기준"에 징계의 종류 및 징계사유를 기술하고, 징계심의에 대한 절차 등을 명확히 기술하고 있으며, 윤리규범 및 회사정책 위반시 징계절차에 따라 징계를 받는다. 4. "취업규칙 및 징계운영기준"에 따르면 징계사유가 발생시 징계위원회를 개최하고, 징계사유 및 징계위원회의 결과에 따라 견책, 감봉, 정직, 해고의 징계를 받도록 하고 있다. | AX11: 기재된 내용대로 실행 가능한 지, 어렵다면 수정해주십시오. | BA11: O | BC11: 윤리헌장 위반사례 접수리스트 | BD11: A | BE11: 1 | BF11: 【문서검사】 1. 윤리헌장 위반사례 접수리스트에서 표본을 추출하여 다음을 확인한다. - 접수된 내용에 대해 조사하고, 그 결과를 대표이사에게 보고했는지 여부 - 징계위원회 개최 여부 - 관련 교육 실시 여부 | BG11: 경영지원팀 전결권자 | BH11: RCM상 '관련 정책 및 문서'를 확인한 결과 통제활동은 해당 정책과 연계되어 있음을 확인함. | BI11: RCM상 기재된 관련 통제위험을 감소시킬수 있도록 통제가 효과적으로 설계 되었음 | BJ11: 예외사항은 해당 통제의 수행시 오류가 발생할 경우로 정의하며, 추가절차를 위해 별도로 설정한 threshold는 없으며, 예외사항 발생시 즉시 추가적인 절차를 취하도록 설계됨. | BK11: 통제를 수행하는데 사용된 정보에 대한 컨트롤이 적절히 수행되고 있음. | BL11: 해당 사업연도 초에 통제가 설계되었으며, 설계이후 해당 통제의 수행기간은 충분하다고 판단됨. | BM11: 업무경험과 교육이수 등을 고려할 때 통제 수행자의 적격성은 충분함 | BN11: 본 통제활동에서 다루는 윤리강령 위반사항의 적시 조사 및 처리 는 거래의 연간 발생 빈도 및 중요도를 고려하여 주기를 A로 설정하였으며 통제 수행빈도는 해당 위험의 적시 예방 적발을 위해 적절하다고 판단됨. | BO11: 해당 통제와 관련한 중요한 위험인 [윤리강령의 위반사항은 적시에 일관된 방식으로 식별되고 개선되지 않아 회사의 내·외부 이해관계자가 윤리적 가치를 준수하지 않을 위험 ]에 대해 완전히 고려되고 있음. | BQ11: O | BS11: O | BW11: 도덕성과 윤리적 가치에 대한 책임 | BX11: [현황] 윤리헌장이 제정되어 있고, 경영진이 윤리경영에 대한 강조를 하고 있으나, 도덕성과 윤리적 가치에 대한 책임을 강조하기 위한 윤리교육, 윤리경영실천서약서 징구, 사이버신문고 제도 및 윤리헌장 위반에 대한 인사조치 규정이 구비되어 있지 아니함. [잠재적위험] 윤리교육 및 관련 제도가 구비되지 않아 윤리의식 부족으로 인해 회사 내부에서의 정보보안, 인권존중, 자산의 보호 등과 관련한 부정 뿐만 아니라, 고객과의 관계에 있어서 책임의식 부재, 불공정거래 등이 발생할 수 있고, 대외적으로 법률규정 미준수 등과 관련한 문제가 발생할 위험이 존재함. | BY11: 도덕성과 윤리적 가치에 대한 책임 강조를 보다 명확하게 하기 위해 주기적으로 교육을 실시하고, 관련 규정 및 제도를 정비해야 함.
A12: 1 | B12: EL | C12: 전사 | D12: EL-010 | E12: 통제환경 | F12: EL-010-50 | G12: EL-010-50-10 | H12: 김세영 | I12: 내부회계관리제도와 관련한 이사회 및 감사의 명확하지 않은 역할과 책임의 정의로 관리 및 감독 기능이 효과적으로 작동되지 못할 위험 | J12: Low | K12: Low | L12: Low | M12: Low | N12: Low | O12: LR | P12: 재무보고 및 내부회계관리제도 감독 관련 이사회 및 감사의 역할∙책임 정의가 명확하며 내부회계관리제도 감독 기능이 효과적으로 작동된다. | Q12: 내부회계관리제도와 관련한 이사회 및 감사의 역할 및 책임 정의 | R12: 내부회계관리제도와 관련한 이사회 및 감사의 역할과 책임을 명확히 정의하고 적격성과 독립성을 주기적으로 검토한다. | S12: Yes | Y12: O | Z12: P | AA12: M | AB12: O | AC12: O | AD12: O | AE12: O | AF12: O | AG12: O | AH12: O | AI12: N/A | AJ12: A | AK12: N/A | AL12: N/A | AM12: N/A | AN12: L | AO12: L | AP12: L | AQ12: L | AR12: L | AS12: L | AT12: L | AU12: L | AV12: Not Higher | AW12: 1. 이사회의 역할, 책임 및 위임 권한은 관련 법규, 정관 및 이사회 규정 등에 정의되며, 이사회는 다음과 같은 업무를 포함하여 경영진을 관리 감독한다. - 내부회계관리규정 제·개정의 결의 및 중요 정책의 승인 - 내부회계관리제도의 설계 및 운영에 대한 경영진의 중요한 조치 사항 검토 - 내부회계관리제도의 중요한 변화 사항에 대한 경영진의 조치 사항 검토 - 내부회계관리제도의 평가 결과 및 개선 조치에 대한 확인 등 2. '내부회계관리규정 및 업무지침' 및 '감사직무규정'을 제/개정하여 감사의 다음과 같은 역할 및 책임을 다음과 같이 정의하고 운영하고 있다. - 내부회계관리제도에 대한 관리 감독 - 부정방지 프로그램에 대한 관리 감독 - 외부감사인에 대한 관리 감독 - 기타 감사 관련 정책, 절차 및 보고에 대한 관리 감독 | AX12: N/A | BA12: O | BC12: 내부회계관리규정 및 업무지침, 감사직무규정 | BD12: A | BE12: 1 | BF12: 【문서검사】 1. '이사회규정'과 '내부회계관리규정 및 업무지침'에 다음의 내용이 규정되어 있는지 확인한다. - 내부회계관리내규 제·개정의 결의 및 중요 정책의 승인 - 내부회계관리제도의 설계 및 운영에 대한 경영진의 중요한 조치 사항 검토 - 내부회계관리제도의 중요한 변화 사항에 대한 경영진의 조치 사항 검토 - 내부회계관리제도의 평가 결과 및 개선 조치에 대한 확인 등 2. '이사회의사록'을 검토하여 '이사회규정' 및 '내부회계관리규정 및 업무지침'에 규정된 상기의 역할이 수행되었는지 확인한다. 3. '감사직무규정'과 '내부회계관리규정 및 업무지침'에 다음의 내용이 규정되어 있는지 확인한다. - 내부회계관리제도에 대한 관리 감독 - 부정방지 프로그램에 대한 관리 감독 - 외부감사인에 대한 관리 감독 - 기타 감사 관련 정책, 절차 및 보고에 대한 관리 감독 | BG12: 경영지원팀 전결권자 | BH12: RCM상 '관련 정책 및 문서'를 확인한 결과 통제활동은 해당 정책과 연계되어 있음을 확인함. | BI12: RCM상 기재된 관련 통제위험을 감소시킬수 있도록 통제가 효과적으로 설계 되었음 | BJ12: 예외사항은 해당 통제의 수행시 오류가 발생할 경우로 정의하며, 추가절차를 위해 별도로 설정한 threshold는 없으며, 예외사항 발생시 즉시 추가적인 절차를 취하도록 설계됨. | BK12: 통제를 수행하는데 사용된 정보에 대한 컨트롤이 적절히 수행되고 있음. | BL12: 해당 사업연도 초에 통제가 설계되었으며, 설계이후 해당 통제의 수행기간은 충분하다고 판단됨. | BM12: 업무경험과 교육이수 등을 고려할 때 통제 수행자의 적격성은 충분함 | BN12: 본 통제활동에서 다루는 내부회계관리제도와 관련한 이사회 및 감사의 역할 및 책임 정의 는 거래의 연간 발생 빈도 및 중요도를 고려하여 주기를 A로 설정하였으며 통제 수행빈도는 해당 위험의 적시 예방 적발을 위해 적절하다고 판단됨. | BO12: 해당 통제와 관련한 중요한 위험인 [내부회계관리제도와 관련한 이사회 및 감사의 명확하지 않은 역할과 책임의 정의로 관리 및 감독 기능이 효과적으로 작동되지 못할 위험 ]에 대해 완전히 고려되고 있음. | BQ12: O | BS12: O | BW12: 내부회계관리제도 관련 규정의 수립 및 준수 | BX12: [현황] 현재는 비상장법인으로 내부회계관리제도의 운영의무가 없기 때문에 규정 및 조직이 구비되어 있지 아니함. [잠재적위험] 내부회계관리규정 및 조직의 미비로 인해 주식회사등의외부감사에관한법률상의 의무를 준수하지 못할 가능성이 존재함. | BY12: 향후 상장 시, 주식회사등의외부감사에관한법률 제8조에 따라 신뢰할 수 있는 회계정보의 작성과 공시를 위하여 다음 각 호의 사항이 포함된 내부회계관리규정과 이를 관리ㆍ운영하는 조직을 갖추어야 함. 1. 회계정보의 식별ㆍ측정ㆍ분류ㆍ기록 및 보고 방법에 관한 사항 2. 회계정보의 오류를 통제하고 이를 수정하는 방법에 관한 사항 3. 회계정보에 대한 정기적인 점검 및 조정 등 내부검증에 관한 사항 4. 회계정보를 기록ㆍ보관하는 장부의 관리 방법과 위조ㆍ변조ㆍ훼손 및 파기를 방지하기 위한 통제 절차에 관한 사항 5. 회계정보의 작성 및 공시와 관련된 임직원의 업무 분장과 책임에 관한 사항 6. 그 밖에 신뢰할 수 있는 회계정보의 작성과 공시를 위하여 필요한 사항으로서 대통령령으로 정하는 사항
A13: 1 | B13: EL | C13: 전사 | D13: EL-010 | E13: 통제환경 | F13: EL-010-60 | G13: EL-010-60-10 | H13: 김세영 | I13: 감사의 독립성과 전문성 결여로 감독 기능이 효과적으로 운영되지 못할 위험. | J13: Low | K13: Low | L13: Low | M13: Low | N13: Low | O13: LR | P13: 감사의 선임 절차를 명확히 하고 전문성과 독립성을 주기적으로 평가하여 감독 기능이 효과적으로 운영된다. | Q13: 감사 선임 및 주기적 평가 | R13: 감사의 선임 기준을 명확히 하고 주기적으로 평가하여 감사의 기능이 효과적으로 운영된다. | S13: Yes | Y13: O | Z13: P | AA13: M | AB13: O | AC13: O | AD13: O | AE13: O | AF13: O | AG13: O | AH13: O | AI13: N/A | AJ13: A | AK13: N/A | AL13: N/A | AM13: N/A | AN13: L | AO13: L | AP13: L | AQ13: L | AR13: L | AS13: L | AT13: L | AU13: L | AV13: Not Higher | AW13: 1. 이사회는 감사의 전문성과 독립성이 적정한지 검토를 수행하며, 다음 항목을 고려하여 검토를 수행한다. - 후보자의 배경 및 평판 - 회사의 외부 재무보고에 영향을 미칠 수 있는 문제를 이해하는데 필요한 회계기준, 회계감사, 내부통제, 관련 법규 및 각종 지식을 포함한 전문성 - 경영진 및 회사와의 독립성을 유지하기 위해 후보가 소속한 조직에서 현재 후보의 역할과 직급 등의 적정성 2. 연1회 감사평가 체크리스트를 작성하여 감사의 적격성과 독립성을 평가한다. | AX13: N/A | BA13: O | BC13: 이사회의사록 (감사 후보 추천 안건) /감사평가체크리스트 | BD13: A | BE13: 1 | BF13: 【문서검사】 1. '이사회의사록'의 감사 후보 추천 안건을 확인하고 감사의 적격성과 독립성이 검토되는지 다음의 사항 등을 확인한다. - 이사회의 감사 후보 검증 절차의 수행 및 문서화(배경 및 평판, 전문성과 독립성, 자격요건 검토 등) 2. '감사 평가 체크리스트'를 입수하여 감사의 적격성과 독립성이 정기적으로 검토되고 있는지 확인한다. | BG13: 경영지원팀 전결권자 | BH13: RCM상 '관련 정책 및 문서'를 확인한 결과 통제활동은 해당 정책과 연계되어 있음을 확인함. | BI13: RCM상 기재된 관련 통제위험을 감소시킬수 있도록 통제가 효과적으로 설계 되었음 | BJ13: 예외사항은 해당 통제의 수행시 오류가 발생할 경우로 정의하며, 추가절차를 위해 별도로 설정한 threshold는 없으며, 예외사항 발생시 즉시 추가적인 절차를 취하도록 설계됨. | BK13: 통제를 수행하는데 사용된 정보에 대한 컨트롤이 적절히 수행되고 있음. | BL13: 해당 사업연도 초에 통제가 설계되었으며, 설계이후 해당 통제의 수행기간은 충분하다고 판단됨. | BM13: 업무경험과 교육이수 등을 고려할 때 통제 수행자의 적격성은 충분함 | BN13: 본 통제활동에서 다루는 감사 선임 및 주기적 평가는 거래의 연간 발생 빈도 및 중요도를 고려하여 주기를 A로 설정하였으며 통제 수행빈도는 해당 위험의 적시 예방 적발을 위해 적절하다고 판단됨. | BO13: 해당 통제와 관련한 중요한 위험인 [감사의 독립성과 전문성 결여로 감독 기능이 효과적으로 운영되지 못할 위험. ]에 대해 완전히 고려되고 있음. | BQ13: O | BS13: O | BW13: 내부회계관리제도 관련 규정의 수립 및 준수 | BX13: [현황] 현재는 비상장법인으로 내부회계관리제도의 운영의무가 없기 때문에 규정 및 조직이 구비되어 있지 아니함. [잠재적위험] 내부회계관리규정 및 조직의 미비로 인해 주식회사등의외부감사에관한법률상의 의무를 준수하지 못할 가능성이 존재함. | BY13: 향후 상장 시, 주식회사등의외부감사에관한법률 제8조에 따라 신뢰할 수 있는 회계정보의 작성과 공시를 위하여 다음 각 호의 사항이 포함된 내부회계관리규정과 이를 관리ㆍ운영하는 조직을 갖추어야 함. 1. 회계정보의 식별ㆍ측정ㆍ분류ㆍ기록 및 보고 방법에 관한 사항 2. 회계정보의 오류를 통제하고 이를 수정하는 방법에 관한 사항 3. 회계정보에 대한 정기적인 점검 및 조정 등 내부검증에 관한 사항 4. 회계정보를 기록ㆍ보관하는 장부의 관리 방법과 위조ㆍ변조ㆍ훼손 및 파기를 방지하기 위한 통제 절차에 관한 사항 5. 회계정보의 작성 및 공시와 관련된 임직원의 업무 분장과 책임에 관한 사항 6. 그 밖에 신뢰할 수 있는 회계정보의 작성과 공시를 위하여 필요한 사항으로서 대통령령으로 정하는 사항
A14: 1 | B14: EL | C14: 전사 | D14: EL-010 | E14: 통제환경 | F14: EL-010-70 | G14: EL-010-70-10 | H14: 김세영 | I14: 이사회 및 감사의 재무보고 및 내부회계관리제도 감독 부실로 인해 내부회계관리제도 감독 기능이 효과적으로 작동되지 못할 위험. | J14: Low | K14: Low | L14: Low | M14: Low | N14: Low | O14: LR | P14: 이사회 및 감사에 의해 재무보고 및 내부회계관리제도가 감독되어 내부회계관리제도가 효과적으로 운영된다. | Q14: 이사회 및 감사의 내부회계관리제도 감독 수행 | R14: 이사회 및 감사에 의해 재무보고 및 내부회계관리제도 활동이 감독된다. | S14: Yes | Y14: O | Z14: P | AA14: M | AB14: O | AC14: O | AD14: O | AE14: O | AF14: O | AG14: O | AH14: O | AI14: N/A | AJ14: A | AK14: N/A | AL14: N/A | AM14: N/A | AN14: L | AO14: L | AP14: L | AQ14: L | AR14: L | AS14: L | AT14: L | AU14: L | AV14: Not Higher | AW14: 1. 내부회계관리제도와 관련한 이사회의 감독 수행은 다음과 같다. - 대표이사는 매 사업연도마다 이사회에 내부회계관리제도의 운영실태를 보고 - 감사는 내부회계관리제 운영실태를 평가하여 이사회에 보고 2. 감사는 경영진의 중요한 판단에 대한 검토 및 외부감사인과 의사소통하는 절차를 수행한다. - 회계 고유의 정책의 선택과 적용 방안 - 회사가 당면한 주요 재무제표 왜곡 표시 위험 - 감사 범위 및 테스트 계획 - 중요성 금액 산정의 근거 - 중요한 회계 정책 - 감사에 필요한 지원 및 인원 (감사투입시간 등 포함) - 감사에 대응하는 조직과 문화 - 내부회계관리제도에 대한 경영진의 평가 - 중요한 감사 발견사항 - 재무보고의 품질 및 신뢰성 - 내부고발자 및 부정 관련 프로그램 관련 제반 사항 | AX14: N/A | BA14: O | BC14: 이사회의사록 /감사록 | BD14: A | BE14: 1 | BF14: 【문서검사】 1. '이사회의사록'을 검토하여 다음사항이 보고되었는지 확인한다. - 내부회계관리제도의 운영실태를 보고 - 내부회계관리제 운영실태를 평가결과 보고 2. '감사록'을 입수하여 감사가 경영진 및 외부 감사인과 다음의 사항 등에 대해 의사소통이 수행되었는지 확인한다. - 회계 고유의 정책의 선택과 적용 방안 - 회사가 당면한 주요 재무제표 왜곡 표시 위험 - 감사 범위 및 테스트 계획 - 중요성 금액 산정의 근거 - 중요한 회계 정책 - 감사에 필요한 지원 및 인원 (감사투입시간 등 포함) - 감사에 대응하는 조직과 문화 - 내부회계관리제도에 대한 경영진의 평가 - 중요한 감사 발견사항 - 재무보고의 품질 및 신뢰성 - 내부고발자 및 부정 관련 프로그램 관련 제반 사항 | BG14: 경영지원팀 전결권자 | BH14: RCM상 '관련 정책 및 문서'를 확인한 결과 통제활동은 해당 정책과 연계되어 있음을 확인함. | BI14: RCM상 기재된 관련 통제위험을 감소시킬수 있도록 통제가 효과적으로 설계 되었음 | BJ14: 예외사항은 해당 통제의 수행시 오류가 발생할 경우로 정의하며, 추가절차를 위해 별도로 설정한 threshold는 없으며, 예외사항 발생시 즉시 추가적인 절차를 취하도록 설계됨. | BK14: 통제를 수행하는데 사용된 정보에 대한 컨트롤이 적절히 수행되고 있음. | BL14: 해당 사업연도 초에 통제가 설계되었으며, 설계이후 해당 통제의 수행기간은 충분하다고 판단됨. | BM14: 업무경험과 교육이수 등을 고려할 때 통제 수행자의 적격성은 충분함 | BN14: 본 통제활동에서 다루는 이사회 및 감사의 내부회계관리제도 감독 수행는 거래의 연간 발생 빈도 및 중요도를 고려하여 주기를 A로 설정하였으며 통제 수행빈도는 해당 위험의 적시 예방 적발을 위해 적절하다고 판단됨. | BO14: 해당 통제와 관련한 중요한 위험인 [이사회 및 감사의 재무보고 및 내부회계관리제도 감독 부실로 인해 내부회계관리제도 감독 기능이 효과적으로 작동되지 못할 위험. ]에 대해 완전히 고려되고 있음. | BQ14: O | BS14: O | BW14: 내부회계관리제도 관련 규정의 수립 및 준수 | BX14: [현황] 현재는 비상장법인으로 내부회계관리제도의 운영의무가 없기 때문에 규정 및 조직이 구비되어 있지 아니함. [잠재적위험] 내부회계관리규정 및 조직의 미비로 인해 주식회사등의외부감사에관한법률상의 의무를 준수하지 못할 가능성이 존재함. | BY14: 향후 상장 시, 주식회사등의외부감사에관한법률 제8조에 따라 신뢰할 수 있는 회계정보의 작성과 공시를 위하여 다음 각 호의 사항이 포함된 내부회계관리규정과 이를 관리ㆍ운영하는 조직을 갖추어야 함. 1. 회계정보의 식별ㆍ측정ㆍ분류ㆍ기록 및 보고 방법에 관한 사항 2. 회계정보의 오류를 통제하고 이를 수정하는 방법에 관한 사항 3. 회계정보에 대한 정기적인 점검 및 조정 등 내부검증에 관한 사항 4. 회계정보를 기록ㆍ보관하는 장부의 관리 방법과 위조ㆍ변조ㆍ훼손 및 파기를 방지하기 위한 통제 절차에 관한 사항 5. 회계정보의 작성 및 공시와 관련된 임직원의 업무 분장과 책임에 관한 사항 6. 그 밖에 신뢰할 수 있는 회계정보의 작성과 공시를 위하여 필요한 사항으로서 대통령령으로 정하는 사항
A15: 1 | B15: EL | C15: 전사 | D15: EL-010 | E15: 통제환경 | F15: EL-010-80 | G15: EL-010-80-10 | H15: 김세영 | I15: 내부회계관리 전담조직의 역할·책임이 명확하게 정의되지 않아 내부회계관리제도 설계·운영의 효과성이 저하되고 내부회계관리제도 관련 의사결정이 적정하게 이루어지지 않을 위험. | J15: Low | K15: Low | L15: Low | M15: Low | N15: Low | O15: LR | P15: 내부회계관리 전담조직의 역할·책임이 명확하게 정의되어 내부회계관리제도 설계·운영이 효과적이고 내부회계관리제도 관련 의사결정이 적정하게 이루어 지고 있다. | Q15: 내부회계관리 조직구조 및 보고체계 정립 | R15: 내부회계관리 전담조직의 역할·책임이 명확하게 정의되어 내부회계관리제도가 효과적으로 운영되고 있다. | S15: Yes | Y15: O | Z15: P | AA15: M | AB15: O | AC15: O | AD15: O | AE15: O | AF15: O | AG15: O | AH15: O | AI15: N/A | AJ15: A | AK15: N/A | AL15: N/A | AM15: N/A | AN15: L | AO15: L | AP15: L | AQ15: L | AR15: L | AS15: L | AT15: L | AU15: L | AV15: Not Higher | AW15: 1. '내부회계관리규정 및 업무지침'에 내부회계관리제도를 설계, 운영 및 평가를 위한 조직의 역할과 책임을 다음과 같이 규정하고 있다. 1) 이사회 -. 내부회계관리제도의 설계 및 운영 감독책임 2) 대표이사 - 내부회계관리제도 관리 , 운영의 궁극적인 책임 - 내부회계관리제도 운영을 담당하는 내부회계관리자 지정 3) 내부회계관리자 - 내부회계관리제도 설계 및 운영을 총괄 - 내부회계관리제도 설계 및 운영 효과성 점검 - 이사회 및 감사에 내부회계관리제도 운영실태 보고 4) 감사 - 내부회계관리제도 운영실태에 대한 평가 및 보고 5) 통제담당자 - 내부회계관리제도 통제활동 적용 책임 - 내부회계관리제도 통제활동 변화 사항 파악 및 보고 | AX15: N/A | BA15: O | BC15: 내부회계관리규정 및 업무지침 | BD15: A | BE15: 1 | BF15: 【문서검사】 1. 내부회계관리규정 및 업무지침'을 징구하여 다음을 포함한 내부회계 관리조직의 역할과 책임이 정의되었는지 확인한다. 1) 이사회 -. 내부회계관리제도의 설계 및 운영 감독책임 2) 대표이사 - 내부회계관리제도 관리 , 운영의 궁극적인 책임 - 내부회계관리제도 운영을 담당하는 내부회계관리자 지정 3) 내부회계관리자 - 내부회계관리제도 설계 및 운영을 총괄 - 내부회계관리제도 설계 및 운영 효과성 점검 - 이사회 및 감사에 내부회계관리제도 운영실태 보고 4) 감사 - 내부회계관리제도 운영실태에 대한 평가 및 보고 5) 통제담당자 - 내부회계관리제도 통제활동 적용 책임 - 내부회계관리제도 통제활동 변화 사항 파악 및 보고 | BG15: 경영지원팀 전결권자 | BH15: RCM상 '관련 정책 및 문서'를 확인한 결과 통제활동은 해당 정책과 연계되어 있음을 확인함. | BI15: RCM상 기재된 관련 통제위험을 감소시킬수 있도록 통제가 효과적으로 설계 되었음 | BJ15: 예외사항은 해당 통제의 수행시 오류가 발생할 경우로 정의하며, 추가절차를 위해 별도로 설정한 threshold는 없으며, 예외사항 발생시 즉시 추가적인 절차를 취하도록 설계됨. | BK15: 통제를 수행하는데 사용된 정보에 대한 컨트롤이 적절히 수행되고 있음. | BL15: 해당 사업연도 초에 통제가 설계되었으며, 설계이후 해당 통제의 수행기간은 충분하다고 판단됨. | BM15: 업무경험과 교육이수 등을 고려할 때 통제 수행자의 적격성은 충분함 | BN15: 본 통제활동에서 다루는 내부회계관리 조직구조 및 보고체계 정립는 거래의 연간 발생 빈도 및 중요도를 고려하여 주기를 A로 설정하였으며 통제 수행빈도는 해당 위험의 적시 예방 적발을 위해 적절하다고 판단됨. | BO15: 해당 통제와 관련한 중요한 위험인 [내부회계관리 전담조직의 역할·책임이 명확하게 정의되지 않아 내부회계관리제도 설계·운영의 효과성이 저하되고 내부회계관리제도 관련 의사결정이 적정하게 이루어지지 않을 위험. ]에 대해 완전히 고려되고 있음. | BQ15: O | BS15: O | BW15: 내부회계관리제도 관련 규정의 수립 및 준수 | BX15: [현황] 현재는 비상장법인으로 내부회계관리제도의 운영의무가 없기 때문에 규정 및 조직이 구비되어 있지 아니함. [잠재적위험] 내부회계관리규정 및 조직의 미비로 인해 주식회사등의외부감사에관한법률상의 의무를 준수하지 못할 가능성이 존재함. | BY15: 향후 상장 시, 주식회사등의외부감사에관한법률 제8조에 따라 신뢰할 수 있는 회계정보의 작성과 공시를 위하여 다음 각 호의 사항이 포함된 내부회계관리규정과 이를 관리ㆍ운영하는 조직을 갖추어야 함. 1. 회계정보의 식별ㆍ측정ㆍ분류ㆍ기록 및 보고 방법에 관한 사항 2. 회계정보의 오류를 통제하고 이를 수정하는 방법에 관한 사항 3. 회계정보에 대한 정기적인 점검 및 조정 등 내부검증에 관한 사항 4. 회계정보를 기록ㆍ보관하는 장부의 관리 방법과 위조ㆍ변조ㆍ훼손 및 파기를 방지하기 위한 통제 절차에 관한 사항 5. 회계정보의 작성 및 공시와 관련된 임직원의 업무 분장과 책임에 관한 사항 6. 그 밖에 신뢰할 수 있는 회계정보의 작성과 공시를 위하여 필요한 사항으로서 대통령령으로 정하는 사항
A16: 1 | B16: EL | C16: 전사 | D16: EL-010 | E16: 통제환경 | F16: EL-010-90 | G16: EL-010-90-10 | H16: 노정희 유헌종 | I16: 내부회계관리제도 운영을 위한 권한 및 책임이 명확하게 정의되지 않아 내부회계관리제도 설계∙운영의 효과성이 저하될 위험. | J16: Low | K16: Low | L16: Low | M16: Low | N16: Low | O16: LR | P16: 내부회계관리제도 운영을 위한 권한 및 책임을 명확하게 정의하여 내부회계관리제도를 효과적으로 설계 및 운영한다. | Q16: 내부회계관리 권한 및 책임 정립 | R16: 위임전결 규정 등을 통해 내부회계관리제도 운영을 위한 권한 및 책임을 명확하게 정의한다. | S16: Yes | Y16: O | Z16: P | AA16: M | AB16: O | AC16: O | AD16: O | AE16: O | AF16: O | AG16: O | AH16: O | AI16: N/A | AJ16: A | AK16: N/A | AL16: N/A | AM16: N/A | AN16: L | AO16: L | AP16: L | AQ16: L | AR16: L | AS16: L | AT16: L | AU16: L | AV16: Not Higher | AW16: 1. 업무분장의 중요성 전달 및 임직원의 권한과 책임을 명확하게 규정하고, 부서 내의 업무보고체계를 확립하고자 다음의 규정을 제정하여 운영하고 있으며, 그룹웨어에 저장되어 모든 임직원에게 공유되고 있다. - 위임전결규정 - 부서별 업무분장 2. 재무보고를 포함한 업무 프로세스의 권한 및 책임을 명확히 하기 위해 제정된 상기 규정에 따라 거래의 승인과 처리, 보고가 이루어지고 있으며, 변경사항 발생 시 업데이트되고 있다. 규정의 업데이트는 대표이사의 승인을 받고 있다. 3. 내부회계관리규정 및 업무지침에서 정의한 RCM을 작성하고 있으며, 해당 문서에 업무담당자별로 관련 업무내역을 기술하고 있다. 4. 내부회계관리규정 및 업무지침를 통해 내부회계관리제도와 관련된 책임을 다음과 같이 정의함. - 내부회게관리제도 운영: 현업부서, 내부회계전담부서 - 내부회계관리제도 운영실태 점검: 내부회계전담부서 - 내부회계관리제도 운영실태 평가: 감사 | AX16: 규정명 확인 필요/재무보고 관련 규정 제정 필요 | BA16: O | BC16: 조직도, 위임전결규정, 부서별 업무분장, 내부회계관리규정 및 업무지침 | BD16: A | BE16: 1 | BF16: 【문서검사】 1. 위임전결규정 및 부서별 업무분장이 구비되어 있고, 해당 규정에 업무분장 및 권한과 책임이 분리되어 있는지 확인한다. 2. 상기 1의 규정이 개정된 경우, 대표이사의 승인을 받았는지 관련 품의서를 확인한다. 3. 내부회계관리규정 및 업무지침에 외부 재무보고 및 내부회계관리제도와 관련된 권한 및 책임을 명시하고 있는지 확인한다. - 내부회계관리조직의 임직원에게 위임된 권한과 책임 - 내부회계관리조직의 주요 역할, 자격요건 | BG16: 경영지원팀 전결권자 | BH16: RCM상 '관련 정책 및 문서'를 확인한 결과 통제활동은 해당 정책과 연계되어 있음을 확인함. | BI16: RCM상 기재된 관련 통제위험을 감소시킬수 있도록 통제가 효과적으로 설계 되었음 | BJ16: 예외사항은 해당 통제의 수행시 오류가 발생할 경우로 정의하며, 추가절차를 위해 별도로 설정한 threshold는 없으며, 예외사항 발생시 즉시 추가적인 절차를 취하도록 설계됨. | BK16: 통제를 수행하는데 사용된 정보에 대한 컨트롤이 적절히 수행되고 있음. | BL16: 해당 사업연도 초에 통제가 설계되었으며, 설계이후 해당 통제의 수행기간은 충분하다고 판단됨. | BM16: 업무경험과 교육이수 등을 고려할 때 통제 수행자의 적격성은 충분함 | BN16: 본 통제활동에서 다루는 내부회계관리 권한 및 책임 정립는 거래의 연간 발생 빈도 및 중요도를 고려하여 주기를 A로 설정하였으며 통제 수행빈도는 해당 위험의 적시 예방 적발을 위해 적절하다고 판단됨. | BO16: 해당 통제와 관련한 중요한 위험인 [내부회계관리제도 운영을 위한 권한 및 책임이 명확하게 정의되지 않아 내부회계관리제도 설계∙운영의 효과성이 저하될 위험. ]에 대해 완전히 고려되고 있음. | BQ16: O | BS16: O | BW16: 내부회계관리제도 관련 규정의 수립 및 준수 | BX16: [현황] 현재는 비상장법인으로 내부회계관리제도의 운영의무가 없기 때문에 규정 및 조직이 구비되어 있지 아니함. [잠재적위험] 내부회계관리규정 및 조직의 미비로 인해 주식회사등의외부감사에관한법률상의 의무를 준수하지 못할 가능성이 존재함. | BY16: 향후 상장 시, 주식회사등의외부감사에관한법률 제8조에 따라 신뢰할 수 있는 회계정보의 작성과 공시를 위하여 다음 각 호의 사항이 포함된 내부회계관리규정과 이를 관리ㆍ운영하는 조직을 갖추어야 함. 1. 회계정보의 식별ㆍ측정ㆍ분류ㆍ기록 및 보고 방법에 관한 사항 2. 회계정보의 오류를 통제하고 이를 수정하는 방법에 관한 사항 3. 회계정보에 대한 정기적인 점검 및 조정 등 내부검증에 관한 사항 4. 회계정보를 기록ㆍ보관하는 장부의 관리 방법과 위조ㆍ변조ㆍ훼손 및 파기를 방지하기 위한 통제 절차에 관한 사항 5. 회계정보의 작성 및 공시와 관련된 임직원의 업무 분장과 책임에 관한 사항 6. 그 밖에 신뢰할 수 있는 회계정보의 작성과 공시를 위하여 필요한 사항으로서 대통령령으로 정하는 사항
A17: 1 | B17: EL | C17: 전사 | D17: EL-010 | E17: 통제환경 | F17: EL-010-100 | G17: EL-010-100-10 | H17: 김세영 | I17: 내부회계관리제도 설계·운영 활동이 적격하지 않은 인원에 의해 수행되어 내부회계관리제도의 목적을 달성하지 못할 위험. | J17: Low | K17: Low | L17: Low | M17: Low | N17: Low | O17: LR | P17: 내부회계관리제도 설계·운영 활동은 적격한 인원에 의해 수행되고 있다 | Q17: 내부회계관리제도 적격성 기준 정의 | R17: 내부회계관리제도를 운영하는 주요 임직원의 적격성 기준을 정의한다. | S17: Yes | Y17: O | Z17: P | AA17: M | AB17: O | AC17: O | AD17: O | AE17: O | AF17: O | AG17: O | AH17: O | AI17: N/A | AJ17: A | AK17: N/A | AL17: N/A | AM17: N/A | AN17: L | AO17: L | AP17: L | AQ17: L | AR17: L | AS17: L | AT17: L | AU17: L | AV17: Not Higher | AW17: 1. '내부회계관리규정 및 업무지침'를 제개정하여 내부회계관리제도 관련 주요 역할 수행 부서의 직무 수행을 위한 필요 지식, 기술, 전문성 등 적격성을 구체적으로 명시하고 있다. | AX17: N/A | BA17: O | BC17: 내부회계관리규정 및 업무지침 | BD17: A | BE17: 1 | BF17: 【문서검사】 1. '내부회계관리규정 및 업무지침'을 입수하여 내부회계관리제도와 관련된 주요 역할별 적격성 기준을 구체적으로 명시하였는지 확인한다. • 내부회계관리자 • 내부회계전담부서 • 회계정보 작성 | BG17: 경영지원팀 전결권자 | BH17: RCM상 '관련 정책 및 문서'를 확인한 결과 통제활동은 해당 정책과 연계되어 있음을 확인함. | BI17: RCM상 기재된 관련 통제위험을 감소시킬수 있도록 통제가 효과적으로 설계 되었음 | BJ17: 예외사항은 해당 통제의 수행시 오류가 발생할 경우로 정의하며, 추가절차를 위해 별도로 설정한 threshold는 없으며, 예외사항 발생시 즉시 추가적인 절차를 취하도록 설계됨. | BK17: 통제를 수행하는데 사용된 정보에 대한 컨트롤이 적절히 수행되고 있음. | BL17: 해당 사업연도 초에 통제가 설계되었으며, 설계이후 해당 통제의 수행기간은 충분하다고 판단됨. | BM17: 업무경험과 교육이수 등을 고려할 때 통제 수행자의 적격성은 충분함 | BN17: 본 통제활동에서 다루는 내부회계관리제도 적격성 기준 정의는 거래의 연간 발생 빈도 및 중요도를 고려하여 주기를 A로 설정하였으며 통제 수행빈도는 해당 위험의 적시 예방 적발을 위해 적절하다고 판단됨. | BO17: 해당 통제와 관련한 중요한 위험인 [내부회계관리제도 설계·운영 활동이 적격하지 않은 인원에 의해 수행되어 내부회계관리제도의 목적을 달성하지 못할 위험. ]에 대해 완전히 고려되고 있음. | BQ17: O | BS17: O | BW17: 내부회계관리제도 관련 규정의 수립 및 준수 | BX17: [현황] 현재는 비상장법인으로 내부회계관리제도의 운영의무가 없기 때문에 규정 및 조직이 구비되어 있지 아니함. [잠재적위험] 내부회계관리규정 및 조직의 미비로 인해 주식회사등의외부감사에관한법률상의 의무를 준수하지 못할 가능성이 존재함. | BY17: 향후 상장 시, 주식회사등의외부감사에관한법률 제8조에 따라 신뢰할 수 있는 회계정보의 작성과 공시를 위하여 다음 각 호의 사항이 포함된 내부회계관리규정과 이를 관리ㆍ운영하는 조직을 갖추어야 함. 1. 회계정보의 식별ㆍ측정ㆍ분류ㆍ기록 및 보고 방법에 관한 사항 2. 회계정보의 오류를 통제하고 이를 수정하는 방법에 관한 사항 3. 회계정보에 대한 정기적인 점검 및 조정 등 내부검증에 관한 사항 4. 회계정보를 기록ㆍ보관하는 장부의 관리 방법과 위조ㆍ변조ㆍ훼손 및 파기를 방지하기 위한 통제 절차에 관한 사항 5. 회계정보의 작성 및 공시와 관련된 임직원의 업무 분장과 책임에 관한 사항 6. 그 밖에 신뢰할 수 있는 회계정보의 작성과 공시를 위하여 필요한 사항으로서 대통령령으로 정하는 사항
A18: 1 | B18: EL | C18: 전사 | D18: EL-010 | E18: 통제환경 | F18: EL-010-110 | G18: EL-010-110-10 | H18: 노정희 유헌종 | I18: 내부회계관리조직이 충분한 능력을 보유하지 못해 내부회계관리제도의 목적을 달성하지 못할 위험 | J18: Low | K18: Low | L18: Low | M18: Low | N18: Low | O18: LR | P18: 내부회계관리제도 설계·운영 활동은 적격한 인원에 의해 수행되고, 이에 대한 평가가 이루어져야 합니다. | Q18: 내부회계관리제도 적격성 평가 | R18: 적격성 기준에 부합한 임직원에 의해 내부회계관리제도가 설계 및 운영되는지 평가된다. | S18: Yes | Y18: O | Z18: P | AA18: M | AB18: O | AC18: O | AD18: O | AE18: O | AF18: O | AG18: O | AH18: O | AI18: N/A | AJ18: A | AK18: N/A | AL18: N/A | AM18: N/A | AN18: L | AO18: L | AP18: L | AQ18: L | AR18: L | AS18: L | AT18: L | AU18: L | AV18: Not Higher | AW18: 1. '내부회계관리업무지침'에 따라 내부회계관리규정을 관리·운영하는 임직원 및 회계정보를 작성하는 임직원(대표자 등)의 적격성을 정의하고 있으며, 통제수행자 및 통제평가자에 대해서는 별도의 적격성 Template을 활용하여 평가하고 있다. 2. 재무보고 및 내부회계관리제도 관련 외부서비스제공자 선정 시 다음과 같은 항목들의 적격성 기준에 따른 평가 절차를 수립·운영한다. - 외부서비스제공자의 경험, 전문성, 기술적 역량, 평판 - 공급업체 관련 회사의 정책 및 윤리적 기준 | AX18: N/A | BA18: O | BC18: 적격성 Template /OSP List | BD18: A | BE18: 1 | BF18: 【문서검사】 1. 통제기술서에서 통제수행자의 적격성을 평가하고 있는지 확인한다. 2. 평가기간의 적격성 Template이 작성되었는지 확인한다. 3. 평가기간 중 신규 계약된 '외부서비스제공자' 중 샘플링 후, 외부서비스제공자 선정 시 다음 항목에 대한 적격성 평가가 이루어지는지 확인한다. - 외부서비스제공자의 경험, 전문성, 기술적 역량, 평판 - 공급업체 관련 회사의 정책 및 윤리적 기준 | BG18: 경영지원팀 전결권자 | BH18: RCM상 '관련 정책 및 문서'를 확인한 결과 통제활동은 해당 정책과 연계되어 있음을 확인함. | BI18: RCM상 기재된 관련 통제위험을 감소시킬수 있도록 통제가 효과적으로 설계 되었음 | BJ18: 예외사항은 해당 통제의 수행시 오류가 발생할 경우로 정의하며, 추가절차를 위해 별도로 설정한 threshold는 없으며, 예외사항 발생시 즉시 추가적인 절차를 취하도록 설계됨. | BK18: 통제를 수행하는데 사용된 정보에 대한 컨트롤이 적절히 수행되고 있음. | BL18: 해당 사업연도 초에 통제가 설계되었으며, 설계이후 해당 통제의 수행기간은 충분하다고 판단됨. | BM18: 업무경험과 교육이수 등을 고려할 때 통제 수행자의 적격성은 충분함 | BN18: 본 통제활동에서 다루는 내부회계관리제도 적격성 평가는 거래의 연간 발생 빈도 및 중요도를 고려하여 주기를 A로 설정하였으며 통제 수행빈도는 해당 위험의 적시 예방 적발을 위해 적절하다고 판단됨. | BO18: 해당 통제와 관련한 중요한 위험인 [내부회계관리조직이 충분한 능력을 보유하지 못해 내부회계관리제도의 목적을 달성하지 못할 위험 ]에 대해 완전히 고려되고 있음. | BQ18: O | BS18: O | BW18: 내부회계관리제도 관련 규정의 수립 및 준수 | BX18: [현황] 현재는 비상장법인으로 내부회계관리제도의 운영의무가 없기 때문에 규정 및 조직이 구비되어 있지 아니함. [잠재적위험] 내부회계관리규정 및 조직의 미비로 인해 주식회사등의외부감사에관한법률상의 의무를 준수하지 못할 가능성이 존재함. | BY18: 향후 상장 시, 주식회사등의외부감사에관한법률 제8조에 따라 신뢰할 수 있는 회계정보의 작성과 공시를 위하여 다음 각 호의 사항이 포함된 내부회계관리규정과 이를 관리ㆍ운영하는 조직을 갖추어야 함. 1. 회계정보의 식별ㆍ측정ㆍ분류ㆍ기록 및 보고 방법에 관한 사항 2. 회계정보의 오류를 통제하고 이를 수정하는 방법에 관한 사항 3. 회계정보에 대한 정기적인 점검 및 조정 등 내부검증에 관한 사항 4. 회계정보를 기록ㆍ보관하는 장부의 관리 방법과 위조ㆍ변조ㆍ훼손 및 파기를 방지하기 위한 통제 절차에 관한 사항 5. 회계정보의 작성 및 공시와 관련된 임직원의 업무 분장과 책임에 관한 사항 6. 그 밖에 신뢰할 수 있는 회계정보의 작성과 공시를 위하여 필요한 사항으로서 대통령령으로 정하는 사항
A19: 1 | B19: EL | C19: 전사 | D19: EL-010 | E19: 통제환경 | F19: EL-010-120 | G19: EL-010-120-10 | H19: 김세영 | I19: 내부회계관리제도 목적에 부합하지 않는 인력으로 인해 내부통제제도가 효과적으로 작동하지 못할 위험 | J19: Low | K19: Low | L19: Low | M19: Low | N19: Low | O19: LR | P19: 내부회계관리제도 설계∙운영에 필요한 수준의 인력이 확보되어 회사 내부통제의 효과성이 지속적으로 유지된다. | Q19: 내부회계관리제도에 대한 적격성 유지 프로그램 운영 | R19: 내부회계관리제도와 관련한 주요 조직 및 인력의 적격성 유지를 위해 정기 혹은 비정기적으로 교육프로그램이 계획되고 운영된다. | S19: Yes | Y19: O | Z19: P | AA19: M | AB19: O | AC19: O | AD19: O | AE19: O | AF19: O | AG19: O | AH19: O | AI19: N/A | AJ19: A | AK19: N/A | AL19: N/A | AM19: N/A | AN19: L | AO19: L | AP19: L | AQ19: L | AR19: L | AS19: L | AT19: L | AU19: L | AV19: Not Higher | AW19: 1. '내부회계관리규정 및 업무지침'에 따라 내부회계관리제도 관련 교육과 관련한 절차 및 지침을 문서화하고 '내부회계관리제도 관련 업무 수행 임직원'을 대상으로 다음과 같이 계획하고 교육 프로그램을 운영하고 있다. 1) 교육주제 - 내부회계관리제도의 이해 - 회계 및 내부회계관리제도 관련 법령, 기준 및 회사 규정의 제·개정 - 회계·재무 역량강화 교육 2) 교육대상 3) 교육일정 4) 진행방법(집합, 온라인 등) 5) 교육이수 모니터링 | AX19: N/A | BA19: O | BC19: 연간교육계획서 /내부회계관리 교육대상자 리스트 | BD19: A | BE19: 1 | BF19: 【문서검사】 1. 내부회계관리제도 역할별 담당자 리스트에서 샘플링하여 내부회계 교육 계획('연간교육계획')에 따라 교육활동이 수행되었는지 교육이수 현황을 확인한다. | BG19: 경영지원팀 전결권자 | BH19: RCM상 '관련 정책 및 문서'를 확인한 결과 통제활동은 해당 정책과 연계되어 있음을 확인함. | BI19: RCM상 기재된 관련 통제위험을 감소시킬수 있도록 통제가 효과적으로 설계 되었음 | BJ19: 예외사항은 해당 통제의 수행시 오류가 발생할 경우로 정의하며, 추가절차를 위해 별도로 설정한 threshold는 없으며, 예외사항 발생시 즉시 추가적인 절차를 취하도록 설계됨. | BK19: 통제를 수행하는데 사용된 정보에 대한 컨트롤이 적절히 수행되고 있음. | BL19: 해당 사업연도 초에 통제가 설계되었으며, 설계이후 해당 통제의 수행기간은 충분하다고 판단됨. | BM19: 업무경험과 교육이수 등을 고려할 때 통제 수행자의 적격성은 충분함 | BN19: 본 통제활동에서 다루는 내부회계관리제도에 대한 적격성 유지 프로그램 운영 는 거래의 연간 발생 빈도 및 중요도를 고려하여 주기를 A로 설정하였으며 통제 수행빈도는 해당 위험의 적시 예방 적발을 위해 적절하다고 판단됨. | BO19: 해당 통제와 관련한 중요한 위험인 [내부회계관리제도 목적에 부합하지 않는 인력으로 인해 내부통제제도가 효과적으로 작동하지 못할 위험 ]에 대해 완전히 고려되고 있음. | BQ19: O | BS19: O | BW19: 내부회계관리제도 관련 규정의 수립 및 준수 | BX19: [현황] 현재는 비상장법인으로 내부회계관리제도의 운영의무가 없기 때문에 규정 및 조직이 구비되어 있지 아니함. [잠재적위험] 내부회계관리규정 및 조직의 미비로 인해 주식회사등의외부감사에관한법률상의 의무를 준수하지 못할 가능성이 존재함. | BY19: 향후 상장 시, 주식회사등의외부감사에관한법률 제8조에 따라 신뢰할 수 있는 회계정보의 작성과 공시를 위하여 다음 각 호의 사항이 포함된 내부회계관리규정과 이를 관리ㆍ운영하는 조직을 갖추어야 함. 1. 회계정보의 식별ㆍ측정ㆍ분류ㆍ기록 및 보고 방법에 관한 사항 2. 회계정보의 오류를 통제하고 이를 수정하는 방법에 관한 사항 3. 회계정보에 대한 정기적인 점검 및 조정 등 내부검증에 관한 사항 4. 회계정보를 기록ㆍ보관하는 장부의 관리 방법과 위조ㆍ변조ㆍ훼손 및 파기를 방지하기 위한 통제 절차에 관한 사항 5. 회계정보의 작성 및 공시와 관련된 임직원의 업무 분장과 책임에 관한 사항 6. 그 밖에 신뢰할 수 있는 회계정보의 작성과 공시를 위하여 필요한 사항으로서 대통령령으로 정하는 사항
A20: 1 | B20: EL | C20: 전사 | D20: EL-010 | E20: 통제환경 | F20: EL-010-130 | G20: EL-010-130-10 | H20: 김세영 | I20: 내부회계관리제도 책임 이행에 적합한 성과 평가 및 보상 정책의 부재로 내부회계관리제도의 목적을 달성하지 못할 위험 | J20: Low | K20: Low | L20: Low | M20: Low | N20: Low | O20: LR | P20: 경영진과 이사회는 내부회계관리제도 목적 달성을 위해 내부회계관리제도 책임 이행과 그에 따른 성과 평가 및 보상을 연계한다. | Q20: 내부회계관리제도 책임 이행 결과를 성과평가와 연계 | R20: 내부회계관리제도 책임 이행과 연계하여 임직원의 성과평가에 반영하고 성과평가의 측정지표는 주기적으로 검토된다. | S20: Yes | Y20: O | Z20: P | AA20: M | AB20: O | AC20: O | AD20: O | AE20: O | AF20: O | AG20: O | AH20: O | AI20: N/A | AJ20: A | AK20: N/A | AL20: N/A | AM20: N/A | AN20: L | AO20: L | AP20: L | AQ20: L | AR20: L | AS20: L | AT20: L | AU20: L | AV20: Not Higher | AW20: 1. 내부회계관리제도 목표 달성을 위하여 성과 평가, 인센티브 및 보상 정책을 수립, 운영한다. - 내부회계관리제도의 중장기 목표를 달성하는데 필요한 조직의 임직원을 대상으로 함. - 내부회계관리제도 평가 결과를 성과평가 지표에 반영하여 인사 또는 보수와 연계함. 2. 이사회 및 경영진은 매년 설정된 내부회계관리제도 성과측정 지표에 대하여 다음 사항을 고려하여 주기적으로 적정성을 검토한다. - 평가지표가 의도한대로 작동하는지 여부(성과평가지표가 통제를 우회할 만한 과도한 압박을 초래하는지 여부 등) - 성과측정지표의 적정 여부 3. 이사회는 내부회계관리제도 성과평가가 적절하게 완료되었음을 관리감독하고 관련 보상계획을 승인한다. | AX20: N/A | BA20: O | BC20: 내부회계관리제도 성과평가 보고자료 /이사회의사록 | BD20: A | BE20: 1 | BF20: 【문서검사】 1. '내부회계관리규정 및 업무지침'에 내부회계관리제도 평가 결과와 성과평가 및 보상체계 등과 연계되는 정책 및 절차가 수립되어 있는지 확인한다. 2. '대표자 등'에 설정된 성과(또는 역량평가) 지표를 징구하여 다음과 같은 지표가 포함되었는지 확인한다. • 윤리적 가치 - 윤리교육 이수 - 윤리설문조사 응답 - 제도 제언 - 비윤리행위 적발 • 내부회계관리제도 및 재무보고 가치 - 내부회계관리제도 및 재무보고 관련 교육 이수 - 통제활동 지적사항 여부 (내부회계관리제도 설계/운영평가 결과 또는 외부감사인 검토 결과) 3. '이사회의사록'에 설정된 성과측정 지표에 대하여 아래와 같은 사항을 고려하여 적정성에 대한 검토가 이루어지고 있는지 확인한다. - 평가지표가 의도한대로 작동하는지 여부 - 성과측정지표의 적정 여부(과도한 압박 요인 등) 4. 평가기간 실시된 '이사회의사록'을 입수하여 성과평가가 적절하게 완료되었음을 관리·감독하고, 관련 보상 계획을 승인하였는지 확인한다. | BG20: 경영지원팀 전결권자 | BH20: RCM상 '관련 정책 및 문서'를 확인한 결과 통제활동은 해당 정책과 연계되어 있음을 확인함. | BI20: RCM상 기재된 관련 통제위험을 감소시킬수 있도록 통제가 효과적으로 설계 되었음 | BJ20: 예외사항은 해당 통제의 수행시 오류가 발생할 경우로 정의하며, 추가절차를 위해 별도로 설정한 threshold는 없으며, 예외사항 발생시 즉시 추가적인 절차를 취하도록 설계됨. | BK20: 통제를 수행하는데 사용된 정보에 대한 컨트롤이 적절히 수행되고 있음. | BL20: 해당 사업연도 초에 통제가 설계되었으며, 설계이후 해당 통제의 수행기간은 충분하다고 판단됨. | BM20: 업무경험과 교육이수 등을 고려할 때 통제 수행자의 적격성은 충분함 | BN20: 본 통제활동에서 다루는 내부회계관리제도 책임 이행 결과를 성과평가와 연계 는 거래의 연간 발생 빈도 및 중요도를 고려하여 주기를 A로 설정하였으며 통제 수행빈도는 해당 위험의 적시 예방 적발을 위해 적절하다고 판단됨. | BO20: 해당 통제와 관련한 중요한 위험인 [내부회계관리제도 책임 이행에 적합한 성과 평가 및 보상 정책의 부재로 내부회계관리제도의 목적을 달성하지 못할 위험 ]에 대해 완전히 고려되고 있음. | BQ20: O | BS20: O | BW20: 내부회계관리제도 관련 규정의 수립 및 준수 | BX20: [현황] 현재는 비상장법인으로 내부회계관리제도의 운영의무가 없기 때문에 규정 및 조직이 구비되어 있지 아니함. [잠재적위험] 내부회계관리규정 및 조직의 미비로 인해 주식회사등의외부감사에관한법률상의 의무를 준수하지 못할 가능성이 존재함. | BY20: 향후 상장 시, 주식회사등의외부감사에관한법률 제8조에 따라 신뢰할 수 있는 회계정보의 작성과 공시를 위하여 다음 각 호의 사항이 포함된 내부회계관리규정과 이를 관리ㆍ운영하는 조직을 갖추어야 함. 1. 회계정보의 식별ㆍ측정ㆍ분류ㆍ기록 및 보고 방법에 관한 사항 2. 회계정보의 오류를 통제하고 이를 수정하는 방법에 관한 사항 3. 회계정보에 대한 정기적인 점검 및 조정 등 내부검증에 관한 사항 4. 회계정보를 기록ㆍ보관하는 장부의 관리 방법과 위조ㆍ변조ㆍ훼손 및 파기를 방지하기 위한 통제 절차에 관한 사항 5. 회계정보의 작성 및 공시와 관련된 임직원의 업무 분장과 책임에 관한 사항 6. 그 밖에 신뢰할 수 있는 회계정보의 작성과 공시를 위하여 필요한 사항으로서 대통령령으로 정하는 사항
... A44: 1 | B44: EL | C44: 전사 | D44: EL-050 | E44: 모니터링 | F44: EL-050-70 | G44: EL-050-70-10 | H44: 김세영 | I44: 이사회 및 감사는 내부통제에 대한 감독기능의 미비로 외부 재무보고에 영향을 미치는 내부통제 미비점이 시정되지 않을 위험 | J44: Low | K44: Low | L44: Low | M44: Low | N44: Low | O44: LR | P44: 이사회 및 감사는 외부 재무보고에 영향을 미치는 내부통제 미비점에 관한 내용과 상황을 이해하고, 경영진의 결론과 시정 계획을 감독한다. | Q44: 미비점 평가 및 시정계획 감독 및 보고 | R44: 이사회 및 감사는 내부회계 운영실태를 평가하고 개선계획을 검토하여 보고한다. | S44: Yes | Y44: O | Z44: P | AA44: M | AB44: O | AC44: O | AD44: O | AE44: O | AF44: O | AG44: O | AH44: O | AI44: N/A | AJ44: A | AK44: N/A | AL44: N/A | AM44: N/A | AN44: L | AO44: L | AP44: L | AQ44: L | AR44: L | AS44: L | AT44: L | AU44: L | AV44: Not Higher | AW44: 1. 감사는 대표이사(또는 내부회계관리자)와의 대면회의를 통해 내부회계 운영실태 점검결과를 논의하고, 평가 수행 및 그 결과에 대한 내부회계관리제도 평가표를 작성한다. 2. 감사는 정기총회 개최 1주 전까지 내부회계관리제도 평가보고서를 이사회에 대면 보고한다. | AX44: N/A | BA44: O | BC44: 내부회계관리제도 평가표, 감사의 평가보고서, 이사회의사록 | BD44: A | BE44: 1 | BF44: 【문서검사】 1. 감사의 평가내역 및 평가보고서, 이사회 의사록을 징구하여 다음을 확인한다. - 감사는 대표이사(또는 내부회계관리자)와의 대면회의를 통해 내부회계평가를 수행하였는지 여부 - 감사는 내부회계관리제도 운영 실태를 평가하고, 평가결과는 적절히 문서화되었는지 여부 2. '이사회의사록'을 통해 감사가 정기총회 개최 1주전까지 내부회계관리제도 평가보고서를 이사회 대면보고 하였는지 여부를 확인한다. | BG44: 경영지원팀 전결권자 | BH44: RCM상 '관련 정책 및 문서'를 확인한 결과 통제활동은 해당 정책과 연계되어 있음을 확인함. | BI44: RCM상 기재된 관련 통제위험을 감소시킬수 있도록 통제가 효과적으로 설계 되었음 | BJ44: 예외사항은 해당 통제의 수행시 오류가 발생할 경우로 정의하며, 추가절차를 위해 별도로 설정한 threshold는 없으며, 예외사항 발생시 즉시 추가적인 절차를 취하도록 설계됨. | BK44: 통제를 수행하는데 사용된 정보에 대한 컨트롤이 적절히 수행되고 있음. | BL44: 해당 사업연도 초에 통제가 설계되었으며, 설계이후 해당 통제의 수행기간은 충분하다고 판단됨. | BM44: 업무경험과 교육이수 등을 고려할 때 통제 수행자의 적격성은 충분함 | BN44: 본 통제활동에서 다루는 미비점 평가 및 시정계획 감독 및 보고는 거래의 연간 발생 빈도 및 중요도를 고려하여 주기를 A로 설정하였으며 통제 수행빈도는 해당 위험의 적시 예방 적발을 위해 적절하다고 판단됨. | BO44: 해당 통제와 관련한 중요한 위험인 [이사회 및 감사는 내부통제에 대한 감독기능의 미비로 외부 재무보고에 영향을 미치는 내부통제 미비점이 시정되지 않을 위험 ]에 대해 완전히 고려되고 있음. | BQ44: O | BS44: O | BW44: 내부회계관리제도 관련 규정의 수립 및 준수 | BX44: [현황] 현재는 비상장법인으로 내부회계관리제도의 운영의무가 없기 때문에 규정 및 조직이 구비되어 있지 아니함. [잠재적위험] 내부회계관리규정 및 조직의 미비로 인해 주식회사등의외부감사에관한법률상의 의무를 준수하지 못할 가능성이 존재함. | BY44: 향후 상장 시, 주식회사등의외부감사에관한법률 제8조에 따라 신뢰할 수 있는 회계정보의 작성과 공시를 위하여 다음 각 호의 사항이 포함된 내부회계관리규정과 이를 관리ㆍ운영하는 조직을 갖추어야 함. 1. 회계정보의 식별ㆍ측정ㆍ분류ㆍ기록 및 보고 방법에 관한 사항 2. 회계정보의 오류를 통제하고 이를 수정하는 방법에 관한 사항 3. 회계정보에 대한 정기적인 점검 및 조정 등 내부검증에 관한 사항 4. 회계정보를 기록ㆍ보관하는 장부의 관리 방법과 위조ㆍ변조ㆍ훼손 및 파기를 방지하기 위한 통제 절차에 관한 사항 5. 회계정보의 작성 및 공시와 관련된 임직원의 업무 분장과 책임에 관한 사항 6. 그 밖에 신뢰할 수 있는 회계정보의 작성과 공시를 위하여 필요한 사항으로서 대통령령으로 정하는 사항
A45: 7 | B45: SD | C45: 매출관리 | D45: SD-010 | E45: 주문 및 거래관리 | F45: SD-010-10 | G45: SD-010-10-10 | H45: 솔루션사업팀 | I45: 1. 고객주문 내용이 완전하게 파악되지 아니하여 잘못된 구매가 발생할 위험 2. 중요한 비경상적인 거래가 통제되지 아니할 위험 | J45: Low | K45: High | L45: Low | M45: Low | N45: Low | O45: LR | P45: 주문은 정확하고 완전하게 처리되어야 한다. | Q45: 견적서 제출전 사전 타당성검토 | R45: 견적서의 제출 시 권한있는 승인권자가 금액 및 거래조건 등에 대하여 승인하고 문서화하여야 한다. | S45: Yes | T45: O | W45: O | Y45: O | Z45: P | AA45: M | AB45: O | AC45: O | AD45: O | AG45: O | AI45: 매출, 매출채권, 계약자산, 계약부채, 부가가치세예수금 | AJ45: D | AK45: N/A | AL45: N/A | AM45: N/A | AN45: L | AO45: H | AP45: L | AQ45: L | AR45: L | AS45: L | AT45: L | AU45: L | AV45: Not Higher | AW45: 1. 고객으로부터 구두 혹은 이메일로 구매요청을 수령하면, 고객이 요구하는 내용 및 가이드라인에 근거하여 영업담당자는 판매가 및 대금 결제조건을 결정함. 2. 작성된 견적서(제안서)는 상위권자에게 문서화를 통하여 보고되며 상위권자의 결제를 득함. | AX45: 1. 고객사로부터의 주문을 접수 시 제안서 또는 견적서를 작성하여 제출함. 2. 제안서 또는 견적서에 대한 문서화된 승인절차는 없으며, 해당 영업팀장에게 구두 보고 후 제출하고 있음. 3. 판매단가의 경우 제품별로 사전에 정해진 가이드라인이 정해져 있으며, 50% 이상의 할인율을 적용할경우 사업본부장에게 이메일로 보고 후 제출하고 있음. | BA45: O | BC45: 매출전표 | BD45: A | BE45: 2 | BF45: 【질문, 문서검사】 1. 솔루션사업본부의 영업담당자에게 견적서(제안서)가 상위권자 승인을 받고 있는지 질문한다. 2. 표본기간 중의 매출전표을 모집단으로 하여 표본수에 해당하는 표본을 추출한다. 2. 표본으로 선정된 매출계약에 대한 견적서(제안서)가 상위권자의 문서화된 결제를 득하였는지 문서검사를 실시한다. | BG45: 솔루션사업본부 전결권자 | BH45: RCM상 '관련 정책 및 문서'를 확인한 결과 통제활동은 해당 정책과 연계되어 있음을 확인함. | BI45: RCM상 기재된 관련 통제위험을 감소시킬수 있도록 통제가 효과적으로 설계 되었음 | BJ45: 예외사항은 해당 통제의 수행시 오류가 발생할 경우로 정의하며, 추가절차를 위해 별도로 설정한 threshold는 없으며, 예외사항 발생시 즉시 추가적인 절차를 취하도록 설계됨. | BK45: 통제를 수행하는데 사용된 정보에 대한 컨트롤이 적절히 수행되고 있음. | BL45: 해당 사업연도 초에 통제가 설계되었으며, 설계이후 해당 통제의 수행기간은 충분하다고 판단됨. | BM45: 업무경험과 교육이수 등을 고려할 때 통제 수행자의 적격성은 충분함 | BN45: 본 통제활동에서 다루는 견적서 제출전 사전 타당성검토는 거래의 연간 발생 빈도 및 중요도를 고려하여 주기를 D로 설정하였으며 통제 수행빈도는 해당 위험의 적시 예방 적발을 위해 적절하다고 판단됨. | BO45: 해당 통제와 관련한 중요한 위험인 [1. 고객주문 내용이 완전하게 파악되지 아니하여 잘못된 구매가 발생할 위험 2. 중요한 비경상적인 거래가 통제되지 아니할 위험 ]에 대해 완전히 고려되고 있음. | BQ45: O | BS45: O | BW45: 견적서(제안서)에 대한 문서화된 승인 | BX45: [현황] 솔루션사업부 내 영업담당자는 견적서(제안서)를 작성 후 상위권자에게 구두 또는 이메일로 보고되고 있으나, 견적서(제안서)의 승인 여부에 대한 별도의 문서화가 이루어지지 않고 있음. [잠재적 위험] 승인권자의 승인이 이루어지지 않은 견적서(제안서)가 제출되어 오류 및 부정이 발생할 수 있는 매출거래가 발생할 위험이 존재함. 또한, 내부회계관리제도 문서화 측면에서 구두 보고는 실제로 통제활동이 이루어지지 않았다고 간주될 수 있음. | BY45: [개선안] 영업담당자가 작성한 견적서(제안서)가 고객사에 제출되기 전에 승인권자의 문서화된 승인을 득함으로서 잘못된 견적서가 제출될 위험을 감소시키는 업무프로세스가 구축되어야 할 것으로 판단됨.
A46: 7 | B46: SD | C46: 매출관리 | D46: SD-010 | E46: 주문 및 거래관리 | F46: SD-010-10 | G46: SD-010-10-20 | H46: 솔루션사업팀 | I46: 검토되지 않은 부적절한 계약으로 매출인식의 오류 및 부정이 발생할 위험 | J46: Low | K46: High | L46: Low | M46: Low | N46: Low | O46: LR | P46: 매출계약은 정당한 승인절차를 거쳐 체결된다. | Q46: 매출계약 승인 | R46: 매출계약은 품의서에 따라 권한있는 승인권자의 검토 및 승인에 따라 체결된다. | S46: Yes | T46: O | U46: O | Y46: O | Z46: P | AA46: M | AB46: O | AC46: O | AD46: O | AG46: O | AH46: O | AI46: 매출, 매출채권, 계약자산, 계약부채, 부가가치세예수금 | AJ46: D | AK46: N/A | AL46: N/A | AM46: N/A | AN46: L | AO46: H | AP46: L | AQ46: H | AR46: L | AS46: L | AT46: L | AU46: L | AV46: Not Higher | AW46: 1. 제안 내용이 채택되어 최종 가격 및 판매조건에 대한 협상이 완료되면 계약서를 작성하며, 계약에 대한 품의서를 작성하여 상위권자의 승인을 받고 있음. | AX46: 1. 제안 내용이 채택되어 최종 가격 및 판매조건에 대한 협상이 완료되면 계약서를 작성하며, 영업담당자는 견적서와 함께 이메일로 경영지원팀장에게 검토를 요청함. 2. 경영지원팀장은 계약서 검토 후 이상이 없는 경우 구두 또는 이메일로 회신하고 있음. | BA46: O | BC46: 매출전표 | BD46: A | BE46: 2 | BF46: 【문서검사】 1. 표본기간 중의 매출전표을 모집단으로 하여 표본수에 해당하는 표본을 추출한다. 2. 표본으로 선정된 매출건에 대한 계약체결품의서 및 계약서가 작성되었는지 확인한다. 3. 품의서상 계약조건이 제안서와 일치하며, 경영지원팀장의 승인을 득하였음을 확인한다. | BG46: 경영지원팀 전결권자 | BH46: RCM상 '관련 정책 및 문서'를 확인한 결과 통제활동은 해당 정책과 연계되어 있음을 확인함. | BI46: RCM상 기재된 관련 통제위험을 감소시킬수 있도록 통제가 효과적으로 설계 되었음 | BJ46: 예외사항은 해당 통제의 수행시 오류가 발생할 경우로 정의하며, 추가절차를 위해 별도로 설정한 threshold는 없으며, 예외사항 발생시 즉시 추가적인 절차를 취하도록 설계됨. | BK46: 통제를 수행하는데 사용된 정보에 대한 컨트롤이 적절히 수행되고 있음. | BL46: 해당 사업연도 초에 통제가 설계되었으며, 설계이후 해당 통제의 수행기간은 충분하다고 판단됨. | BM46: 업무경험과 교육이수 등을 고려할 때 통제 수행자의 적격성은 충분함 | BN46: 본 통제활동에서 다루는 매출계약 승인는 거래의 연간 발생 빈도 및 중요도를 고려하여 주기를 D로 설정하였으며 통제 수행빈도는 해당 위험의 적시 예방 적발을 위해 적절하다고 판단됨. | BO46: 해당 통제와 관련한 중요한 위험인 [검토되지 않은 부적절한 계약으로 매출인식의 오류 및 부정이 발생할 위험 ]에 대해 완전히 고려되고 있음. | BQ46: O | BS46: O | BW46: 매출계약서에 대한 문서화된 승인 | BX46: [현황] 매출계약의 체결 시 이메일로 경영지원팀장에게 계약서에 대한 검토를 요청하고 있으나, 승인여부에 대한 별도의 문서화가 이루어지지 않고 있음. [잠재적 위험] 매출계약서에 대한 승인권자의 검토 및 승인이 이루어지지 않은 계약이 체결되어 오류 또는 부정이 발생할 위험이 존재함. 또한, 내부회계관리제도 문서화 측면에서 구두 보고는 실제로 통제활동이 이루어지지 않았다고 간주될 수 있음. | BY46: [개선안] 매출계약서는 사전에 정해진 체크리스트를 통해 검토가 이뤄지고, 권한있는 승인권자는 체크리스트 및 계약의 주요한 조건에 대한 검토를 실시하는 업무프로세스가 구축되어야 함. 매출계약 체결에 대하여 승인권자의 문서화된 승인을 득한 이후 계약서의 법인인감날인이 이뤄지게 함으로서 잘못된 매출계약이 체결될 위험을 감소시키는 업무프로세스가 구축되어야 함.
A47: 13 | B47: SD | C47: 매출관리 | D47: SD-020 | E47: 매출기록 및 청구 | F47: SD-020-10 | G47: SD-020-10-10 | H47: 솔루션사업팀 | I47: 매출인식이 부정확하게 기록되어 매출의 측정 및 기간귀속에 왜곡표시가 발생할 위험 | J47: High | K47: High | L47: High | M47: High | N47: Low | O47: SR | P47: 수익은 완전하고 정확하게 집계되어 처리되어야 한다. | Q47: 매출전표의 승인 | R47: 매출은 관련 증빙에 따라 권한있는 승인권자의 검토 및 승인절차를 통해 기록된다. | S47: Yes | T47: O | U47: O | Z47: P | AA47: M | AD47: O | AE47: O | AF47: O | AG47: O | AH47: O | AI47: 매출, 매출채권, 계약자산, 계약부채, 부가가치세예수금 | AJ47: D | AK47: N/A | AL47: 더존 | AM47: N/A | AN47: L | AO47: H | AP47: H | AQ47: H | AR47: L | AS47: H | AT47: H | AU47: L | AV47: Higher | AW47: 1. 솔루션사업본부 담당자는 고객사 확인을 받은 납품확인서, 인증서, 검수확인서, 견적서, 계약서 등을 첨부하여 세금계산서발행요청서 기재하여 경영지원팀에게 세금계산서 발행을 요청함. 2. 경영지원팀장은 관련 증빙을 확인 후 세금계산서발행요청서를 승인하며, 세금계산서 발행 후 매출전표를 작성하여 경영지원팀장의 승인을 받음. 3. 경영지원팀 담당자는 월별로 매출 발생 내역을 엑셀로 정리하여 경영지원팀장, 대표이사에게 보고하고 있으며, 이를 통해 매출누락 여부 등이 확인됨. | AX47: 1. 영업부 담당자는 계약서, 견적서를 첨부한 세금계산서발행요청서를 작성하여 영업팀장의 승인을 득한 후 경영지원팀에 세금계산서 발행을 요청함. 2. 세금계산서발행요청서 상 납품확인서, 인증서, 검수확인서 등 매출 완료 여부를 확인할 수 있는 증빙은 첨부되고 있지 아니함. 2. 세금계산서 발행 후 매출전표를 작성하고 있으며, 별도로 경영지원팀장의 승인을 득하고 있지 아니함. 3. 월별로 매출내역은 대표이사에게 보고되고 있음. | BA47: O | BC47: 매출전표 | BD47: A | BE47: 15 | BF47: 【문서검사】 1. 표본기간 중의 매출전표을 모집단으로 하여 표본수에 해당하는 표본을 추출한다. 2. 표본으로 선정된 매출건에 대하여 관련 증빙(검수확인서, 납품확인서, 인증서, 계약서 등)과 세금계산서발행요청서, 매출전표과 일치하는지 여부를 확인한다. 3. 세금계산서 발행요청서와 매출전표는 경영지원팀장의 승인을 득하였는지 확인한다. | BG47: 경영지원팀 전결권자 | BH47: RCM상 '관련 정책 및 문서'를 확인한 결과 통제활동은 해당 정책과 연계되어 있음을 확인함. | BI47: RCM상 기재된 관련 통제위험을 감소시킬수 있도록 통제가 효과적으로 설계 되었음 | BJ47: 예외사항은 해당 통제의 수행시 오류가 발생할 경우로 정의하며, 추가절차를 위해 별도로 설정한 threshold는 없으며, 예외사항 발생시 즉시 추가적인 절차를 취하도록 설계됨. | BK47: 통제를 수행하는데 사용된 정보에 대한 컨트롤이 적절히 수행되고 있음. | BL47: 해당 사업연도 초에 통제가 설계되었으며, 설계이후 해당 통제의 수행기간은 충분하다고 판단됨. | BM47: 업무경험과 교육이수 등을 고려할 때 통제 수행자의 적격성은 충분함 | BN47: 본 통제활동에서 다루는 매출전표의 승인는 거래의 연간 발생 빈도 및 중요도를 고려하여 주기를 D로 설정하였으며 통제 수행빈도는 해당 위험의 적시 예방 적발을 위해 적절하다고 판단됨. | BO47: 해당 통제와 관련한 중요한 위험인 [매출인식이 부정확하게 기록되어 매출의 측정 및 기간귀속에 왜곡표시가 발생할 위험 ]에 대해 완전히 고려되고 있음. | BQ47: O | BS47: O | BW47: 매출 발생 증빙에 대한 검토 | BX47: [현황] 솔루션사업부 내 영업담당자는 세금계산서 발행 요청 시 견적서, 계약서를 첨부한 세금계산서발행요청서를 작성하여 경영지원팀에 요청하고 있으나, 실제 납품이 이뤄졌음을 확인할 수 있는 증빙(납품확인서, 검수확인서, 인증서 등)에 대한 검토는 경영지원팀에서 이뤄지고 있지 아니함. 세금계산서발행요청서에 대하여 경영지원팀장의 승인이 이루어지지 않고 있음. [잠재적 위험] 세금계산서의 발급이 적절히 이뤄지지 않아 매출인식이 부정확하게 기록되어 매출의 측정 및 기간귀속에 왜곡표시가 발생할 위험이 존재함. | BY47: [개선안] 경영지원팀 담당자는 견적서, 계약서 외에 실제 납품의 발생사실을 확인할 수 있는 증빙을 입수하여 검토하는 업무프로세스가 구축되어야 함. 세금계산서 발행요청서는 승인권자의 문서화된 승인을 득함으로서 매출이 부적확하게 기록될 위험을 감소시키는 업무프로세스가 구축되어야 함.
A48: 2 | B48: SD | C48: 매출관리 | D48: SD-020 | E48: 매출기록 및 청구 | F48: SD-020-30 | G48: SD-020-20-30 | H48: 이단비 | I48: 유지보수매출에 대한 계산이 정확하고 완전하게 계산되지 않아 왜곡표시가 발생할 위험 | J48: Low | K48: Low | L48: High | M48: Low | N48: High | O48: HR | P48: 유지보수매출은 정확하게 완전하게 기록된다 | Q48: 유지보수매출 조정 | R48: 유지보수 매출 관련 조정분개는 정확하게 계산되어야 하고, 정확성을 확보할 수 있도록 적절한 검토가 이루어져야 한다. | S48: Yes | T48: O | U48: O | W48: O | X48: O | Z48: P | AA48: M | AB48: O | AC48: O | AD48: O | AE48: O | AH48: O | AI48: 매출, 매출채권, 계약자산, 계약부채 | AJ48: Q | AK48: Y | AL48: 더존 | AM48: 유지보수매출 계산파일 | AN48: H | AO48: L | AP48: H | AQ48: L | AR48: L | AS48: L | AT48: L | AU48: L | AV48: Not Higher | AW48: 전결권자는 담당자가 작성한 유지보수매출 조정관련 회계전표와 첨부된 검증내역 대해 다음의 관점에서 검토 후 승인한다. - 소프트웨어 매출 조정파일의 내용의 관련 매출계약서상의 내용과 일치하는지를 확인 - 회계처리에 사용된 유지보수 매출 인식 스케쥴이 최초 유지보수 매출계산시 사용된 스케쥴표와 변경되었는지 여부에 대한 확인 - 유지보수 매출계산에 있어 사용된 로직의 변경사항이 존재하는지와 산출된 계산내역이 적절한지를 확인함. | AX48: IFRS적용에 따른 유지보수매출 조정과 관련한 프로세스는 현재 별도로 존재하지 않음 | BA48: O | BC48: 유지보수매출 조정전표 | BD48: A | BE48: 2 | BF48: 【문서검사】 1. 표본기간 중의 유지보수매출 조정전표을 모집단으로 하여 표본수에 해당하는 표본을 추출한다. 2. 표본으로 선정된 매출전표 상 계약부채, 계약자산 금액과 경영지원팀 담당자가 작성한 유지보수매출 조정 엑셀파일이 일치하는지 확인한다. 3. 유지보수매출 계산에 사용된 계약정보가 계약서상 기재된 정보(계약금액, 유지보수기간)와 일치하는지 확인한다. 4. 유지보수 조정전표가 경영지원팀장의 승인을 받았는지 확인한다. | BG48: 경영지원팀 전결권자 | BH48: RCM상 '관련 정책 및 문서'를 확인한 결과 통제활동은 해당 정책과 연계되어 있음을 확인함. | BI48: RCM상 기재된 관련 통제위험을 감소시킬수 있도록 통제가 효과적으로 설계 되었음 | BJ48: 예외사항은 해당 통제의 수행시 오류가 발생할 경우로 정의하며, 추가절차를 위해 별도로 설정한 threshold는 없으며, 예외사항 발생시 즉시 추가적인 절차를 취하도록 설계됨. | BK48: 통제를 수행하는데 사용된 정보에 대한 컨트롤이 적절히 수행되고 있음. | BL48: 해당 사업연도 초에 통제가 설계되었으며, 설계이후 해당 통제의 수행기간은 충분하다고 판단됨. | BM48: 업무경험과 교육이수 등을 고려할 때 통제 수행자의 적격성은 충분함 | BN48: 본 통제활동에서 다루는 유지보수매출 조정는 거래의 연간 발생 빈도 및 중요도를 고려하여 주기를 Q로 설정하였으며 통제 수행빈도는 해당 위험의 적시 예방 적발을 위해 적절하다고 판단됨. | BO48: 해당 통제와 관련한 중요한 위험인 [유지보수매출에 대한 계산이 정확하고 완전하게 계산되지 않아 왜곡표시가 발생할 위험 ]에 대해 완전히 고려되고 있음. | BQ48: O | BS48: O | BW48: 유지보수매출 조정에 대한 검증절차 | BX48: [현황] S/W 매출은 S/W 공급과 유지보수용역의 수행의무로 분리됨에 따라 유지보수 수행의무에 대한 매출인식의 조정이 이뤄지고 있음. 유지보수매출의 조정은 엑셀파일로 이뤄지고 있으나 이에 대한 상위권자에 의한 검토 및 승인절차가 구비되어 있지 아니함. [잠재적위험] 유지보수매출 조정 전표가 부정확하게 계산되거나 부적절하게 기록되어 재무제표에 왜곡이 발생할 위험 | BY48: 적절한 상위권자가 유지보수매출 조정 계산내역을 확인하고 조정전표와 계산파일 상의 결과값이 일치하는지 검토 후 전표를 승인하는 프로세스를 구축할 것을 권고함.
A49: 2 | B49: SD | C49: 매출관리 | D49: SD-030 | E49: 채권관리 및 대손상각 | F49: SD-030-10 | G49: SD-030-10-10 | H49: 이단비 | I49: 채권이 거래처별, 만기별, 신용거래한도내 거래가 관리되지 아니하여 부실채권이 발생할 위험 | J49: Low | K49: Low | L49: Low | M49: Low | N49: Low | O49: LR | P49: 매출채권은 적절하게 관리되어야 한다. | Q49: 거래처별, 만기별, 신용거래 한도내 채권관리 | R49: 매출채권은 거래처별, 만기별,신용거래 한도내 거래가 되도록 관리되어야 한다. | S49: Yes | T49: O | U49: O | Y49: O | Z49: P | AA49: M | AD49: O | AE49: O | AH49: O | AI49: 매출채권, 계약자산, 대손충당금, 대손상각비 | AJ49: M | AK49: N/A | AL49: N/A | AM49: N/A | AN49: L | AO49: H | AP49: L | AQ49: H | AR49: L | AS49: H | AT49: H | AU49: L | AV49: Higher | AW49: 1. 여신관리 규정이 제정되어 적용되고 있으며, 여신관리 규정에 따라 일정 신용등급 이하의 거래처에 대해서는 여신한도를 부여함. 2. 매출계약체결 품의서 작성 시 해당 거래처의 여신한도 및 채권잔액을 기재하여 여신한도를 초과한 주문접수를 방지하고 있음. | AX49: 1. 별도의 여신한도를 설정하고 있지 아니하며, 신규거래처의 경우 별도로 거래처에 대한 신용조사는 이뤄지고 있지 아니함. | BA49: O | BC49: 매출전표 | BD49: A | BE49: 2 | BF49: 【문서검사】 1. 여신관리 규정이 제정되어 적용되고 있는지 질문한다. 2. 표본기간 중의 매출전표을 모집단으로 하여 표본수에 해당하는 표본을 추출한다. 3. 표본으로 선정된 매출에 대한 계약체결품의서 상 여신한도 및 채건잔액을 기재하고 있는지 문서검사한다. | BG49: 경영지원팀 내 채권담당자 | BH49: RCM상 '관련 정책 및 문서'를 확인한 결과 통제활동은 해당 정책과 연계되어 있음을 확인함. | BI49: RCM상 기재된 관련 통제위험을 감소시킬수 있도록 통제가 효과적으로 설계 되었음 | BJ49: 예외사항은 해당 통제의 수행시 오류가 발생할 경우로 정의하며, 추가절차를 위해 별도로 설정한 threshold는 없으며, 예외사항 발생시 즉시 추가적인 절차를 취하도록 설계됨. | BK49: 통제를 수행하는데 사용된 정보에 대한 컨트롤이 적절히 수행되고 있음. | BL49: 해당 사업연도 초에 통제가 설계되었으며, 설계이후 해당 통제의 수행기간은 충분하다고 판단됨. | BM49: 업무경험과 교육이수 등을 고려할 때 통제 수행자의 적격성은 충분함 | BN49: 본 통제활동에서 다루는 거래처별, 만기별, 신용거래 한도내 채권관리는 거래의 연간 발생 빈도 및 중요도를 고려하여 주기를 M로 설정하였으며 통제 수행빈도는 해당 위험의 적시 예방 적발을 위해 적절하다고 판단됨. | BO49: 해당 통제와 관련한 중요한 위험인 [채권이 거래처별, 만기별, 신용거래한도내 거래가 관리되지 아니하여 부실채권이 발생할 위험 ]에 대해 완전히 고려되고 있음. | BQ49: O | BS49: O | BW49: 고객신용평가절차 및 여신관리규정 구비 | BX49: [현황] 신규거래 발생 시 고객에 대한 신용조사가 이뤄지고 있지 아니하며, 기존 고객에 대하여 신용평가가 주기적으로 이뤄지고 있지 아니함 고객에 대한 신용등급 및 담보력 평가에 대한 여신관리 규정이 미비함. [잠재적 위험] 여신관리의 미비로 인해 부실채권 발생을 예방하지 못할 위험 | BY49: 신규 고객에 대한 거래 발생 시 거래처의 신용평가서, 재무제표 등을 입수하여 경영지원팀에서 고객에 대한 신용거래 여부에 대한 승인을 득하는 업무프로세스를 구축하여야 함. 고객을 신용등급에 따라 구분하여 신용등급이 일정 등급 이하인 고객에 대해서는 여신한도를 설정하고, 여신한도를 초과하는 거래에 대해서는 신규 수주를 방지하는 등의 내용이 담긴 여신한도 규정을 신설하여 부실채권의 발생을 예방하는 업무프로세스를 구축하여야 함.
A50: 3 | B50: SD | C50: 매출관리 | D50: SD-030 | E50: 채권관리 및 대손상각 | F50: SD-030-20 | G50: SD-030-20-10 | H50: 이단비 | I50: 주기적으로 업체별 채권현황 및 지연현황이 보고되지 않아 부실채권이 발생할 위험 | J50: High | K50: High | L50: Low | M50: Low | N50: Low | O50: HR | P50: 미회수채권은 지연사유가 명확히 규명,관리되어야 한다. | Q50: 채권관리현황보고 | R50: 미회수채권은 그 발생원인이 규명되어야 하며 주기적인 상위권자 보고를 통하여 관리되어야 한다. | S50: Yes | U50: O | X50: O | Z50: P | AA50: M | AD50: O | AE50: O | AG50: O | AH50: O | AI50: 매출채권, 계약자산, 대손충당금, 대손상각비 | AJ50: M | AK50: N/A | AL50: 더존 | AM50: N/A | AN50: L | AO50: H | AP50: L | AQ50: L | AR50: L | AS50: H | AT50: H | AU50: L | AV50: Not Higher | AW50: 1. <xxx실, 팀>담당자는 각 거래처별 대금 회수 조건을 관리하고 있으며, 매월말 대금 회수 기간이 경과하였음에도 회수되지 않는 채권에 대해서는 매월말 집계하여 영업담당자에게 통보함. 2. 각 영업담당자는 원인을 조사하여 경영지원팀 담당자 및 경영지원팀장에게 문서로 보고함. 3. 경영지원팀 담당자는 경영지원팀의 승인을 받은 문서에 근거하여 회계처리를 함. | AX50: 1. <xxx실, 팀>담당자는 각 거래처별 대금 회수 조건을 관리하고 있으며, 매월말 대금 회수 기간이 경과하였음에도 회수되지 않는 채권에 대해서는 매월말 집계하여 영업담당자에게 통보함. 2. 각 영업담당자는 원인을 조사하여 경영지원팀 담당자 및 경영지원팀장에게 문서로 보고함. | BA50: O | BC50: 회수기간 초과 채권 확인요청 리스트 | BD50: A | BE50: 2 | BF50: 【질문, 문서검사】 1. 경영지원팀 담당자가 매월 대금 회수 기간을 경과한 채권이 있는지 여부를 검토하고 있는지 질문한다. 2. 회수기간 경과채권에 대해서는 경영지원팀장에게 보고 및 승인 받은 문서를 확인하고, 승인 받은 내용대로 회계처리되었는지 회계전표를 확인한다. | BG50: 경영지원팀 내 채권담당자 | BH50: RCM상 '관련 정책 및 문서'를 확인한 결과 통제활동은 해당 정책과 연계되어 있음을 확인함. | BI50: RCM상 기재된 관련 통제위험을 감소시킬수 있도록 통제가 효과적으로 설계 되었음 | BJ50: 예외사항은 해당 통제의 수행시 오류가 발생할 경우로 정의하며, 추가절차를 위해 별도로 설정한 threshold는 없으며, 예외사항 발생시 즉시 추가적인 절차를 취하도록 설계됨. | BK50: 통제를 수행하는데 사용된 정보에 대한 컨트롤이 적절히 수행되고 있음. | BL50: 해당 사업연도 초에 통제가 설계되었으며, 설계이후 해당 통제의 수행기간은 충분하다고 판단됨. | BM50: 업무경험과 교육이수 등을 고려할 때 통제 수행자의 적격성은 충분함 | BN50: 본 통제활동에서 다루는 채권관리현황보고는 거래의 연간 발생 빈도 및 중요도를 고려하여 주기를 M로 설정하였으며 통제 수행빈도는 해당 위험의 적시 예방 적발을 위해 적절하다고 판단됨. | BO50: 해당 통제와 관련한 중요한 위험인 [주기적으로 업체별 채권현황 및 지연현황이 보고되지 않아 부실채권이 발생할 위험 ]에 대해 완전히 고려되고 있음. | BQ50: O | BS50: O
A51: 2 | B51: SD | C51: 매출관리 | D51: SD-030 | E51: 채권관리 및 대손상각 | F51: SD-030-40 | G51: SD-030-40-10 | H51: 노정희 | I51: 대손충당금이 과소/과다계상되어 채권잔액이 부적절하게 평가될 위험 | J51: Low | K51: Low | L51: High | M51: Low | N51: High | O51: HR | P51: 대손충당금은 정확하게 완전하게 기록된다 | Q51: 대손충당금의 설정 | R51: 대손충당금은 정확하게 계산되어야 하고, 정확성을 확보할 수 있도록 적절한 검토가 이루어져야 한다. | S51: Yes | T51: O | U51: O | W51: O | X51: O | Z51: P | AA51: M | AB51: O | AC51: O | AD51: O | AE51: O | AH51: O | AI51: 매출채권, 계약자산, 대손충당금, 대손상각비 | AJ51: Q | AK51: Y | AL51: 더존 | AM51: 대손충당금계산파일 | AN51: H | AO51: H | AP51: H | AQ51: L | AR51: L | AS51: H | AT51: L | AU51: L | AV51: Higher | AW51: 1. 경영지원팀 담당자는 채권 명세서를 기초로 대손충당금 금액을 산출한 후 계산내역을 첨부하여 대손충당금 전표를 상신한다. 2. 전결권자는 담당자가 작성한 대손충당금 회계전표와 첨부된 대손충당금 계산내역에 대하 다음의 관점에서 검토 후 승인한다. - 계산파일 상의 매출채권 잔액이 결산일 현재 매출채권 잔액과 일치하는지를 확인 - 연령분석표 상 매출채권의 연령이 ERP 상에서 산출된 연령과 일치하는지를 확인 - 손실률 추정에 대한 계산로직의 변경사항이 존재하는지와 산출된 계산내역이 적절한지 확인 | AX51: IFRS적용에 따른 대손충당금 조정과 관련한 프로세스는 현재 별도로 존재하지 않음 | BA51: O | BC51: 매출채권 대손전표 | BD51: A | BE51: 2 | BF51: 【문서검사】 1. 표본기간 중의 대손충당금 전표을 모집단으로 하여 표본수에 해당하는 표본을 추출한다. 2. 표본으로 선정된 기간에 대한 대손충당금 결산전표와 계산근거를 수령한다. 3. 전표 금액과 계산 근거가 일치하는지 확인한다. 4. 대손충당금 전표 상 경영지원팀장의 승인이 있는지 확인한다. | BG51: 경영지원팀 전결권자 | BH51: RCM상 '관련 정책 및 문서'를 확인한 결과 통제활동은 해당 정책과 연계되어 있음을 확인함. | BI51: RCM상 기재된 관련 통제위험을 감소시킬수 있도록 통제가 효과적으로 설계 되었음 | BJ51: 예외사항은 해당 통제의 수행시 오류가 발생할 경우로 정의하며, 추가절차를 위해 별도로 설정한 threshold는 없으며, 예외사항 발생시 즉시 추가적인 절차를 취하도록 설계됨. | BK51: 통제를 수행하는데 사용된 정보에 대한 컨트롤이 적절히 수행되고 있음. | BL51: 해당 사업연도 초에 통제가 설계되었으며, 설계이후 해당 통제의 수행기간은 충분하다고 판단됨. | BM51: 업무경험과 교육이수 등을 고려할 때 통제 수행자의 적격성은 충분함 | BN51: 본 통제활동에서 다루는 대손충당금의 설정는 거래의 연간 발생 빈도 및 중요도를 고려하여 주기를 Q로 설정하였으며 통제 수행빈도는 해당 위험의 적시 예방 적발을 위해 적절하다고 판단됨. | BO51: 해당 통제와 관련한 중요한 위험인 [대손충당금이 과소/과다계상되어 채권잔액이 부적절하게 평가될 위험 ]에 대해 완전히 고려되고 있음. | BQ51: O | BS51: O | BW51: 대손충당금 검증 및 승인절차 | BX51: [현황] 대손충당금은 채권연령분석표에 따라 엑셀파일로 계산되고 있으나 계산파일에 대한 상위권자에 의한 검토 및 대손충당금 전표에 대한 승인절차가 구비되어 있지 아니함. [잠재적위험] 대손충당금 계산내역에 대한 상위권자의 검토 및 승인절차가 구비되어 있지 않음에 따라 조정전표가 부적절하게 기표되어 재무제표에 왜곡이 발생할 위험 | BY51: 상위권자가 분기별로 계산된 대손충당금 산출내역을 확인하고 관련전표와 계산파일 상의 내역이 일치하는지 검토 후 승인하는 프로세스를 개선할 것을 권고함.
A52: 1 | B52: SD | C52: 매출관리 | D52: SD-040 | E52: 마스터 데이터 관리 | F52: SD-040-10 | G52: SD-040-10-20 | H52: 채새롬 이단비 | I52: 승인 받지 않은 고객정보가 입력되어 마스터테이터가 부적절하게 등록될 위험. 권한없는 자의 마스터데이터 접근으로 인하여 잘못된 정보가 입력될 위험. | J52: Low | K52: Low | L52: Low | M52: Low | N52: Low | O52: LR | P52: 마스터 데이터는 정확하게 관리되어야 한다. | Q52: 고객마스터데이터에 대한 접근통제 | R52: 고객파일에 대한 접근은 수정권한이 있는 부서로 한정되어 관리되어야 한다. | S52: Yes | U52: O | V52: O | W52: O | Y52: O | Z52: P | AA52: M | AD52: O | AF52: O | AH52: O | AI52: 매출, 매출채권, 계약자산, 계약부채, 부가가치세예수금 | AJ52: A | AK52: N/A | AL52: 더존 | AM52: N/A | AN52: L | AO52: L | AP52: L | AQ52: L | AR52: L | AS52: L | AT52: L | AU52: L | AV52: Not Higher | AW52: 1. 신규 거래처 등록이나 변경 등록 시, 영업담당자는 고객정보변경/등록요청서를 작성하여 담당부서장의 승인을 받고 있으며, 승인 받은 요청서에 근거하여 접근권한을 부여 받은 경영지원팀 담당자가 등록을 하고 있음. | AX52: 1. 거래처 마스터파일은 영업팀에서 관리하고 있으며, 세금계산서 발행 등은 각 부서에서 건별로 요청시 첨부된 자료에 따라 이루어지고 있음. | BA52: O | BC52: 접근권한 리스트 | BD52: A | BE52: 1 | BF52: 【문서검사】 1. 접근권한 리스트를 요청하여 담당자 이외의 자의 접근이 가능한지 문서검사한다. | BG52: 경영지원팀 내 채권담당자 | BH52: RCM상 '관련 정책 및 문서'를 확인한 결과 통제활동은 해당 정책과 연계되어 있음을 확인함. | BI52: RCM상 기재된 관련 통제위험을 감소시킬수 있도록 통제가 효과적으로 설계 되었음 | BJ52: 예외사항은 해당 통제의 수행시 오류가 발생할 경우로 정의하며, 추가절차를 위해 별도로 설정한 threshold는 없으며, 예외사항 발생시 즉시 추가적인 절차를 취하도록 설계됨. | BK52: 통제를 수행하는데 사용된 정보에 대한 컨트롤이 적절히 수행되고 있음. | BL52: 해당 사업연도 초에 통제가 설계되었으며, 설계이후 해당 통제의 수행기간은 충분하다고 판단됨. | BM52: 업무경험과 교육이수 등을 고려할 때 통제 수행자의 적격성은 충분함 | BN52: 본 통제활동에서 다루는 고객마스터데이터에 대한 접근통제는 거래의 연간 발생 빈도 및 중요도를 고려하여 주기를 A로 설정하였으며 통제 수행빈도는 해당 위험의 적시 예방 적발을 위해 적절하다고 판단됨. | BO52: 해당 통제와 관련한 중요한 위험인 [승인 받지 않은 고객정보가 입력되어 마스터테이터가 부적절하게 등록될 위험. 권한없는 자의 마스터데이터 접근으로 인하여 잘못된 정보가 입력될 위험. ]에 대해 완전히 고려되고 있음. | BQ52: O | BS52: O | BW52: 고객마스터에 대한 접근권한 관리 | BX52: [현황] 고객마스터파일은 영업팀에서 관리하고 있으며, 고객마스터파일에 대한 접근 및 변경권한은 제한되어 있지 아니함. [잠재적 위험] 고객마스터에 대한 접근 통제 미비로 가공의 거래처 등록을 예방하지 못할 위험 | BY52: 고객마스터파일은 중앙(경영지원팀 등)에서 일원적으로 관리하여야 하며, 각 인원별로 접근권한을 부여하고 접근권한리스트를 주기적으로 확인하여 권한부여가 적절하게 되어 있는지 확인해야 함
A53: 7 | B53: TR | C53: 자금관리 | D53: TR-010 | E53: 입출금관리 | F53: TR-010-10 | G53: TR-010-10-10 | H53: 이단비 | I53: 대금의 입금은 정당한 절차를 거쳐 이루어지고, 입금내역은 적시에 적절한 회계계정으로 기록되어야 한다. | J53: Low | K53: high | L53: Low | M53: Low | N53: Low | O53: LR | P53: 대금의 입금이 정당한 절차를 거치지 않을 경우 입금의 누락이 발생할 수 있으며, 입금내역이 적시에 기록되지 않거나 정확한 상대계정이 부여되지 않을 경우, 예금 및 채권이 정확하지 않게 재무제표에 기표될 가능성이 존재함. | Q53: 입금내역의 반영 | R53: 입금내역은 적시에 장부에 반영되어야 한다. | S53: Yes | U53: O | X53: O | Y53: O | Z53: P | AA53: M | AB53: O | AD53: O | AG53: O | AI53: 현금성자산, 매출채권 | AJ53: D | AK53: N/A | AL53: 더존 | AM53: N/A | AN53: L | AO53: H | AP53: L | AQ53: L | AR53: L | AS53: L | AT53: L | AU53: L | AV53: Not Higher | AW53: 1. 회사는 대부분의 매출대금을 현금으로 회수하고 있으며, 일부거래처에 대해서는 전자어음을 수령하고 있음(전자어음의 경우 은행을 통해 만기 입금이 이루어짐) 2. 경영지원팀의 자금담당자는 수시로 통장상의 입금내역을 확인(주거래통장은 더존과 연동되어 수시로 확인, 기타 통장은 월별로 확인)하며, 입금발생시 영업부서에 입금내역에 대한 통지를 실시함. 3. 입금내역에 대한 영업부서의 확인 후 경영지원팀 담당자는 입금전표를 작성하고관련 증빙을 첨부하여 전결권자로부터의 검토 및 승인을 진행하고 있으며, 입금내역이 반영된 자금일계표를 작성하여 일계표에 대한 승인절차를 진행함. | AX53: 1. 회사는 대부분의 매출대금을 현금으로 회수하고 있으며, 일부거래처에 대해서는 전자어음을 수령하고 있음(전자어음의 경우 은행을 통해 만기 입금이 이루어짐) 2. 별도의 자금과 관련한 일마감 절차 등은 수행하고 있지 않으며, 이에 따라 즉시 입금처리가 이루어지지 않는 경우가 존재함. | BA53: O | BC53: 통장, 회계전표, 일계표 | BD53: A | BE53: 7 | BF53: 【문서검사】 1. 표본기간 중의 보통예금통장상의 입금내역을 모집단으로 하여 표본수에 해당하는 표본을 추출한다. 2. 보통예금통장상의 입금내역과 매출채권 회수 관련 회계전표의 입금일자가 일치하는지 확인한다. 3. 보통예금 입금일의 일계표를 징구하여 일계표상 동 입금내역이 적절히 기재되어 있음을 확인한다. | BG53: 경영지원팀 자금전결권자 | BH53: RCM상 '관련 정책 및 문서'를 확인한 결과 통제활동은 해당 정책과 연계되어 있음을 확인함. | BI53: RCM상 기재된 관련 통제위험을 감소시킬수 있도록 통제가 효과적으로 설계 되었음 | BJ53: 예외사항은 해당 통제의 수행시 오류가 발생할 경우로 정의하며, 추가절차를 위해 별도로 설정한 threshold는 없으며, 예외사항 발생시 즉시 추가적인 절차를 취하도록 설계됨. | BK53: 통제를 수행하는데 사용된 정보에 대한 컨트롤이 적절히 수행되고 있음. | BL53: 해당 사업연도 초에 통제가 설계되었으며, 설계이후 해당 통제의 수행기간은 충분하다고 판단됨. | BM53: 업무경험과 교육이수 등을 고려할 때 통제 수행자의 적격성은 충분함 | BN53: 본 통제활동에서 다루는 입금내역의 반영는 거래의 연간 발생 빈도 및 중요도를 고려하여 주기를 D로 설정하였으며 통제 수행빈도는 해당 위험의 적시 예방 적발을 위해 적절하다고 판단됨. | BO53: 해당 통제와 관련한 중요한 위험인 [대금의 입금은 정당한 절차를 거쳐 이루어지고, 입금내역은 적시에 적절한 회계계정으로 기록되어야 한다. ]에 대해 완전히 고려되고 있음. | BQ53: O | BS53: O | BW53: 입금관련 업무분장 및 채권의 회수관리 | BX53: [현황] 자금 담당자는 매출발생시 전표처리를 실시하고, 매출채권 입금시에는 통장에서 입금내역(입금자, 입금액, 입금일자)을 확인하고, 직접 입금처리를 실시하는 한편, 월별로 거래처별 채권리스트를 작성하여 영업부서에 전달하고 있음. . 자금담당자는 통장별로 입금과 출금, 잔액을 확인할 수 있으나 동 거래내역을 근거로 즉시 전표처리를 실시하지 않으며, 일부 채권에 대해서는 월차 결산시에 일괄하여 전표처리를 실시함. [잠재적위험] 실질적인 매출채권의 관리부서인 영업부서가 아닌 경영지원팀에서 매출의 회계처리, 채권의 관리 및 입금에 대한 회계처리를 실시하고 있음에 따라, 매출계상 및 입금내역에 대한 부적절한 회계처리가 발생할 가능성이 있으며, 업무분장의 관점에서 적절하지 않음. 또한, 입금과 관련한 회계처리가 즉시 이루어져 관련 회계처리에 대한 검토가 이루어지지 않음에 따라, 회계처리상의 오류를 적시에 발견하지 못할 수 있으며, 거래처의 회수지연 등의 사유에 대해서 지속적인 관리가 이루어지지 않을 수 있음. | BY53: 입금과 관련한 내역을 채권의 관리 담당부서인 영업부서에서 직접 확인하여 회계처리를 실시하고, 경영지원팀에서는 회계처리 및 자금운용 관점에서 이를 검토하도록 업무분장을 구분하는 것이 적절함. 또한, 입금과 관련한 회계처리는 입금 즉시 이루어지는 한편 자금현황에 반영되어 장부상잔액과 자금현황이 일치하는지에 대해 수시로 검토 및 보고하는 프로세스가 구축되어야 함.
A54: 7 | B54: TR | C54: 자금관리 | D54: TR-010 | E54: 입출금관리 | F54: TR-010-10 | G54: TR-010-10-20 | H54: 이단비 | I54: 대금의 입금은 정당한 절차를 거쳐 이루어지고, 입금내역은 적시에 적절한 회계계정으로 기록되어야 한다. | J54: Low | K54: high | L54: Low | M54: Low | N54: Low | O54: LR | P54: 대금의 입금이 정당한 절차를 거치지 않을 경우 입금의 누락이 발생할 수 있으며, 입금내역이 적시에 기록되지 않거나 정확한 상대계정이 부여되지 않을 경우, 예금 및 채권이 정확하지 않게 재무제표에 기표될 가능성이 존재함. | Q54: 입금의 반제처리 | R54: 입금내역은 관련 채권과 적절히 상계되고 검토되어야 한다. | S54: Yes | T54: O | U54: O | X54: O | Y54: O | Z54: P | AA54: M | AB54: O | AC54: O | AG54: O | AI54: 현금성자산, 매출채권 | AJ54: D | AK54: N/A | AL54: 더존 | AM54: N/A | AN54: L | AO54: H | AP54: L | AQ54: L | AR54: L | AS54: L | AT54: L | AU54: L | AV54: Not Higher | AW54: 1. 경영지원팀의 자금담당자는 입금발생시 영업부서에 입금내역에 대한 통지를 실시함. 2. 경영지원실에서는 입금내역을 확인하여 영업부서에 공유함. 3. 경영지원실의 자금담당자는 채권과 입금액을 상계하는 입금전표를 작성함. 4. 경영지원팀에서는 월별로 입금처리가 완료된 거래처별 채권리스트를 작성하여 영업팀에 송부하며, 영업팀에서는 관리하고 있는 채권리스트와 경영지원팀에서 송부된 회계상의 채권리스트가 일치하는지에 대한 확인을 실시함. | AX54: 1. 경영지원팀의 자금담당자는 입금내역에 대해 경영지원팀에서 관리하고 있는 거래처별 채권리스트와 비교확인을 실시함. 2. 주거래통장과 과련한 입금처리는 더존의 입금전송기능을 사용하여 채권과의 매칭을 통해 수행하고, 기타의 통장과 관련한 입금처리는 직접 전표를 작성하고 있음. 3. 입금처리에 있어 확인이 어려운 채권이 존재하는 경우 영업팀에 채권리스트를 송부하여 해당 채권에 대한 문의를 진행하고 있으며, 월별로 입금처리가 완료된 거래처별 채권리스트를 작성하여 영업팀에 송부하고 있음. | BA54: O | BC54: 통장, 회계전표, 매출채권명세서 | BD54: A | BE54: 7 | BF54: 【문서검사】 1. 표본기간 중의 보통예금통장상의 입금내역을 모집단으로 하여 표본수에 해당하는 표본을 추출한다. 2. 보통예금통장상의 입금내역과 매출채권 회수 관련 회계전표의 거래처, 입금액이 일치하는지 확인한다. 3. 해당 입금된 금액과 관련한 매출채권 계상전표를 징구하여 매출채권계상액과 입금액이 일치하는지를 확인하고, 차이가 발생한 경우에는 차이내역에 대해 문의한다. | BG54: 경영지원팀 자금전결권자 | BH54: RCM상 '관련 정책 및 문서'를 확인한 결과 통제활동은 해당 정책과 연계되어 있음을 확인함. | BI54: RCM상 기재된 관련 통제위험을 감소시킬수 있도록 통제가 효과적으로 설계 되었음 | BJ54: 예외사항은 해당 통제의 수행시 오류가 발생할 경우로 정의하며, 추가절차를 위해 별도로 설정한 threshold는 없으며, 예외사항 발생시 즉시 추가적인 절차를 취하도록 설계됨. | BK54: 통제를 수행하는데 사용된 정보에 대한 컨트롤이 적절히 수행되고 있음. | BL54: 해당 사업연도 초에 통제가 설계되었으며, 설계이후 해당 통제의 수행기간은 충분하다고 판단됨. | BM54: 업무경험과 교육이수 등을 고려할 때 통제 수행자의 적격성은 충분함 | BN54: 본 통제활동에서 다루는 입금의 반제처리는 거래의 연간 발생 빈도 및 중요도를 고려하여 주기를 D로 설정하였으며 통제 수행빈도는 해당 위험의 적시 예방 적발을 위해 적절하다고 판단됨. | BO54: 해당 통제와 관련한 중요한 위험인 [대금의 입금은 정당한 절차를 거쳐 이루어지고, 입금내역은 적시에 적절한 회계계정으로 기록되어야 한다. ]에 대해 완전히 고려되고 있음. | BQ54: O | BS54: O | BW54: 입금관련 업무분장 및 채권의 회수관리 | BX54: [현황] 자금 담당자는 매출발생시 전표처리를 실시하고, 매출채권 입금시에는 통장에서 입금내역(입금자, 입금액, 입금일자)을 확인하고, 직접 입금처리를 실시하는 한편, 월별로 거래처별 채권리스트를 작성하여 영업부서에 전달하고 있음. . 자금담당자는 통장별로 입금과 출금, 잔액을 확인할 수 있으나 동 거래내역을 근거로 즉시 전표처리를 실시하지 않으며, 일부 채권에 대해서는 월차 결산시에 일괄하여 전표처리를 실시함. [잠재적위험] 실질적인 매출채권의 관리부서인 영업부서가 아닌 경영지원팀에서 매출의 회계처리, 채권의 관리 및 입금에 대한 회계처리를 실시하고 있음에 따라, 매출계상 및 입금내역에 대한 부적절한 회계처리가 발생할 가능성이 있으며, 업무분장의 관점에서 적절하지 않음. 또한, 입금과 관련한 회계처리가 즉시 이루어져 관련 회계처리에 대한 검토가 이루어지지 않음에 따라, 회계처리상의 오류를 적시에 발견하지 못할 수 있으며, 거래처의 회수지연 등의 사유에 대해서 지속적인 관리가 이루어지지 않을 수 있음. | BY54: 입금과 관련한 내역을 채권의 관리 담당부서인 영업부서에서 직접 확인하여 회계처리를 실시하고, 경영지원팀에서는 회계처리 및 자금운용 관점에서 이를 검토하도록 업무분장을 구분하는 것이 적절함. 또한, 입금과 관련한 회계처리는 입금 즉시 이루어지는 한편 자금현황에 반영되어 장부상잔액과 자금현황이 일치하는지에 대해 수시로 검토 및 보고하는 프로세스가 구축되어야 함.
