Workbook
Name _: #REF!
Name _.4: #REF!
Name _1: #REF!
Name _10: #REF!
Name _10T1: #REF!
Name _10T2: #REF!
Name _10월: #REF!
Name _11월: #REF!
Name _12월: #REF!
Name _13a1_: #REF!
Name _14A17000_: #REF!
Name _15P1_: #REF!
Name _16p11_: #REF!
Name _17p2_: #REF!
Name _1월: #REF!
Name _2_?: #REF!
Name _20: #REF!
Name _20T1: #REF!
Name _20T2: #REF!
Name _2월: #REF!
Name _3월: #REF!
Name _4_?__C: #REF!
Name _40: #REF!
Name _40T1: #REF!
Name _40T2: #REF!
Name _4월: #REF!
Name _50: #REF!
Name _50T1: #REF!
Name _50T2: #REF!
Name _5납품기록PGM__.통합: #REF!
Name _5월: #REF!
Name _6_2000년입출고: #REF!
Name _60: #REF!
Name _60T1: #REF!
Name _60T2: #REF!
Name _6월: #REF!
Name _70T1: #REF!
Name _70T2: #REF!
Name _7월: #REF!
Name _8월: #REF!
Name _90: #REF!
Name _90T1: #REF!
Name _90T2: #REF!
Name _9월: #REF!
Name _A100000: #REF!
Name _A70000: #REF!
Name _E100000: #REF!
Name _MAP1: #REF!
Name _POP1: #REF!
Name _POP2: #REF!
Name _Report: "Sensitivity Table"
Name _Threshold: #REF!
Name _ZEBITDA_Sensitivity: {0;0;0;0;5;1;0.75;0;0;0;2;FALSE;FALSE;FALSE;FALSE;FALSE;#N/A;1;100;#N/A;#N/A;"";""}
Name _ZSensitivity_Table: {0;0;0;0;5;1;0.75;0;0;0;2;FALSE;FALSE;FALSE;FALSE;FALSE;#N/A;1;100;#N/A;#N/A;"";""}
Name \d: #REF!
Name \SC: #REF!
Name \x: #REF!
Name a: #REF!
Name aa: #REF!
Name AAAAAA: #REF!

Sheet 총괄
B2: 주식회사 사이냅소프트
B4: 내부회계관리제도 Scoping
C7: 0. 내부회계관리제도
D9: 내부회계관리제도는 회사의 재무제표가 일반적으로 인정되는 회계처리기준(이하 “회계처리기준”이라 함)에 따라 작성·공시되었는지에 대한 합리적 확신을 제공하기 위해 설계·운영되는 내부통제제도의 일부분으로서 회사의 경영진과 이사회를 포함한 모든 구성원들에 의해 지속적으로 실행되는 과정을 의미
C12: 1. Planning & Scoping Table 개관
D14: 이 문서는 내부회계관리제도의 Planning & Scoping을 위한 목적으로 작성됨
C17: 2. 내부회계관리제도 평가절차
D19: Step | H19: Document
D21: 가. | E21: 유의한 계정과목 및 주석정보의 파악
E23: ① 양적 중요성 기준의 결정 | H23: 1. 중요성 기준
E24: ② 질적 중요성의 고려 & ③ 유의한 계정과목 및 주석정보의 파악 | H24: 2.1 유의한 계정과목 (BS)
H25: 2.2 유의한 계정과목 (PL)
H26: 2.3 유의한 주석
H27: 2.4 유의한 영업현금 관련항목
D31: 다. | E31: 유의한 업무프로세스 파악 및 유의적 계정과목과 연계
E34: ① 유의한 계정과목과 업무프로세스의 연계 | H34: 2.1 유의한 계정과목 (BS)
H35: 2.2 유의한 계정과목 (PL)
H36: 2.3 유의한 주석
H37: 2.4 유의한 영업현금 관련항목
D39: 라. | E39: GITC Scoping 검토 - Risk로 부터 식별된 IT Element | H39: 3. GITC Scoping

Sheet 1. 중요성 기준
B2: 중요성 기준 설정 (Materiality)
C4: 1. 중요성 기준 결정
D6: [내부회계관리기준 설계운영 적용기법_6.3 중요성의 고려 ]
D7: 57 계정과목 및 주석정보가 개별적 또는 다른 계정과목이나 주석정보와 결합하여 재무제표의 중요한 왜곡표시가 합리적인 수준 이상으로 발생 가능하다면, 이를 유의한 계정과목 및 주석정보(“유의한 계정과목 등”)라 한다.
D9: 58 경영진은 다음과 같은 양적 요소와 질적 요소를 모두 고려하여 외부 재무보고의 유의한 계정과목 등을 선정한다.
D10: • 재무제표 정보이용자가 누구인지
D11: • 재무제표 정보이용자의 판단이나 의사결정에 중요한 영향을 미치는 항목
D12: • 재무제표 요소의 크기 (예: 유동 자산, 유동 부채, 총자산, 총수익, 순이익) 및 재무제표 종류 (예: 재무상태표, 손익계산서, 현금흐름표)
D13: • 회사 업종의 특성
D14: • 잔액이나 특정 거래 평가가 어려운 정도
D15: • 재무제표의 주요 추세(예: 이익, 매출, 현금흐름 등)
D17: [내부회계관리기준 설계운영 적용기법_7.2 계정과목 등에 대한 위험 평가 ]
D18: 64 하기와 같은 양적 요소와 질적 요소를 고려하여 주요 재무제표 항목별 잠재적인 중요한 왜곡표시 발생 위험을 평가하고 그 결과를 높음, 중간 및 낮음 등으로 분류한다. 만일 특정 계정에 속하는 세부 계정에 따라 위험의 정도가 다른 경우
D19: 세부 계정의 수준에서 계정의 위험의 정도를 결정한다. 위험을 식별하고 분석하는 절차는 다음을 포함하는 양적 요소와 질적 요소를 모두 고려한다. 이러한 위험평가결과와 위험 대응 방안은 감사(위원회) 및 내부회계관리자의 확인과 검토가
... D30: • 세전순이익이 영업의 규모를 적절히 반영하지 못하는 경우
C33: 2. 양적 중요성 기준
D35: 가. 과거 3개년 주요 benchmark | G35: (단위: 원)
D36: 구분 | F36: FY2022 | G36: FY2021
D37: 매출 | F37: 11141354865 | G37: 8915413700 | H37: IFRS변환 후 재무제표
D38: 세전이익 | F38: 4818843993 | G38: 3792692890
D39: 조정세전순이익* | F39: =F46 -> 4818843993 | G39: =G46 -> 3792692890
D42: * 조정세전순이익
D43: 세전이익 | F43: =F38 -> 4818843993 | G43: =G38 -> 3792692890
D44: 조정 | H44: 유의적인 비경상 거래 등 미발생
D46: 조정후 세전순이익 | F46: =SUM(F43:F45) -> 4818843993 | G46: =G43-SUM(G45:G45) -> 3792692890
D49: 나. Benchmark
D50: 구 분 | F50: benchmark 1 | G50: benchmark 2
D51: Benchmark: | F51: 조정 세전순이익 | G51: 영업수익(매출액)
D52: Benchmark balance | F52: =F46 -> 4818843993 | G52: =F37 -> 11141354865
D53: Factor: | F53: 0.05 | G53: 0.005 | H53: =Notes!B4 -> Note 1
D54: Calculated amount: | F54: =ROUND(F52*F53,) -> 240942200 | G54: =ROUND(G52*G53,) -> 55706774
D56: 다. 양적중요성 기준 설정
D58: ① Materiality by Entity: | G58: =ROUND(F54,-3) -> 240942000 | H58: 원
D60: ② 유의한 왜곡표시 금액 설정율 | G60: 0.7 | H60: =Notes!B8 -> Note 2
D62: ③ 유의한 왜곡표시 금액기준(Significant Misstatement Threshold) | G62: =ROUND(G58*G60,) -> 168659400 | H62: 원
D65: <설정근거>
D66: 설정근거 : 평가기간의 세전이익로 선정하는 이유는 다음과 같음.
D67: 세전이익의 경우 내부회계관리제도모범규준에서 중요성 금액 산정시 일반적으로 권고하는 benchmark에 해당함.
D68: 회사의 주요영업이 해외 자회사를 통해 발생하고 있으며, 자회사의 성과가 배당금수익을 통해 실현되고 있다는 점 및 이러한 점에서 회사의 규모대비 매출액이 적다는 점에서 세전이익을 근거로 중요성을 설정함.
C72: 3. 질적 중요성 기준 | E72: [내부회계관리제도 평가 및 보고 적용기법: 질적요소 42]
...

Sheet 2.1 유의한 계정과목(BS)
B2: 유의한 계정과목 및 공시(BS)
B4: 1. 일반사항
B5: - 이 Spreadsheet는 회사의 재무제표상 계정과목에 대한 질적 중요성을 측정하는데 그 목적이 있음
B7: 2. 질적중요성의 판단
B8: - 양적 기준 검토 결과 "N"라고 파악된 계정과목 및 주석정보에 대하여 2차적으로 질적중요성 검토를 수행함
B9: - 계정과목 및 주석사항에 대하여 10가지 질적 요소에 대한 평가를 통해 Risk Rating을 실시
B10: - Risk Rating은 단순평균방식으로 계산되며, Rating결과가 2(Medium)을 초과할 경우 질적으로 중요하다고 판단함
B12: High | C12: 3
B13: Medium | C13: 2
B14: Low | C14: 1
D16: (단위 : 원) | F16: 계정과목 내 개별 거래의 복잡성, 동질성 | G16: 추정이나 판단이 개입되는 회계처리 및 평가 | H16: 회계처리 및 보고의 복잡성 | I16: 우발채무의 발생가능성 | J16: 특수관계자와 유의적 거래의 존재 여부 | K16: 계정과목 성격의 변화 및 당기 금액 변화 정도 | L16: 비 경상적인 거래 | M16: 관련 회계처리 기준의 변경 | N16: 법규 및 감독당국의 강조 사항 | O16: 주요한 외부환경의 변화가 존재하는 계정 | T16: 매출관리 | U16: 경비관리 | V16: 자금관리 | W16: 재무결산및보고 | X16: 급여및인사관리 | Y16: 고정자산관리
B17: 계정과목 | C17: FY2022 | D17: FY2021 | E17: 양적 유의여부(2022) | F17: 질적기준 | P17: 질적 유의여부 | Q17: 질적판단 근거(note1) | R17: 유의성 결론
B18: 자산
B19: Ⅰ. 유 동 자 산 | C19: =C20+C34 -> 13384335493 | D19: =D20+D34 -> 12853911767
B20: (1) 당 좌 자 산 | C20: =SUM(C21:C33) -> 13384335493 | D20: =SUM(D21:D33) -> 12853911767
B21: 현금및현금성자산 | C21: 6005655731 | D21: 10824294574 | E21: =+IF(ABS($C21)>='1. 중요성 기준'!$G$62,"Y","N") -> Y | F21: Low | G21: Low | H21: Low | I21: Low | J21: Low | K21: Low | L21: Low | M21: Low | N21: Low | O21: Low | P21: =IF(SUM(COUNTIF($F21:$O21,"High")*$C$12+COUNTIF($F21:$O21,"Medium")*$C$13+COUNTIF($F21:$O21,"Low")*$C$14)/10>=2,"Y","N") -> N | R21: =IF(COUNTIF($E21:$P21,"Y")>0,"Y","N") -> Y | V21: O | W21: △
B22: 단기금융상품 | C22: 3000000000 | D22: 0 | E22: =+IF(ABS($C22)>='1. 중요성 기준'!$G$62,"Y","N") -> Y | P22: =IF(SUM(COUNTIF($F22:$O22,"High")*$C$12+COUNTIF($F22:$O22,"Medium")*$C$13+COUNTIF($F22:$O22,"Low")*$C$14)/10>=2,"Y","N") -> N | R22: =IF(COUNTIF($E22:$P22,"Y")>0,"Y","N") -> Y | V22: O | W22: △
B23: 매출채권 | C23: 1719683514 | D23: 1742611903 | E23: =+IF(ABS($C23)>='1. 중요성 기준'!$G$62,"Y","N") -> Y | F23: Low | G23: Low | H23: Low | I23: Low | J23: Low | K23: Low | L23: Low | M23: Low | N23: Low | O23: Low | P23: =IF(SUM(COUNTIF($F23:$O23,"High")*$C$12+COUNTIF($F23:$O23,"Medium")*$C$13+COUNTIF($F23:$O23,"Low")*$C$14)/10>=2,"Y","N") -> N | R23: =IF(COUNTIF($E23:$P23,"Y")>0,"Y","N") -> Y | T23: O | V23: O | W23: △
B24: 대손충당금(매출채권) | C24: -1077067 | D24: -69715814 | E24: =+IF(ABS($C24)>='1. 중요성 기준'!$G$62,"Y","N") -> N | F24: High | G24: High | H24: Medium | I24: Low | J24: Low | K24: High | L24: Low | M24: Low | N24: High | O24: Medium | P24: =IF(SUM(COUNTIF($F24:$O24,"High")*$C$12+COUNTIF($F24:$O24,"Medium")*$C$13+COUNTIF($F24:$O24,"Low")*$C$14)/10>=2,"Y","N") -> Y | Q24: 추정이나 판단의 개입이 존재할 수 있는 항목으로 질적으로 중요하다고 판단함. | R24: =IF(COUNTIF($E24:$P24,"Y")>0,"Y","N") -> Y | T24: O | W24: △
B25: 단기매매증권(FVPL) | C25: 314997332 | E25: =+IF(ABS($C25)>='1. 중요성 기준'!$G$62,"Y","N") -> Y | P25: =IF(SUM(COUNTIF($F25:$O25,"High")*$C$12+COUNTIF($F25:$O25,"Medium")*$C$13+COUNTIF($F25:$O25,"Low")*$C$14)/10>=2,"Y","N") -> N | R25: =IF(COUNTIF($E25:$P25,"Y")>0,"Y","N") -> Y | V25: O | W25: △
B26: 매도가능증권(FVOCI) | C26: 2275992400 | D26: 305303700 | E26: =+IF(ABS($C26)>='1. 중요성 기준'!$G$62,"Y","N") -> Y | P26: =IF(SUM(COUNTIF($F26:$O26,"High")*$C$12+COUNTIF($F26:$O26,"Medium")*$C$13+COUNTIF($F26:$O26,"Low")*$C$14)/10>=2,"Y","N") -> N | R26: =IF(COUNTIF($E26:$P26,"Y")>0,"Y","N") -> Y | V26: O | W26: △
B27: 미수금 | C27: 5948300 | D27: 0 | E27: =+IF(ABS($C27)>='1. 중요성 기준'!$G$62,"Y","N") -> N | F27: Low | G27: Low | H27: Low | I27: Low | J27: Low | K27: Low | L27: Low | M27: Low | N27: Low | O27: Low | P27: =IF(SUM(COUNTIF($F27:$O27,"High")*$C$12+COUNTIF($F27:$O27,"Medium")*$C$13+COUNTIF($F27:$O27,"Low")*$C$14)/10>=2,"Y","N") -> N | Q27: 추정이나 판단의 개입이 적으며 비경상적 거래가 아니므로 질적으로 중요하지 않다고 판단함. | R27: =IF(COUNTIF($E27:$P27,"Y")>0,"Y","N") -> N
B28: 미수수익 | C28: 46830564 | D28: 0 | E28: =+IF(ABS($C28)>='1. 중요성 기준'!$G$62,"Y","N") -> N | F28: High | G28: High | H28: Medium | I28: Low | J28: Low | K28: High | L28: Low | M28: Low | N28: High | O28: Medium | P28: =IF(SUM(COUNTIF($F28:$O28,"High")*$C$12+COUNTIF($F28:$O28,"Medium")*$C$13+COUNTIF($F28:$O28,"Low")*$C$14)/10>=2,"Y","N") -> Y | Q28: 주요한 결산항목으로 오류발생가능성이 존재함에 따라 질적으로 중요하다고 판단함. | R28: =IF(COUNTIF($E28:$P28,"Y")>0,"Y","N") -> Y | V28: O | W28: △
B29: 선급금 | C29: 6407772 | D29: 7846108 | E29: =+IF(ABS($C29)>='1. 중요성 기준'!$G$62,"Y","N") -> N | F29: Low | G29: Low | H29: Low | I29: Low | J29: Low | K29: Medium | L29: Low | M29: Low | N29: Low | O29: Low | P29: =IF(SUM(COUNTIF($F29:$O29,"High")*$C$12+COUNTIF($F29:$O29,"Medium")*$C$13+COUNTIF($F29:$O29,"Low")*$C$14)/10>=2,"Y","N") -> N | Q29: 추정이나 판단의 개입이 적으며 비경상적 거래가 아니므로 질적으로 중요하지 않다고 판단함. | R29: =IF(COUNTIF($E29:$P29,"Y")>0,"Y","N") -> N
B30: 선급비용 | C30: 4896947 | D30: 6722777 | E30: =+IF(ABS($C30)>='1. 중요성 기준'!$G$62,"Y","N") -> N | F30: Low | G30: Low | H30: Low | I30: Low | J30: Low | K30: Low | L30: Low | M30: Low | N30: Low | O30: Low | P30: =IF(SUM(COUNTIF($F30:$O30,"High")*$C$12+COUNTIF($F30:$O30,"Medium")*$C$13+COUNTIF($F30:$O30,"Low")*$C$14)/10>=2,"Y","N") -> N | Q30: 추정이나 판단의 개입이 적으며 비경상적 거래가 아니므로 질적으로 중요하지 않다고 판단함. | R30: =IF(COUNTIF($E30:$P30,"Y")>0,"Y","N") -> N
B31: 계약자산 | C31: 0 | D31: 1503230 | E31: =+IF(ABS($C31)>='1. 중요성 기준'!$G$62,"Y","N") -> N | F31: Low | G31: Low | H31: Low | I31: Low | J31: Low | K31: Low | L31: Low | M31: Low | N31: Low | O31: Low | P31: =IF(SUM(COUNTIF($F31:$O31,"High")*$C$12+COUNTIF($F31:$O31,"Medium")*$C$13+COUNTIF($F31:$O31,"Low")*$C$14)/10>=2,"Y","N") -> N | Q31: 추정이나 판단의 개입이 적으며 비경상적 거래가 아니므로 질적으로 중요하지 않다고 판단함. | R31: =IF(COUNTIF($E31:$P31,"Y")>0,"Y","N") -> N
B32: 당기법인세자산 | C32: 0 | D32: 25345289 | E32: =+IF(ABS($C32)>='1. 중요성 기준'!$G$62,"Y","N") -> N | F32: High | G32: High | H32: High | I32: Low | J32: High | K32: Low | L32: Low | M32: High | N32: Low | O32: Low | P32: =IF(SUM(COUNTIF($F32:$O32,"High")*$C$12+COUNTIF($F32:$O32,"Medium")*$C$13+COUNTIF($F32:$O32,"Low")*$C$14)/10>=2,"Y","N") -> Y | Q32: 추정이나 판단의 개입이 존재할 수 있는 항목으로 질적으로 중요하다고 판단함. | R32: =IF(COUNTIF($E32:$P32,"Y")>0,"Y","N") -> Y | W32: O
B33: 단기대여금 | C33: 5000000 | D33: 10000000 | E33: =+IF(ABS($C33)>='1. 중요성 기준'!$G$62,"Y","N") -> N | F33: Low | G33: Low | H33: Low | I33: Low | J33: Low | K33: Low | L33: Low | M33: Low | N33: Low | O33: Low | P33: =IF(SUM(COUNTIF($F33:$O33,"High")*$C$12+COUNTIF($F33:$O33,"Medium")*$C$13+COUNTIF($F33:$O33,"Low")*$C$14)/10>=2,"Y","N") -> N | Q33: 추정이나 판단의 개입이 적으며 비경상적 거래가 아니므로 질적으로 중요하지 않다고 판단함. | R33: =IF(COUNTIF($E33:$P33,"Y")>0,"Y","N") -> N
B34: (2) 재 고 자 산 | C34: 0 | D34: 0 | F34: High | G34: High | H34: High | I34: High | J34: High | K34: High | L34: High | M34: High | N34: High | O34: High | P34: =IF(SUM(COUNTIF($F34:$O34,"High")*$C$12+COUNTIF($F34:$O34,"Medium")*$C$13+COUNTIF($F34:$O34,"Low")*$C$14)/10>=2,"Y","N") -> Y
B35: Ⅰ. 비 유 동 자 산 | C35: =C36+C39+C43+C54+C60+C63 -> 23630026635 | D35: =D36+D39+D43+D54+D60+D63 -> 22188630005
B36: (1) 투자자산 | C36: =SUM(C37:C38) -> 3470148450 | D36: =SUM(D37:D38) -> 1675349527
B37: 단기매매증권_비유동(FVPL) | C37: 2946952902 | D37: 1354621654 | E37: =+IF(ABS($C37)>='1. 중요성 기준'!$G$62,"Y","N") -> Y | R37: =IF(COUNTIF($E37:$P37,"Y")>0,"Y","N") -> Y | V37: O | W37: △
B38: 매도가능증권_비유동(FVOCI) | C38: 523195548 | D38: 320727873 | E38: =+IF(ABS($C38)>='1. 중요성 기준'!$G$62,"Y","N") -> Y | R38: =IF(COUNTIF($E38:$P38,"Y")>0,"Y","N") -> Y | V38: O | W38: △
B39: (2) 투자부동산 | C39: =SUM(C40:C42) -> 1443829918 | D39: =SUM(D40:D42) -> 1469045104
B40: 투자부동산_토지 | C40: 738080364 | D40: 738080364 | E40: =+IF(ABS($C40)>='1. 중요성 기준'!$G$62,"Y","N") -> Y | R40: =IF(COUNTIF($E40:$P40,"Y")>0,"Y","N") -> Y | W40: △ | Y40: O
B41: 투자부동산_건물 | C41: 1008607517 | D41: 1008607517 | E41: =+IF(ABS($C41)>='1. 중요성 기준'!$G$62,"Y","N") -> Y | R41: =IF(COUNTIF($E41:$P41,"Y")>0,"Y","N") -> Y | W41: △ | Y41: O
B42: 감가상각누계액 | C42: -302857963 | D42: -277642777 | E42: =+IF(ABS($C42)>='1. 중요성 기준'!$G$62,"Y","N") -> Y | R42: =IF(COUNTIF($E42:$P42,"Y")>0,"Y","N") -> Y | W42: △ | Y42: O
B43: (3) 유 형 자 산 | C43: =SUM(C44:C53) -> 18481114050 | D43: =SUM(D44:D53) -> 18756617793
B44: 토지 | C44: 4544533340 | D44: 4544533340 | E44: =+IF(ABS($C44)>='1. 중요성 기준'!$G$62,"Y","N") -> Y | F44: Medium | G44: Low | H44: Low | I44: Low | J44: Medium | K44: Low | L44: Medium | M44: Low | N44: Low | O44: Low | P44: =IF(SUM(COUNTIF($F44:$O44,"High")*$C$12+COUNTIF($F44:$O44,"Medium")*$C$13+COUNTIF($F44:$O44,"Low")*$C$14)/10>=2,"Y","N") -> N | R44: =IF(COUNTIF($E44:$P44,"Y")>0,"Y","N") -> Y | W44: △ | Y44: O
B45: 건물 | C45: 14012218982 | D45: 14012218982 | E45: =+IF(ABS($C45)>='1. 중요성 기준'!$G$62,"Y","N") -> Y | F45: Medium | G45: Low | H45: Low | I45: Low | J45: Medium | K45: Low | L45: Medium | M45: Low | N45: Low | O45: Low | P45: =IF(SUM(COUNTIF($F45:$O45,"High")*$C$12+COUNTIF($F45:$O45,"Medium")*$C$13+COUNTIF($F45:$O45,"Low")*$C$14)/10>=2,"Y","N") -> N | R45: =IF(COUNTIF($E45:$P45,"Y")>0,"Y","N") -> Y | W45: △ | Y45: O
...

Sheet 2.2 유의한 계정과목(PL)
B2: 유의한 계정과목 및 공시(PL)
B4: 1. 일반사항
B5: - 이 Spreadsheet는 회사의 재무제표상 계정과목에 대한 질적 중요성을 측정하는데 그 목적이 있음
B7: 2. 질적중요성의 판단
B8: - 양적 기준 검토 결과 "N"라고 파악된 계정과목 및 주석정보에 대하여 2차적으로 질적중요성 검토를 수행함
B9: - 계정과목 및 주석사항에 대하여 10가지 질적 요소에 대한 평가를 통해 Risk Rating을 실시
B10: - Risk Rating은 단순평균방식으로 계산되며, Rating결과가 2(Medium)을 초과할 경우 질적으로 중요하다고 판단함
B12: High | C12: 3
B13: Medium | C13: 2
B14: Low | C14: 1
D16: (단위 : 원) | F16: 계정과목 내 개별 거래의 복잡성, 동질성 | G16: 추정이나 판단이 개입되는 회계처리 및 평가 | H16: 회계처리 및 보고의 복잡성 | I16: 우발채무의 발생가능성 | J16: 특수관계자와 유의적 거래의 존재 여부 | K16: 계정과목 성격의 변화 및 당기 금액 변화 정도 | L16: 비 경상적인 거래 | M16: 관련 회계처리 기준의 변경 | N16: 법규 및 감독당국의 강조 사항 | O16: 주요한 외부환경의 변화가 존재하는 계정 | T16: 매출관리 | U16: 경비관리 | V16: 자금관리 | W16: 재무결산및보고 | X16: 급여및인사관리 | Y16: 고정자산관리
B17: 계정과목 | C17: ='2.1 유의한 계정과목(BS)'!C17 -> FY2022 | D17: ='2.1 유의한 계정과목(BS)'!D17 -> FY2021 | E17: 양적 유의여부(2022) | F17: 질적기준 | P17: 질적 유의여부 | Q17: 질적판단 근거(note1) | R17: 유의성 결론
B18: Ⅰ.영업수익 | C18: =SUM(C19:C21) -> 11141354865 | D18: =SUM(D19:D21) -> 8915413700
B19: 수입수수료 | C19: 10725837726 | D19: 8664956434 | E19: =+IF(ABS($C19)>='1. 중요성 기준'!$G$62,"Y","N") -> Y | P19: =IF(SUM(COUNTIF($F19:$O19,"High")*$C$12+COUNTIF($F19:$O19,"Medium")*$C$13+COUNTIF($F19:$O19,"Low")*$C$14)/10>=2,"Y","N") -> N | R19: =IF(COUNTIF($E19:$P19,"Y")>0,"Y","N") -> Y | T19: O | W19: △
B20: 수출 | C20: 263117139 | D20: 230257266 | E20: =+IF(ABS($C20)>='1. 중요성 기준'!$G$62,"Y","N") -> Y | F20: High | G20: High | H20: High | I20: Low | J20: High | K20: High | L20: Medium | M20: Medium | N20: Medium | O20: Low | P20: =IF(SUM(COUNTIF($F20:$O20,"High")*$C$12+COUNTIF($F20:$O20,"Medium")*$C$13+COUNTIF($F20:$O20,"Low")*$C$14)/10>=2,"Y","N") -> Y | R20: =IF(COUNTIF($E20:$P20,"Y")>0,"Y","N") -> Y | T20: O | W20: △
B21: 수입임대료 | C21: 152400000 | D21: 20200000 | E21: =+IF(ABS($C21)>='1. 중요성 기준'!$G$62,"Y","N") -> N | F21: Low | G21: Low | H21: Low | I21: Low | J21: High | K21: High | L21: Medium | M21: Low | N21: Low | O21: Low | P21: =IF(SUM(COUNTIF($F21:$O21,"High")*$C$12+COUNTIF($F21:$O21,"Medium")*$C$13+COUNTIF($F21:$O21,"Low")*$C$14)/10>=2,"Y","N") -> N | Q21: 추정이나 판단의 개입이 적으며 질적으로 중요하지 않다고 판단함. | R21: =IF(COUNTIF($E21:$P21,"Y")>0,"Y","N") -> N
B22: II. 영업비용 | C22: =SUM(C23:C48) -> 6286911960 | D22: =SUM(D23:D48) -> 5208317681
B23: 급여 | C23: 1125784179 | D23: 1143183620 | E23: =+IF(ABS($C23)>='1. 중요성 기준'!$G$62,"Y","N") -> Y | P23: =IF(SUM(COUNTIF($F23:$O23,"High")*$C$12+COUNTIF($F23:$O23,"Medium")*$C$13+COUNTIF($F23:$O23,"Low")*$C$14)/10>=2,"Y","N") -> N | R23: =IF(COUNTIF($E23:$P23,"Y")>0,"Y","N") -> Y | W23: △ | X23: O
B24: 기타장기종업원급여 | C24: -970091 | D24: 50900155 | E24: =+IF(ABS($C24)>='1. 중요성 기준'!$G$62,"Y","N") -> N | F24: High | G24: High | H24: High | I24: Medium | J24: Low | K24: High | L24: Low | M24: Low | N24: Medium | O24: Low | P24: =IF(SUM(COUNTIF($F24:$O24,"High")*$C$12+COUNTIF($F24:$O24,"Medium")*$C$13+COUNTIF($F24:$O24,"Low")*$C$14)/10>=2,"Y","N") -> Y | Q24: 질적중요성은 낮으나 추정에 근거한 평가가 수반되는 항목임에 따라 대상으로 설정함 | R24: =IF(COUNTIF($E24:$P24,"Y")>0,"Y","N") -> Y | W24: △ | X24: O
B25: 퇴직급여 | C25: 71054160 | D25: 89006740 | E25: =+IF(ABS($C25)>='1. 중요성 기준'!$G$62,"Y","N") -> N | F25: High | G25: High | H25: High | I25: Medium | J25: Low | K25: High | L25: Low | M25: Low | N25: Medium | O25: Low | P25: =IF(SUM(COUNTIF($F25:$O25,"High")*$C$12+COUNTIF($F25:$O25,"Medium")*$C$13+COUNTIF($F25:$O25,"Low")*$C$14)/10>=2,"Y","N") -> Y | Q25: 질적중요성은 낮으나 추정에 근거한 평가가 수반되는 항목임에 따라 대상으로 설정함 | R25: =IF(COUNTIF($E25:$P25,"Y")>0,"Y","N") -> Y | W25: △ | X25: O
B26: 인력개발비 | C26: 1062500 | D26: 0 | E26: =+IF(ABS($C26)>='1. 중요성 기준'!$G$62,"Y","N") -> N | F26: Low | G26: Low | H26: Low | I26: Low | J26: Low | K26: Low | L26: Medium | M26: Low | N26: Low | O26: Low | P26: =IF(SUM(COUNTIF($F26:$O26,"High")*$C$12+COUNTIF($F26:$O26,"Medium")*$C$13+COUNTIF($F26:$O26,"Low")*$C$14)/10>=2,"Y","N") -> N | Q26: 추정이나 판단의 개입이 적으며 비경상적 거래가 아니므로 질적으로 중요하지 않다고 판단함. | R26: =IF(COUNTIF($E26:$P26,"Y")>0,"Y","N") -> N
B27: 복리후생비 | C27: 172516388 | D27: 215159411 | E27: =+IF(ABS($C27)>='1. 중요성 기준'!$G$62,"Y","N") -> Y | P27: =IF(SUM(COUNTIF($F27:$O27,"High")*$C$12+COUNTIF($F27:$O27,"Medium")*$C$13+COUNTIF($F27:$O27,"Low")*$C$14)/10>=2,"Y","N") -> N | R27: =IF(COUNTIF($E27:$P27,"Y")>0,"Y","N") -> Y | U27: O | W27: △ | X27: O
B28: 여비교통비 | C28: 27112121 | D28: 18808276 | E28: =+IF(ABS($C28)>='1. 중요성 기준'!$G$62,"Y","N") -> N | F28: Low | G28: Low | H28: Low | I28: Low | J28: Low | K28: Low | L28: Medium | M28: Low | N28: Low | O28: Low | P28: =IF(SUM(COUNTIF($F28:$O28,"High")*$C$12+COUNTIF($F28:$O28,"Medium")*$C$13+COUNTIF($F28:$O28,"Low")*$C$14)/10>=2,"Y","N") -> N | Q28: 추정이나 판단의 개입이 적으며 비경상적 거래가 아니므로 질적으로 중요하지 않다고 판단함. | R28: =IF(COUNTIF($E28:$P28,"Y")>0,"Y","N") -> N
B29: 접대비 | C29: 38837116 | D29: 51365780 | E29: =+IF(ABS($C29)>='1. 중요성 기준'!$G$62,"Y","N") -> N | F29: Low | G29: Low | H29: Low | I29: Low | J29: Low | K29: Low | L29: Medium | M29: Low | N29: Low | O29: Low | P29: =IF(SUM(COUNTIF($F29:$O29,"High")*$C$12+COUNTIF($F29:$O29,"Medium")*$C$13+COUNTIF($F29:$O29,"Low")*$C$14)/10>=2,"Y","N") -> N | Q29: 추정이나 판단의 개입이 적으며 비경상적 거래가 아니므로 질적으로 중요하지 않다고 판단함. | R29: =IF(COUNTIF($E29:$P29,"Y")>0,"Y","N") -> N
B30: 통신비 | C30: 20943484 | D30: 21746966 | E30: =+IF(ABS($C30)>='1. 중요성 기준'!$G$62,"Y","N") -> N | F30: Low | G30: Low | H30: Low | I30: Low | J30: Low | K30: Low | L30: Medium | M30: Low | N30: Low | O30: Low | P30: =IF(SUM(COUNTIF($F30:$O30,"High")*$C$12+COUNTIF($F30:$O30,"Medium")*$C$13+COUNTIF($F30:$O30,"Low")*$C$14)/10>=2,"Y","N") -> N | Q30: 추정이나 판단의 개입이 적으며 비경상적 거래가 아니므로 질적으로 중요하지 않다고 판단함. | R30: =IF(COUNTIF($E30:$P30,"Y")>0,"Y","N") -> N
B31: 수도광열비 | C31: 21906393 | D31: 4021581 | E31: =+IF(ABS($C31)>='1. 중요성 기준'!$G$62,"Y","N") -> N | F31: Low | G31: Low | H31: Low | I31: Low | J31: Low | K31: Low | L31: Medium | M31: Low | N31: Low | O31: Low | P31: =IF(SUM(COUNTIF($F31:$O31,"High")*$C$12+COUNTIF($F31:$O31,"Medium")*$C$13+COUNTIF($F31:$O31,"Low")*$C$14)/10>=2,"Y","N") -> N | Q31: 추정이나 판단의 개입이 적으며 비경상적 거래가 아니므로 질적으로 중요하지 않다고 판단함. | R31: =IF(COUNTIF($E31:$P31,"Y")>0,"Y","N") -> N
B32: 전력비 | C32: 40644028 | D32: 3230884 | E32: =+IF(ABS($C32)>='1. 중요성 기준'!$G$62,"Y","N") -> N | F32: Low | G32: Low | H32: Low | I32: Low | J32: Low | K32: Low | L32: Medium | M32: Low | N32: Low | O32: Low | P32: =IF(SUM(COUNTIF($F32:$O32,"High")*$C$12+COUNTIF($F32:$O32,"Medium")*$C$13+COUNTIF($F32:$O32,"Low")*$C$14)/10>=2,"Y","N") -> N | Q32: 추정이나 판단의 개입이 적으며 비경상적 거래가 아니므로 질적으로 중요하지 않다고 판단함. | R32: =IF(COUNTIF($E32:$P32,"Y")>0,"Y","N") -> N
B33: 건물관리비 | C33: 0 | D33: 25405710 | E33: =+IF(ABS($C33)>='1. 중요성 기준'!$G$62,"Y","N") -> N | F33: Low | G33: Low | H33: Low | I33: Low | J33: Low | K33: Low | L33: Medium | M33: Low | N33: Low | O33: Low | P33: =IF(SUM(COUNTIF($F33:$O33,"High")*$C$12+COUNTIF($F33:$O33,"Medium")*$C$13+COUNTIF($F33:$O33,"Low")*$C$14)/10>=2,"Y","N") -> N | Q33: 추정이나 판단의 개입이 적으며 비경상적 거래가 아니므로 질적으로 중요하지 않다고 판단함. | R33: =IF(COUNTIF($E33:$P33,"Y")>0,"Y","N") -> N
B34: 세금과공과금 | C34: 88689848 | D34: 56661909 | E34: =+IF(ABS($C34)>='1. 중요성 기준'!$G$62,"Y","N") -> N | F34: Low | G34: Low | H34: Low | I34: Low | J34: Low | K34: Low | L34: Medium | M34: Low | N34: Low | O34: Low | P34: =IF(SUM(COUNTIF($F34:$O34,"High")*$C$12+COUNTIF($F34:$O34,"Medium")*$C$13+COUNTIF($F34:$O34,"Low")*$C$14)/10>=2,"Y","N") -> N | Q34: 추정이나 판단의 개입이 적으며 비경상적 거래가 아니므로 질적으로 중요하지 않다고 판단함. | R34: =IF(COUNTIF($E34:$P34,"Y")>0,"Y","N") -> N
B35: 감가상각비 | C35: 155299232 | D35: 61944959 | E35: =+IF(ABS($C35)>='1. 중요성 기준'!$G$62,"Y","N") -> N | F35: High | G35: Medium | H35: High | I35: Low | J35: Low | K35: Medium | L35: Medium | M35: Medium | N35: High | O35: Low | P35: =IF(SUM(COUNTIF($F35:$O35,"High")*$C$12+COUNTIF($F35:$O35,"Medium")*$C$13+COUNTIF($F35:$O35,"Low")*$C$14)/10>=2,"Y","N") -> Y | Q35: 양적중요성은 낮으나 추정에 근거한 평가가 수반되는 항목임에 따라 대상으로 설정함 | R35: =IF(COUNTIF($E35:$P35,"Y")>0,"Y","N") -> Y | W35: △ | Y35: O
B36: 사용권자산감가상각비 | C36: 4880184 | D36: 4880184 | E36: =+IF(ABS($C36)>='1. 중요성 기준'!$G$62,"Y","N") -> N | F36: High | G36: Medium | H36: High | I36: Low | J36: Low | K36: Medium | L36: Medium | M36: Medium | N36: High | O36: Low | P36: =IF(SUM(COUNTIF($F36:$O36,"High")*$C$12+COUNTIF($F36:$O36,"Medium")*$C$13+COUNTIF($F36:$O36,"Low")*$C$14)/10>=2,"Y","N") -> Y | Q36: 양적중요성은 낮으나 추정에 근거한 평가가 수반되는 항목임에 따라 대상으로 설정함 | R36: =IF(COUNTIF($E36:$P36,"Y")>0,"Y","N") -> Y | W36: △ | Y36: O
B37: 무형고정자산상각 | C37: 4795132 | D37: 4911317 | E37: =+IF(ABS($C37)>='1. 중요성 기준'!$G$62,"Y","N") -> N | F37: Low | G37: Low | H37: Low | I37: Low | J37: Low | K37: Low | L37: Low | M37: Low | N37: Low | O37: Low | P37: =IF(SUM(COUNTIF($F37:$O37,"High")*$C$12+COUNTIF($F37:$O37,"Medium")*$C$13+COUNTIF($F37:$O37,"Low")*$C$14)/10>=2,"Y","N") -> N | Q37: 추정이나 판단의 개입이 적으며 비경상적 거래가 아니므로 질적으로 중요하지 않다고 판단함. | R37: =IF(COUNTIF($E37:$P37,"Y")>0,"Y","N") -> N
B38: 보험료 | C38: 2069968 | D38: 1066303 | E38: =+IF(ABS($C38)>='1. 중요성 기준'!$G$62,"Y","N") -> N | F38: Low | G38: Low | H38: Low | I38: Low | J38: Low | K38: Low | L38: Low | M38: Low | N38: Low | O38: Low | P38: =IF(SUM(COUNTIF($F38:$O38,"High")*$C$12+COUNTIF($F38:$O38,"Medium")*$C$13+COUNTIF($F38:$O38,"Low")*$C$14)/10>=2,"Y","N") -> N | Q38: 추정이나 판단의 개입이 적으며 비경상적 거래가 아니므로 질적으로 중요하지 않다고 판단함. | R38: =IF(COUNTIF($E38:$P38,"Y")>0,"Y","N") -> N
B39: 차량유지비 | C39: 2734021 | D39: 4229200 | E39: =+IF(ABS($C39)>='1. 중요성 기준'!$G$62,"Y","N") -> N | F39: Low | G39: Low | H39: Low | I39: Low | J39: Low | K39: Low | L39: Low | M39: Low | N39: Low | O39: Low | P39: =IF(SUM(COUNTIF($F39:$O39,"High")*$C$12+COUNTIF($F39:$O39,"Medium")*$C$13+COUNTIF($F39:$O39,"Low")*$C$14)/10>=2,"Y","N") -> N | Q39: 추정이나 판단의 개입이 적으며 비경상적 거래가 아니므로 질적으로 중요하지 않다고 판단함. | R39: =IF(COUNTIF($E39:$P39,"Y")>0,"Y","N") -> N
B40: 경상연구개발비 | C40: 3350063105 | D40: 2451659217 | E40: =+IF(ABS($C40)>='1. 중요성 기준'!$G$62,"Y","N") -> Y | F40: Low | G40: Low | H40: Low | I40: Low | J40: Low | K40: Low | L40: Low | M40: Low | N40: Low | O40: Low | P40: =IF(SUM(COUNTIF($F40:$O40,"High")*$C$12+COUNTIF($F40:$O40,"Medium")*$C$13+COUNTIF($F40:$O40,"Low")*$C$14)/10>=2,"Y","N") -> N | Q40: 추정이나 판단의 개입이 적으며 비경상적 거래가 아니므로 질적으로 중요하지 않다고 판단함. | R40: =IF(COUNTIF($E40:$P40,"Y")>0,"Y","N") -> Y | U40: O | W40: △ | X40: O
B41: 운반비 | C41: 97500 | D41: 377300 | E41: =+IF(ABS($C41)>='1. 중요성 기준'!$G$62,"Y","N") -> N | F41: Low | G41: Low | H41: Low | I41: Low | J41: Low | K41: Low | L41: Low | M41: Low | N41: Low | O41: Low | P41: =IF(SUM(COUNTIF($F41:$O41,"High")*$C$12+COUNTIF($F41:$O41,"Medium")*$C$13+COUNTIF($F41:$O41,"Low")*$C$14)/10>=2,"Y","N") -> N | Q41: 추정이나 판단의 개입이 적으며 비경상적 거래가 아니므로 질적으로 중요하지 않다고 판단함. | R41: =IF(COUNTIF($E41:$P41,"Y")>0,"Y","N") -> N
B42: 교육훈련비 | C42: 3470850 | D42: 2578655 | E42: =+IF(ABS($C42)>='1. 중요성 기준'!$G$62,"Y","N") -> N | F42: Low | G42: Low | H42: Low | I42: Low | J42: Low | K42: Low | L42: Low | M42: Low | N42: Low | O42: Low | P42: =IF(SUM(COUNTIF($F42:$O42,"High")*$C$12+COUNTIF($F42:$O42,"Medium")*$C$13+COUNTIF($F42:$O42,"Low")*$C$14)/10>=2,"Y","N") -> N | Q42: 추정이나 판단의 개입이 적으며 비경상적 거래가 아니므로 질적으로 중요하지 않다고 판단함. | R42: =IF(COUNTIF($E42:$P42,"Y")>0,"Y","N") -> N
B43: 도서인쇄비 | C43: 3464861 | D43: 4296760 | E43: =+IF(ABS($C43)>='1. 중요성 기준'!$G$62,"Y","N") -> N | F43: Low | G43: Low | H43: Low | I43: Low | J43: Low | K43: Low | L43: Low | M43: Low | N43: Low | O43: Low | P43: =IF(SUM(COUNTIF($F43:$O43,"High")*$C$12+COUNTIF($F43:$O43,"Medium")*$C$13+COUNTIF($F43:$O43,"Low")*$C$14)/10>=2,"Y","N") -> N | Q43: 추정이나 판단의 개입이 적으며 비경상적 거래가 아니므로 질적으로 중요하지 않다고 판단함. | R43: =IF(COUNTIF($E43:$P43,"Y")>0,"Y","N") -> N
B44: 소모품비 | C44: 26417581 | D44: 49977920 | E44: =+IF(ABS($C44)>='1. 중요성 기준'!$G$62,"Y","N") -> N | F44: Low | G44: Low | H44: Low | I44: Low | J44: Low | K44: Low | L44: Low | M44: Low | N44: Low | O44: Low | P44: =IF(SUM(COUNTIF($F44:$O44,"High")*$C$12+COUNTIF($F44:$O44,"Medium")*$C$13+COUNTIF($F44:$O44,"Low")*$C$14)/10>=2,"Y","N") -> N | Q44: 추정이나 판단의 개입이 적으며 비경상적 거래가 아니므로 질적으로 중요하지 않다고 판단함. | R44: =IF(COUNTIF($E44:$P44,"Y")>0,"Y","N") -> N
B45: 지급수수료 | C45: 218875832 | D45: 125164842 | E45: =+IF(ABS($C45)>='1. 중요성 기준'!$G$62,"Y","N") -> Y | F45: Low | G45: Low | H45: Low | I45: Low | J45: Low | K45: Low | L45: Low | M45: Low | N45: Low | O45: Low | P45: =IF(SUM(COUNTIF($F45:$O45,"High")*$C$12+COUNTIF($F45:$O45,"Medium")*$C$13+COUNTIF($F45:$O45,"Low")*$C$14)/10>=2,"Y","N") -> N | R45: =IF(COUNTIF($E45:$P45,"Y")>0,"Y","N") -> Y | U45: O | W45: △
...

Sheet 2.3 유의한 주석
B2: 유의한 주석공시
B4: 1. 일반사항
B5: - 이 Spreadsheet는 회사의 재무제표상 계정과목에 대한 질적 중요성을 측정하는데 그 목적이 있음
B7: 2. 질적중요성의 판단
B8: - 양적 기준 검토 결과 "N"라고 파악된 계정과목 및 주석정보에 대하여 2차적으로 질적중요성 검토를 수행함
B9: - 계정과목 및 주석사항에 대하여 10가지 질적 요소에 대한 평가를 통해 Risk Rating을 실시
B10: - Risk Rating은 단순평균방식으로 계산되며, Rating결과가 2(Medium)을 초과할 경우 질적으로 중요하다고 판단함
B12: High | C12: 3
B13: Medium | C13: 2
B14: Low | C14: 1
E16: (단위 : 백만원) | G16: 계정과목 내 개별 거래의 복잡성, 동질성 | H16: 추정이나 판단이 개입되는 회계처리 및 평가 | I16: 회계처리 및 보고의 복잡성 | J16: 우발채무의 발생가능성 | K16: 특수관계자와 유의적 거래의 존재 여부 | L16: 계정과목 성격의 변화 및 당기 금액 변화 정도 | M16: 비 경상적인 거래 | N16: 관련 회계처리 기준의 변경 | O16: 법규 및 감독당국의 강조 사항 | P16: 주요한 외부환경의 변화가 존재하는 계정 | U16: 매출관리 | V16: 경비관리 | W16: 자금관리 | X16: 재무결산및보고 | Y16: 급여및인사관리 | Z16: 고정자산관리
B17: 계정과목 | C17: 양적중요성 Factor | D17: FY2019.03 | E17: FY2018 | F17: 양적 유의여부* | G17: 질적기준 | Q17: 질적 유의여부 | R17: 질적판단 근거 | S17: 유의성 결론
B18: Disclosure
B19: 1. 당사의 개요 | G19: Low | H19: Low | I19: Low | J19: Low | K19: Low | L19: Low | M19: Low | N19: Low | O19: Low | P19: Medium | Q19: =IF(SUM(COUNTIF($G19:$P19,"High")*$C$12+COUNTIF($G19:$P19,"Medium")*$C$13+COUNTIF($G19:$P19,"Low")*$C$14)/10>=2,"Y","N") -> N | R19: 일반사항은 설립일 및 주주의 내역으로 유의적인 변동이 없으며, 재무제표에 미치는 영향이 중요하지 않을 것으로 판단하여 질적으로 유의적이지 않을 것으로 판단함. | S19: =IF(COUNTIF($F19:$Q19,"Y")>0,"Y","N") -> N
B20: 2. 재무제표작성기준 및 유의적인 회계정책 | G20: Low | H20: Low | I20: Low | J20: Low | K20: Low | L20: Low | M20: Low | N20: Medium | O20: Medium | P20: Medium | Q20: =IF(SUM(COUNTIF($G20:$P20,"High")*$C$12+COUNTIF($G20:$P20,"Medium")*$C$13+COUNTIF($G20:$P20,"Low")*$C$14)/10>=2,"Y","N") -> N | R20: 투자 및 재무활동이 제한되어 회계정책의 변경 및 신규기준서 등의 개정으로 인한 영향 등을 크게 받지 않아 질적으로 유의적이지 않을 것으로 판단함. | S20: =IF(COUNTIF($F20:$Q20,"Y")>0,"Y","N") -> N
B21: 3. 중요한 판단과 추정불확실성의 주요 원천 | D21: 10086000000 | E21: 871528000 | G21: Low | H21: Low | I21: Low | J21: Low | K21: Low | L21: Medium | M21: Medium | N21: Low | O21: Medium | P21: Medium | Q21: =IF(SUM(COUNTIF($G21:$P21,"High")*$C$12+COUNTIF($G21:$P21,"Medium")*$C$13+COUNTIF($G21:$P21,"Low")*$C$14)/10>=2,"Y","N") -> N | R21: 투자 및 재무활동이 제한되어 회계정책의 변경 및 신규기준서 등의 개정으로 인한 영향 등을 크게 받지 않아 질적으로 유의적이지 않을 것으로 판단함. | S21: =IF(COUNTIF($F21:$Q21,"Y")>0,"Y","N") -> N
B22: 4. 영업부문 | D22: ='2.1 유의한 계정과목(BS)'!C34 -> 0 | E22: ='2.1 유의한 계정과목(BS)'!D34 -> 0 | G22: Low | H22: Low | I22: Low | J22: Low | K22: Low | L22: Low | M22: Low | N22: Low | O22: Low | P22: Low | Q22: =IF(SUM(COUNTIF($G22:$P22,"High")*$C$12+COUNTIF($G22:$P22,"Medium")*$C$13+COUNTIF($G22:$P22,"Low")*$C$14)/10>=2,"Y","N") -> N | R22: 별도재무제표상 부문에 대한 정보를 별도로 공시하고 있지 않음에 따라 질적으로 유의적이지 않을 것으로 판단함. | S22: =IF(COUNTIF($F22:$Q22,"Y")>0,"Y","N") -> N
B23: 5. 현금및현금성자산 | D23: =SUM('2.1 유의한 계정과목(BS)'!C21:C33,'2.1 유의한 계정과목(BS)'!#REF!,'2.1 유의한 계정과목(BS)'!#REF!,'2.1 유의한 계정과목(BS)'!#REF!,'2.1 유의한 계정과목(BS)'!#REF!,'2.1 유의한 계정과목(BS)'!C64,'2.1 유의한 계정과목(BS)'!#REF!,'2.1 유의한 계정과목(BS)'!#REF!)+SUM('2.1 유의한 계정과목(BS)'!#REF!,'2.1 유의한 계정과목(BS)'!#REF!,'2.1 유의한 계정과목(BS)'!#REF!,'2.1 유의한 계정과목(BS)'!#REF!,'2.1 유의한 계정과목(BS)'!#REF!,'2.1 유의한 계정과목(BS)'!#REF!,'2.1 유의한 계정과목(BS)'!#REF!,'2.1 유의한 계정과목(BS)'!C73,'2.1 유의한 계정과목(BS)'!#REF!,'2.1 유의한 계정과목(BS)'!C79,'2.1 유의한 계정과목(BS)'!C80,'2.1 유의한 계정과목(BS)'!C83,'2.1 유의한 계정과목(BS)'!#REF!,'2.1 유의한 계정과목(BS)'!#REF!,'2.1 유의한 계정과목(BS)'!#REF!) -> #REF! | E23: =SUM('2.1 유의한 계정과목(BS)'!D21:D33,'2.1 유의한 계정과목(BS)'!#REF!,'2.1 유의한 계정과목(BS)'!#REF!,'2.1 유의한 계정과목(BS)'!#REF!,'2.1 유의한 계정과목(BS)'!#REF!,'2.1 유의한 계정과목(BS)'!D64,'2.1 유의한 계정과목(BS)'!#REF!,'2.1 유의한 계정과목(BS)'!#REF!)+SUM('2.1 유의한 계정과목(BS)'!#REF!,'2.1 유의한 계정과목(BS)'!#REF!,'2.1 유의한 계정과목(BS)'!#REF!,'2.1 유의한 계정과목(BS)'!#REF!,'2.1 유의한 계정과목(BS)'!#REF!,'2.1 유의한 계정과목(BS)'!#REF!,'2.1 유의한 계정과목(BS)'!#REF!,'2.1 유의한 계정과목(BS)'!D73,'2.1 유의한 계정과목(BS)'!#REF!,'2.1 유의한 계정과목(BS)'!D79,'2.1 유의한 계정과목(BS)'!D80,'2.1 유의한 계정과목(BS)'!D83,'2.1 유의한 계정과목(BS)'!#REF!,'2.1 유의한 계정과목(BS)'!#REF!,'2.1 유의한 계정과목(BS)'!#REF!) -> #REF! | G23: Low | H23: Low | I23: Low | J23: Low | K23: Low | L23: Low | M23: Low | N23: Low | O23: Low | P23: Low | Q23: =IF(SUM(COUNTIF($G23:$P23,"High")*$C$12+COUNTIF($G23:$P23,"Medium")*$C$13+COUNTIF($G23:$P23,"Low")*$C$14)/10>=2,"Y","N") -> N | R23: 해당 계정과목에 대한 집계사항으로 추정이나 판단이 개입되지 않으며, 회계처리등의 복잡성도 낮음에 따라 질적으로 유의적이지 않을 것으로 판단함. | S23: =IF(COUNTIF($F23:$Q23,"Y")>0,"Y","N") -> N
B24: 6. 단기금융상품 | G24: Low | H24: Low | I24: Low | J24: Low | K24: Low | L24: Low | M24: Low | N24: Low | O24: Low | P24: Low | Q24: =IF(SUM(COUNTIF($G24:$P24,"High")*$C$12+COUNTIF($G24:$P24,"Medium")*$C$13+COUNTIF($G24:$P24,"Low")*$C$14)/10>=2,"Y","N") -> N | R24: 해당 계정과목에 대한 집계사항으로 추정이나 판단이 개입되지 않으며, 회계처리등의 복잡성도 낮음에 따라 질적으로 유의적이지 않을 것으로 판단함. | S24: =IF(COUNTIF($F24:$Q24,"Y")>0,"Y","N") -> N
B25: 7. 매출채권및기타채권 | D25: ='2.1 유의한 계정과목(BS)'!#REF! -> #REF! | E25: ='2.1 유의한 계정과목(BS)'!#REF! -> #REF! | G25: Low | H25: Low | I25: Low | J25: Low | K25: Low | L25: Low | M25: Low | N25: Low | O25: Low | P25: Low | Q25: =IF(SUM(COUNTIF($G25:$P25,"High")*$C$12+COUNTIF($G25:$P25,"Medium")*$C$13+COUNTIF($G25:$P25,"Low")*$C$14)/10>=2,"Y","N") -> N | R25: 해당 계정과목에 대한 집계사항으로 추정이나 판단이 개입되지 않으며, 회계처리등의 복잡성도 낮음에 따라 질적으로 유의적이지 않을 것으로 판단함. | S25: =IF(COUNTIF($F25:$Q25,"Y")>0,"Y","N") -> N
B26: 8. 당기손익공정가치측정금융자산 | G26: Low | H26: Low | I26: Low | J26: Low | K26: Low | L26: Low | M26: Low | N26: Low | O26: Low | P26: Low | Q26: =IF(SUM(COUNTIF($G26:$P26,"High")*$C$12+COUNTIF($G26:$P26,"Medium")*$C$13+COUNTIF($G26:$P26,"Low")*$C$14)/10>=2,"Y","N") -> N | R26: 해당 계정과목에 대한 집계사항으로 추정이나 판단이 개입되지 않으며, 회계처리등의 복잡성도 낮음에 따라 질적으로 유의적이지 않을 것으로 판단함. | S26: =IF(COUNTIF($F26:$Q26,"Y")>0,"Y","N") -> N
B27: 9. 기타포괄손익공정가치측정금융자산 | D27: =SUM('2.1 유의한 계정과목(BS)'!#REF!) -> #REF! | E27: =SUM('2.1 유의한 계정과목(BS)'!#REF!) -> #REF! | G27: Low | H27: Low | I27: Low | J27: Low | K27: Low | L27: Low | M27: Low | N27: Low | O27: Low | P27: Low | Q27: =IF(SUM(COUNTIF($G27:$P27,"High")*$C$12+COUNTIF($G27:$P27,"Medium")*$C$13+COUNTIF($G27:$P27,"Low")*$C$14)/10>=2,"Y","N") -> N | R27: 해당 계정과목에 대한 집계사항으로 추정이나 판단이 개입되지 않으며, 회계처리등의 복잡성도 낮음에 따라 질적으로 유의적이지 않을 것으로 판단함. | S27: =IF(COUNTIF($F27:$Q27,"Y")>0,"Y","N") -> N
B28: 10. 기타유동자산 | G28: Low | H28: Low | I28: Low | J28: Low | K28: Low | L28: Low | M28: Low | N28: Low | O28: Low | P28: Low | Q28: =IF(SUM(COUNTIF($G28:$P28,"High")*$C$12+COUNTIF($G28:$P28,"Medium")*$C$13+COUNTIF($G28:$P28,"Low")*$C$14)/10>=2,"Y","N") -> N | R28: 해당 계정과목에 대한 집계사항으로 추정이나 판단이 개입되지 않으며, 회계처리등의 복잡성도 낮음에 따라 질적으로 유의적이지 않을 것으로 판단함. | S28: =IF(COUNTIF($F28:$Q28,"Y")>0,"Y","N") -> N
B29: 11. 유형자산 | D29: ='2.2 유의한 계정과목(PL)'!C68 -> 404133090 | E29: ='2.2 유의한 계정과목(PL)'!D68 -> 268553004 | G29: High | H29: Medium | I29: High | J29: Low | K29: Low | L29: High | M29: Low | N29: Low | O29: Medium | P29: Medium | Q29: =IF(SUM(COUNTIF($G29:$P29,"High")*$C$12+COUNTIF($G29:$P29,"Medium")*$C$13+COUNTIF($G29:$P29,"Low")*$C$14)/10>=2,"Y","N") -> N | R29: 유형자산의 경우 고정자산 잔액 및 변동 내역내역을 공시하고 있음. 해당 계정과목에 대한 집계사항으로 추정이나 판단이 개입되지 않으며, 회계처리등의 복잡성도 낮음에 따라 질적으로 유의적이지 않을 것으로 판단함. | S29: =IF(COUNTIF($F29:$Q29,"Y")>0,"Y","N") -> N
B30: 12. 투자부동산 | G30: High | H30: Medium | I30: High | J30: Low | K30: Low | L30: High | M30: Low | N30: Low | O30: Medium | P30: Medium | Q30: =IF(SUM(COUNTIF($G30:$P30,"High")*$C$12+COUNTIF($G30:$P30,"Medium")*$C$13+COUNTIF($G30:$P30,"Low")*$C$14)/10>=2,"Y","N") -> N | R30: 투자부동산의 경우 고정자산 잔액 및 변동 내역내역을 공시하고 있음. 해당 계정과목에 대한 집계사항으로 추정이나 판단이 개입되지 않으며, 회계처리등의 복잡성도 낮음에 따라 질적으로 유의적이지 않을 것으로 판단함. | S30: =IF(COUNTIF($F30:$Q30,"Y")>0,"Y","N") -> N
B31: 13. 사용권자산 | D31: =5005866000+1227635000 -> 6233501000 | E31: =9819044000+1175465000 -> 10994509000 | G31: High | H31: Medium | I31: High | J31: Low | K31: Low | L31: Low | M31: Low | N31: High | O31: Medium | P31: Low | Q31: =IF(SUM(COUNTIF($G31:$P31,"High")*$C$12+COUNTIF($G31:$P31,"Medium")*$C$13+COUNTIF($G31:$P31,"Low")*$C$14)/10>=2,"Y","N") -> N | R31: 사용권자산의 경우 고정자산 잔액 및 변동 내역내역을 공시하고 있음. 해당 계정과목에 대한 집계사항으로 추정이나 판단이 개입되지 않으며, 회계처리등의 복잡성도 낮음에 따라 질적으로 유의적이지 않을 것으로 판단함. | S31: =IF(COUNTIF($F31:$Q31,"Y")>0,"Y","N") -> N
B32: 14. 무형자산 | D32: 10000000000 | E32: 10000000000 | G32: High | H32: Medium | I32: High | J32: Low | K32: Low | L32: High | M32: Low | N32: High | O32: Medium | P32: Low | Q32: =IF(SUM(COUNTIF($G32:$P32,"High")*$C$12+COUNTIF($G32:$P32,"Medium")*$C$13+COUNTIF($G32:$P32,"Low")*$C$14)/10>=2,"Y","N") -> Y | R32: 무형자산의 경우 고정자산 잔액 및 변동 내역내역을 공시하고 있음. 다만 중요성이 낮은 항목에 해당함에 따라 제외함 | S32: N
B33: 15. 매입채무및기타채무 | G33: Low | H33: Low | I33: Low | J33: Low | K33: Low | L33: Low | M33: Low | N33: Low | O33: Low | P33: Low | Q33: =IF(SUM(COUNTIF($G33:$P33,"High")*$C$12+COUNTIF($G33:$P33,"Medium")*$C$13+COUNTIF($G33:$P33,"Low")*$C$14)/10>=2,"Y","N") -> N | R33: 해당 계정과목에 대한 집계사항으로 추정이나 판단이 개입되지 않으며, 회계처리등의 복잡성도 낮음에 따라 질적으로 유의적이지 않을 것으로 판단함. | S33: =IF(COUNTIF($F33:$Q33,"Y")>0,"Y","N") -> N
B34: 16. 차입금 등 | G34: Low | H34: Low | I34: Low | J34: Low | K34: Low | L34: Low | M34: Low | N34: Low | O34: Low | P34: Low | Q34: =IF(SUM(COUNTIF($G34:$P34,"High")*$C$12+COUNTIF($G34:$P34,"Medium")*$C$13+COUNTIF($G34:$P34,"Low")*$C$14)/10>=2,"Y","N") -> N | R34: 해당 계정과목에 대한 집계사항으로 추정이나 판단이 개입되지 않으며, 회계처리등의 복잡성도 낮음에 따라 질적으로 유의적이지 않을 것으로 판단함. | S34: =IF(COUNTIF($F34:$Q34,"Y")>0,"Y","N") -> N
B35: 17. 리스 | D35: ='2.1 유의한 계정과목(BS)'!C48 -> -71399000 | E35: ='2.1 유의한 계정과목(BS)'!D48 -> -71399000 | G35: High | H35: Medium | I35: High | J35: Low | K35: Low | L35: High | M35: Low | N35: High | O35: Low | P35: Low | Q35: =IF(SUM(COUNTIF($G35:$P35,"High")*$C$12+COUNTIF($G35:$P35,"Medium")*$C$13+COUNTIF($G35:$P35,"Low")*$C$14)/10>=2,"Y","N") -> N | R35: 리스부채는 관련 잔액뿐 아니라 만기에 대한 분석정보를 추가적으로 요구하고 있음. 다만 중요성이 낮은 항목에 해당함에 따라 제외함 | S35: =IF(COUNTIF($F35:$Q35,"Y")>0,"Y","N") -> N
B36: 18. 기타유동부채 | D36: ='2.1 유의한 계정과목(BS)'!C49 -> 472489866 | E36: ='2.1 유의한 계정과목(BS)'!D49 -> 372165127 | G36: Low | H36: Low | I36: Low | J36: Low | K36: Low | L36: Low | M36: Low | N36: Low | O36: Low | P36: Low | Q36: =IF(SUM(COUNTIF($G36:$P36,"High")*$C$12+COUNTIF($G36:$P36,"Medium")*$C$13+COUNTIF($G36:$P36,"Low")*$C$14)/10>=2,"Y","N") -> N | R36: 해당 계정과목에 대한 집계사항으로 추정이나 판단이 개입되지 않으며, 회계처리등의 복잡성도 낮음에 따라 질적으로 유의적이지 않을 것으로 판단함. | S36: =IF(COUNTIF($F36:$Q36,"Y")>0,"Y","N") -> N
B37: 19. 충당부채 | D37: ='2.1 유의한 계정과목(BS)'!C17 -> FY2022 | E37: ='2.1 유의한 계정과목(BS)'!D17 -> FY2021 | G37: Low | H37: Low | I37: Low | J37: Low | K37: Low | L37: Low | M37: Low | N37: Low | O37: Low | P37: Low | Q37: =IF(SUM(COUNTIF($G37:$P37,"High")*$C$12+COUNTIF($G37:$P37,"Medium")*$C$13+COUNTIF($G37:$P37,"Low")*$C$14)/10>=2,"Y","N") -> N | R37: 해당 계정과목에 대한 집계사항으로 추정이나 판단이 개입되지 않으며, 회계처리등의 복잡성도 낮음에 따라 질적으로 유의적이지 않을 것으로 판단함. | S37: =IF(COUNTIF($F37:$Q37,"Y")>0,"Y","N") -> N
B38: 20. 계약자산 및 계약부채 | G38: Low | H38: Low | I38: Low | J38: Low | K38: Low | L38: Low | M38: Low | N38: Low | O38: Low | P38: Low | Q38: =IF(SUM(COUNTIF($G38:$P38,"High")*$C$12+COUNTIF($G38:$P38,"Medium")*$C$13+COUNTIF($G38:$P38,"Low")*$C$14)/10>=2,"Y","N") -> N | R38: 해당 계정과목에 대한 집계사항으로 추정이나 판단이 개입되지 않으며, 회계처리등의 복잡성도 낮음에 따라 질적으로 유의적이지 않을 것으로 판단함. | S38: =IF(COUNTIF($F38:$Q38,"Y")>0,"Y","N") -> N
B39: 21. 자본금 | G39: Low | H39: Low | I39: Low | J39: Low | K39: Low | L39: Low | M39: Low | N39: Low | O39: Low | P39: Low | Q39: =IF(SUM(COUNTIF($G39:$P39,"High")*$C$12+COUNTIF($G39:$P39,"Medium")*$C$13+COUNTIF($G39:$P39,"Low")*$C$14)/10>=2,"Y","N") -> N | R39: 해당 계정과목에 대한 집계사항으로 추정이나 판단이 개입되지 않으며, 회계처리등의 복잡성도 낮음에 따라 질적으로 유의적이지 않을 것으로 판단함. | S39: =IF(COUNTIF($F39:$Q39,"Y")>0,"Y","N") -> N
B40: 22. 기타불입자본 | G40: Low | H40: Low | I40: Low | J40: Low | K40: Low | L40: Low | M40: Low | N40: Low | O40: Low | P40: Low | Q40: =IF(SUM(COUNTIF($G40:$P40,"High")*$C$12+COUNTIF($G40:$P40,"Medium")*$C$13+COUNTIF($G40:$P40,"Low")*$C$14)/10>=2,"Y","N") -> N | R40: 해당 계정과목에 대한 집계사항으로 추정이나 판단이 개입되지 않으며, 회계처리등의 복잡성도 낮음에 따라 질적으로 유의적이지 않을 것으로 판단함. | S40: =IF(COUNTIF($F40:$Q40,"Y")>0,"Y","N") -> N
B41: 23. 기타자본구성요소 | G41: Low | H41: Low | I41: Low | J41: Low | K41: Low | L41: Low | M41: Low | N41: Low | O41: Low | P41: Low | Q41: =IF(SUM(COUNTIF($G41:$P41,"High")*$C$12+COUNTIF($G41:$P41,"Medium")*$C$13+COUNTIF($G41:$P41,"Low")*$C$14)/10>=2,"Y","N") -> N | R41: 해당 계정과목에 대한 집계사항으로 추정이나 판단이 개입되지 않으며, 회계처리등의 복잡성도 낮음에 따라 질적으로 유의적이지 않을 것으로 판단함. | S41: =IF(COUNTIF($F41:$Q41,"Y")>0,"Y","N") -> N
B42: 24. 이익잉여금 | G42: Low | H42: Low | I42: Low | J42: Low | K42: Low | L42: Low | M42: Low | N42: Low | O42: Low | P42: Low | Q42: =IF(SUM(COUNTIF($G42:$P42,"High")*$C$12+COUNTIF($G42:$P42,"Medium")*$C$13+COUNTIF($G42:$P42,"Low")*$C$14)/10>=2,"Y","N") -> N | R42: 해당 계정과목에 대한 집계사항으로 추정이나 판단이 개입되지 않으며, 회계처리등의 복잡성도 낮음에 따라 질적으로 유의적이지 않을 것으로 판단함. | S42: =IF(COUNTIF($F42:$Q42,"Y")>0,"Y","N") -> N
B43: 25. 수익 | G43: Low | H43: Low | I43: Low | J43: Low | K43: Low | L43: Low | M43: Low | N43: Low | O43: Low | P43: Low | Q43: =IF(SUM(COUNTIF($G43:$P43,"High")*$C$12+COUNTIF($G43:$P43,"Medium")*$C$13+COUNTIF($G43:$P43,"Low")*$C$14)/10>=2,"Y","N") -> N | R43: 해당 계정과목에 대한 집계사항으로 추정이나 판단이 개입되지 않으며, 회계처리등의 복잡성도 낮음에 따라 질적으로 유의적이지 않을 것으로 판단함. | S43: =IF(COUNTIF($F43:$Q43,"Y")>0,"Y","N") -> N
B44: 26. 판매비및관리비 | G44: Low | H44: Low | I44: Low | J44: Low | K44: Low | L44: Low | M44: Low | N44: Low | O44: Low | P44: Low | Q44: =IF(SUM(COUNTIF($G44:$P44,"High")*$C$12+COUNTIF($G44:$P44,"Medium")*$C$13+COUNTIF($G44:$P44,"Low")*$C$14)/10>=2,"Y","N") -> N | R44: 해당 계정과목에 대한 집계사항으로 추정이나 판단이 개입되지 않으며, 회계처리등의 복잡성도 낮음에 따라 질적으로 유의적이지 않을 것으로 판단함. | S44: =IF(COUNTIF($F44:$Q44,"Y")>0,"Y","N") -> N
B45: 27. 금융이익 및 금융원가 | G45: Low | H45: Low | I45: Low | J45: Low | K45: Low | L45: Low | M45: Low | N45: Low | O45: Low | P45: Low | Q45: =IF(SUM(COUNTIF($G45:$P45,"High")*$C$12+COUNTIF($G45:$P45,"Medium")*$C$13+COUNTIF($G45:$P45,"Low")*$C$14)/10>=2,"Y","N") -> N | R45: 해당 계정과목에 대한 집계사항으로 추정이나 판단이 개입되지 않으며, 회계처리등의 복잡성도 낮음에 따라 질적으로 유의적이지 않을 것으로 판단함. | S45: =IF(COUNTIF($F45:$Q45,"Y")>0,"Y","N") -> N
...

Sheet 2.4 유의한 현금흐름 관련항목 
B2: 유의한 계정과목 및 공시(영업활동현금흐름)
B4: 1. 일반사항
B5: - 이 Spreadsheet는 회사의 재무제표상 계정과목에 대한 질적 중요성을 측정하는데 그 목적이 있음
B7: 2. 질적중요성의 판단
B8: - 양적 기준 검토 결과 "N"라고 파악된 계정과목 및 주석정보에 대하여 2차적으로 질적중요성 검토를 수행함
B9: - 계정과목 및 주석사항에 대하여 10가지 질적 요소에 대한 평가를 통해 Risk Rating을 실시
B10: - Risk Rating은 단순평균방식으로 계산되며, Rating결과가 2(Medium)을 초과할 경우 질적으로 중요하다고 판단함
B12: High | C12: 3
B13: Medium | C13: 2
B14: Low | C14: 1
D16: (단위 : 원) | F16: 계정과목 내 개별 거래의 복잡성, 동질성 | G16: 추정이나 판단이 개입되는 회계처리 및 평가 | H16: 회계처리 및 보고의 복잡성 | I16: 우발채무의 발생가능성 | J16: 특수관계자와 유의적 거래의 존재 여부 | K16: 계정과목 성격의 변화 및 당기 금액 변화 정도 | L16: 비 경상적인 거래 | M16: 관련 회계처리 기준의 변경 | N16: 법규 및 감독당국의 강조 사항 | O16: 주요한 외부환경의 변화가 존재하는 계정 | T16: 매출관리 | U16: 경비관리 | V16: 자금관리 | W16: 재무결산및보고 | X16: 급여및인사관리 | Y16: 고정자산관리
A17: 0.55069444 | B17: 계정과목 | C17: ='2.1 유의한 계정과목(BS)'!C17 -> FY2022 | D17: ='2.1 유의한 계정과목(BS)'!D17 -> FY2021 | E17: 양적 유의여부(*) | F17: 질적기준 | P17: 질적 유의여부 | Q17: 질적판단 근거 | R17: 유의성 결론
Q18: 현금흐름표의 경우 간접법형식으로 작성되며, 재무제표 확정이후 일부조정후 산출됨. 따라서 항목별로 추정이나 판단이 개입되지 않음에 따라 질적으로 중요하지 않다고 판단됨. 단, 현금흐름표의 전반적 산출 통제 및 영업현금관련 항목에 대해서는 재무결산 프로세스에서 검토함.
B19: I. 영업활동으로 인한 현금흐름 | C19: =SUM(C20,C48:C51) -> 5590104148 | D19: =SUM(D20,D48:D51) -> 3922676504
B20: 1. 영업활동에서 창출된 현금흐름 | C20: =SUM(C21,C22,C40) -> 5731836143 | D20: =SUM(D21,D22,D40) -> 3965445748
B21: (1) 당기순이익 | C21: 4414710903 | D21: 3524139886
B22: (2) 조정 | C22: =SUM(C23:C39) -> 877249782 | D22: =SUM(D23:D39) -> 475991567
B23: 대손상각비(충당금환입) | C23: -68638747 | D23: 26252791 | F23: Low | G23: Low | H23: Medium | I23: Low | J23: Low | K23: Low | L23: Low | M23: Low | N23: Medium | O23: Medium | P23: =IF(SUM(COUNTIF($F23:$O23,"High")*$C$12+COUNTIF($F23:$O23,"Medium")*$C$13+COUNTIF($F23:$O23,"Low")*$C$14)/10>=2,"Y","N") -> N | R23: =IF(COUNTIF($E23:$P23,"Y")>0,"Y","N") -> N | W23: O
B24: 감가상각비 | C24: 465332658 | D24: 155396992 | F24: Low | G24: Low | H24: Medium | I24: Low | J24: Low | K24: Low | L24: Low | M24: Low | N24: Medium | O24: Medium | P24: =IF(SUM(COUNTIF($F24:$O24,"High")*$C$12+COUNTIF($F24:$O24,"Medium")*$C$13+COUNTIF($F24:$O24,"Low")*$C$14)/10>=2,"Y","N") -> N | R24: =IF(COUNTIF($E24:$P24,"Y")>0,"Y","N") -> N | W24: O
B25: 사용권자산상각비 | C25: 4880184 | D25: 4880184 | F25: Low | G25: Low | H25: Medium | I25: Low | J25: Low | K25: Low | L25: Low | M25: Low | N25: Medium | O25: Medium | P25: =IF(SUM(COUNTIF($F25:$O25,"High")*$C$12+COUNTIF($F25:$O25,"Medium")*$C$13+COUNTIF($F25:$O25,"Low")*$C$14)/10>=2,"Y","N") -> N | R25: =IF(COUNTIF($E25:$P25,"Y")>0,"Y","N") -> N | W25: O
B26: 무형자산상각비 | C26: 4795132 | D26: 4911317 | F26: Low | G26: Low | H26: Medium | I26: Low | J26: Low | K26: Low | L26: Low | M26: Low | N26: Medium | O26: Medium | P26: =IF(SUM(COUNTIF($F26:$O26,"High")*$C$12+COUNTIF($F26:$O26,"Medium")*$C$13+COUNTIF($F26:$O26,"Low")*$C$14)/10>=2,"Y","N") -> N | R26: =IF(COUNTIF($E26:$P26,"Y")>0,"Y","N") -> N | W26: O
B27: 장기종업원급여 | C27: -970091 | D27: 50900155 | F27: Low | G27: Low | H27: Medium | I27: Low | J27: Low | K27: Low | L27: Low | M27: Low | N27: Medium | O27: Medium | P27: =IF(SUM(COUNTIF($F27:$O27,"High")*$C$12+COUNTIF($F27:$O27,"Medium")*$C$13+COUNTIF($F27:$O27,"Low")*$C$14)/10>=2,"Y","N") -> N | R27: =IF(COUNTIF($E27:$P27,"Y")>0,"Y","N") -> N | W27: O
B28: 이자비용 | C28: 132625520 | D28: 95695074 | F28: Low | G28: Low | H28: Medium | I28: Low | J28: Low | K28: Low | L28: Low | M28: Low | N28: Medium | O28: Medium | P28: =IF(SUM(COUNTIF($F28:$O28,"High")*$C$12+COUNTIF($F28:$O28,"Medium")*$C$13+COUNTIF($F28:$O28,"Low")*$C$14)/10>=2,"Y","N") -> N | R28: =IF(COUNTIF($E28:$P28,"Y")>0,"Y","N") -> N | W28: O
B29: 외화환산손실 | C29: 35991165 | D29: 6242932 | F29: Low | G29: Low | H29: Medium | I29: Low | J29: Low | K29: Low | L29: Low | M29: Low | N29: Medium | O29: Medium | P29: =IF(SUM(COUNTIF($F29:$O29,"High")*$C$12+COUNTIF($F29:$O29,"Medium")*$C$13+COUNTIF($F29:$O29,"Low")*$C$14)/10>=2,"Y","N") -> N | R29: =IF(COUNTIF($E29:$P29,"Y")>0,"Y","N") -> N | W29: O
B30: 당기손익공정가치측정금융자산평가손실 | C30: 235148010 | D30: 112126660 | F30: Low | G30: Low | H30: Medium | I30: Low | J30: Low | K30: Low | L30: Low | M30: Low | N30: Medium | O30: Medium | P30: =IF(SUM(COUNTIF($F30:$O30,"High")*$C$12+COUNTIF($F30:$O30,"Medium")*$C$13+COUNTIF($F30:$O30,"Low")*$C$14)/10>=2,"Y","N") -> N | R30: =IF(COUNTIF($E30:$P30,"Y")>0,"Y","N") -> N | W30: O
B31: 기타포괄손익공정가치측정금융자산처분손실 | C31: 13410617 | D31: 0 | F31: Low | G31: Low | H31: Medium | I31: Low | J31: Low | K31: Low | L31: Low | M31: Low | N31: Medium | O31: Medium | P31: =IF(SUM(COUNTIF($F31:$O31,"High")*$C$12+COUNTIF($F31:$O31,"Medium")*$C$13+COUNTIF($F31:$O31,"Low")*$C$14)/10>=2,"Y","N") -> N | R31: =IF(COUNTIF($E31:$P31,"Y")>0,"Y","N") -> N | W31: O
B32: 잡손실 | C32: 1000 | D32: 8325 | F32: Low | G32: Low | H32: Medium | I32: Low | J32: Low | K32: Low | L32: Low | M32: Low | N32: Medium | O32: Medium | P32: =IF(SUM(COUNTIF($F32:$O32,"High")*$C$12+COUNTIF($F32:$O32,"Medium")*$C$13+COUNTIF($F32:$O32,"Low")*$C$14)/10>=2,"Y","N") -> N | R32: =IF(COUNTIF($E32:$P32,"Y")>0,"Y","N") -> N | W32: O
B33: 법인세비용 | C33: 404133090 | D33: 268553004 | F33: Low | G33: Low | H33: Medium | I33: Low | J33: Low | K33: Low | L33: Low | M33: Low | N33: Medium | O33: Medium | P33: =IF(SUM(COUNTIF($F33:$O33,"High")*$C$12+COUNTIF($F33:$O33,"Medium")*$C$13+COUNTIF($F33:$O33,"Low")*$C$14)/10>=2,"Y","N") -> N | R33: =IF(COUNTIF($E33:$P33,"Y")>0,"Y","N") -> N | W33: O
B34: 이자수익 | C34: -283791169 | D34: -75560395 | F34: Low | G34: Low | H34: Medium | I34: Low | J34: Low | K34: Low | L34: Low | M34: Low | N34: Medium | O34: Medium | P34: =IF(SUM(COUNTIF($F34:$O34,"High")*$C$12+COUNTIF($F34:$O34,"Medium")*$C$13+COUNTIF($F34:$O34,"Low")*$C$14)/10>=2,"Y","N") -> N | R34: =IF(COUNTIF($E34:$P34,"Y")>0,"Y","N") -> N | W34: O
... B39: 당기손익공정가치측정금융자산처분이익 | C39: -6531110 | D39: -54452389 | F39: Low | G39: Low | H39: Medium | I39: Low | J39: Low | K39: Low | L39: Low | M39: Low | N39: Medium | O39: Medium | P39: =IF(SUM(COUNTIF($F39:$O39,"High")*$C$12+COUNTIF($F39:$O39,"Medium")*$C$13+COUNTIF($F39:$O39,"Low")*$C$14)/10>=2,"Y","N") -> N | R39: =IF(COUNTIF($E39:$P39,"Y")>0,"Y","N") -> N | W39: O
B40: (3) 운전자본 변동 | C40: =SUM(C41:C47) -> 439875458 | D40: =SUM(D41:D47) -> -34685705
B41: 매출채권및기타채권 | C41: 17554644 | D41: -337083972 | F41: Low | G41: Low | H41: Medium | I41: Low | J41: Low | K41: Low | L41: Low | M41: Low | N41: Medium | O41: Medium | P41: =IF(SUM(COUNTIF($F41:$O41,"High")*$C$12+COUNTIF($F41:$O41,"Medium")*$C$13+COUNTIF($F41:$O41,"Low")*$C$14)/10>=2,"Y","N") -> N | R41: =IF(COUNTIF($E41:$P41,"Y")>0,"Y","N") -> N | W41: O
B42: 계약자산 | C42: 1503230 | D42: 46346321 | F42: Low | G42: Low | H42: Medium | I42: Low | J42: Low | K42: Low | L42: Low | M42: Low | N42: Medium | O42: Medium | P42: =IF(SUM(COUNTIF($F42:$O42,"High")*$C$12+COUNTIF($F42:$O42,"Medium")*$C$13+COUNTIF($F42:$O42,"Low")*$C$14)/10>=2,"Y","N") -> N | R42: =IF(COUNTIF($E42:$P42,"Y")>0,"Y","N") -> N | W42: O
B43: 기타유동자산 | C43: 3264166 | D43: 11646260 | F43: Low | G43: Low | H43: Medium | I43: Low | J43: Low | K43: Low | L43: Low | M43: Low | N43: Medium | O43: Medium | P43: =IF(SUM(COUNTIF($F43:$O43,"High")*$C$12+COUNTIF($F43:$O43,"Medium")*$C$13+COUNTIF($F43:$O43,"Low")*$C$14)/10>=2,"Y","N") -> N | R43: =IF(COUNTIF($E43:$P43,"Y")>0,"Y","N") -> N | W43: O
B44: 매입채무및기타채무 | C44: 419570444 | D44: -196045426 | F44: Low | G44: Low | H44: Medium | I44: Low | J44: Low | K44: Low | L44: Low | M44: Low | N44: Medium | O44: Medium | P44: =IF(SUM(COUNTIF($F44:$O44,"High")*$C$12+COUNTIF($F44:$O44,"Medium")*$C$13+COUNTIF($F44:$O44,"Low")*$C$14)/10>=2,"Y","N") -> N | R44: =IF(COUNTIF($E44:$P44,"Y")>0,"Y","N") -> N | W44: O
B45: 계약부채 | C45: -133233015 | D45: 480035701 | F45: Low | G45: Low | H45: Medium | I45: Low | J45: Low | K45: Low | L45: Low | M45: Low | N45: Medium | O45: Medium | P45: =IF(SUM(COUNTIF($F45:$O45,"High")*$C$12+COUNTIF($F45:$O45,"Medium")*$C$13+COUNTIF($F45:$O45,"Low")*$C$14)/10>=2,"Y","N") -> N | R45: =IF(COUNTIF($E45:$P45,"Y")>0,"Y","N") -> N | W45: O
B46: 기타유동부채 | C46: 163347463 | D46: 337247 | F46: Low | G46: Low | H46: Medium | I46: Low | J46: Low | K46: Low | L46: Low | M46: Low | N46: Medium | O46: Medium | P46: =IF(SUM(COUNTIF($F46:$O46,"High")*$C$12+COUNTIF($F46:$O46,"Medium")*$C$13+COUNTIF($F46:$O46,"Low")*$C$14)/10>=2,"Y","N") -> N | R46: =IF(COUNTIF($E46:$P46,"Y")>0,"Y","N") -> N | W46: O
B47: 충당부채 | C47: -32131474 | D47: -39921836 | F47: Low | G47: Low | H47: Medium | I47: Low | J47: Low | K47: Low | L47: Low | M47: Low | N47: Medium | O47: Medium | P47: =IF(SUM(COUNTIF($F47:$O47,"High")*$C$12+COUNTIF($F47:$O47,"Medium")*$C$13+COUNTIF($F47:$O47,"Low")*$C$14)/10>=2,"Y","N") -> N | R47: =IF(COUNTIF($E47:$P47,"Y")>0,"Y","N") -> N | W47: O
B48: 2. 이자의 수취 | C48: 227691408 | D48: 76137268 | F48: Low | G48: Low | H48: Medium | I48: Low | J48: Low | K48: Low | L48: Low | M48: Low | N48: Medium | O48: Medium | P48: =IF(SUM(COUNTIF($F48:$O48,"High")*$C$12+COUNTIF($F48:$O48,"Medium")*$C$13+COUNTIF($F48:$O48,"Low")*$C$14)/10>=2,"Y","N") -> N | R48: =IF(COUNTIF($E48:$P48,"Y")>0,"Y","N") -> N | W48: O
B49: 3. 이자의 지급 | C49: -130019592 | D49: 0 | F49: Low | G49: Low | H49: Medium | I49: Low | J49: Low | K49: Low | L49: Low | M49: Low | N49: Medium | O49: Medium | P49: =IF(SUM(COUNTIF($F49:$O49,"High")*$C$12+COUNTIF($F49:$O49,"Medium")*$C$13+COUNTIF($F49:$O49,"Low")*$C$14)/10>=2,"Y","N") -> N | R49: =IF(COUNTIF($E49:$P49,"Y")>0,"Y","N") -> N | W49: O
...

Sheet 3. GITC Scoping_
B2: ■ GITC Scoping 검토 - RoMM에 식별된 IT Element
B4: Control | G4: IUC | J4: GITC Test
B5: 통제활동번호 | C5: 통제활동설명 | D5: Key Control(Yes/No) | E5: Automated 여부 (A(Input,Processing,Output),A(Calculation),A(Application Access)/M) | F5: 관련 시스템 | G5: IPE(or IUC) 문서명 | H5: 관련 시스템 | I5: REF(EX: IUC 1) | J5: GITC 대상 여부 (Yes / No/ N/A) | K5: GITC 대상이 아닌 것으로 분류한 경우 Rationale(NO 로 기재한 부분 사유 기재)
B7: EL-010-10-10 | C7: 이사회 및 경영진이 추구하는 윤리경영에 대한 준수사항은 회사의 규정 및 정책에 명문화 되어 있다. | D7: Yes | E7: M | F7: N/A | G7: N/A | H7: N/A | J7: N/A | K7: 시스템관련 통제가 아님에 따라 대상에 해당하지 않음
B8: EL-010-20-10 | C8: 이사회 및 경영진은 도덕성과 윤리적 가치를 다양한 형태로 모든 임직원을 포함한 외부 이해관계자에게 지속적으로 강조하고 있다. | D8: Yes | E8: M | F8: N/A | G8: N/A | H8: N/A | J8: N/A | K8: 시스템관련 통제가 아님에 따라 대상에 해당하지 않음
B9: EL-010-30-10 | C9: 임직원 및 외부 이해관계자의 윤리규범 준수를 위해 윤리경영 준수에 대한 평가가 실시되고 있다. | D9: Yes | E9: M | F9: N/A | G9: N/A | H9: N/A | J9: N/A | K9: 시스템관련 통제가 아님에 따라 대상에 해당하지 않음
B10: EL-010-40-10 | C10: 윤리 위반사항의 식별, 조사, 보고 및 조치결과(대응방안)의 공표 등 일관된 절차에 의해 업무가 처리되도록 문서화하고 운영한다. | D10: Yes | E10: M | F10: N/A | G10: N/A | H10: N/A | J10: N/A | K10: 시스템관련 통제가 아님에 따라 대상에 해당하지 않음
B11: EL-010-50-10 | C11: 내부회계관리제도와 관련한 이사회 및 감사의 역할과 책임을 명확히 정의하고 적격성과 독립성을 주기적으로 검토한다. | D11: Yes | E11: M | F11: N/A | G11: N/A | H11: N/A | J11: N/A | K11: 시스템관련 통제가 아님에 따라 대상에 해당하지 않음
B12: EL-010-60-10 | C12: 감사의 선임 기준을 명확히 하고 주기적으로 평가하여 감사의 기능이 효과적으로 운영된다. | D12: Yes | E12: M | F12: N/A | G12: N/A | H12: N/A | J12: N/A | K12: 시스템관련 통제가 아님에 따라 대상에 해당하지 않음
B13: EL-010-70-10 | C13: 이사회 및 감사에 의해 재무보고 및 내부회계관리제도 활동이 감독된다. | D13: Yes | E13: M | F13: N/A | G13: N/A | H13: N/A | J13: N/A | K13: 시스템관련 통제가 아님에 따라 대상에 해당하지 않음
B14: EL-010-80-10 | C14: 내부회계관리 전담조직의 역할·책임이 명확하게 정의되어 내부회계관리제도가 효과적으로 운영되고 있다. | D14: Yes | E14: M | F14: N/A | G14: N/A | H14: N/A | J14: N/A | K14: 시스템관련 통제가 아님에 따라 대상에 해당하지 않음
B15: EL-010-90-10 | C15: 위임전결 규정 등을 통해 내부회계관리제도 운영을 위한 권한 및 책임을 명확하게 정의한다. | D15: Yes | E15: M | F15: N/A | G15: N/A | H15: N/A | J15: N/A | K15: 시스템관련 통제가 아님에 따라 대상에 해당하지 않음
B16: EL-010-100-10 | C16: 내부회계관리제도를 운영하는 주요 임직원의 적격성 기준을 정의한다. | D16: Yes | E16: M | F16: N/A | G16: N/A | H16: N/A | J16: N/A | K16: 시스템관련 통제가 아님에 따라 대상에 해당하지 않음
B17: EL-010-110-10 | C17: 적격성 기준에 부합한 임직원에 의해 내부회계관리제도가 설계 및 운영되는지 평가된다. | D17: Yes | E17: M | F17: N/A | G17: N/A | H17: N/A | J17: N/A | K17: 시스템관련 통제가 아님에 따라 대상에 해당하지 않음
B18: EL-010-120-10 | C18: 내부회계관리제도와 관련한 주요 조직 및 인력의 적격성 유지를 위해 정기 혹은 비정기적으로 교육프로그램이 계획되고 운영된다. | D18: Yes | E18: M | F18: N/A | G18: N/A | H18: N/A | J18: N/A | K18: 시스템관련 통제가 아님에 따라 대상에 해당하지 않음
... B45: SD-010-10-20 | C45: 매출계약은 품의서에 따라 권한있는 승인권자의 검토 및 승인에 따라 체결된다. | D45: Yes | E45: M | F45: N/A | G45: N/A | H45: N/A | J45: N/A | K45: 시스템관련 통제가 아님에 따라 대상에 해당하지 않음
B46: SD-020-10-10 | C46: 매출은 관련 증빙에 따라 권한있는 승인권자의 검토 및 승인절차를 통해 기록된다. | D46: Yes | E46: M | F46: 더존 | G46: N/A | H46: 더존 | J46: YES
B47: SD-020-20-10 | C47: 세금계산서 또는 invoice는 매출내역에 따라 정확하게 집계되어 빠짐없이 발행되어야 한다. | D47: No | E47: M | F47: 더존 | G47: N/A | H47: 더존 | J47: YES
B48: SD-020-20-30 | C48: 유지보수 매출 관련 조정분개는 정확하게 계산되어야 하고, 정확성을 확보할 수 있도록 적절한 검토가 이루어져야 한다. | D48: Yes | E48: M | F48: 더존 | G48: Y | H48: 더존 | J48: YES
B49: SD-030-10-10 | C49: 매출채권은 거래처별, 만기별,신용거래 한도내 거래가 되도록 관리되어야 한다. | D49: Yes | E49: M | F49: N/A | G49: N/A | H49: N/A | J49: N/A | K49: 시스템관련 통제가 아님에 따라 대상에 해당하지 않음
B50: SD-030-20-10 | C50: 미회수채권은 그 발생원인이 규명되어야 하며 주기적인 상위권자 보고를 통하여 관리되어야 한다. | D50: Yes | E50: M | F50: 더존 | G50: N/A | H50: 더존 | J50: YES
B51: SD-030-30-10 | C51: 대손처리는 회수가능여부을 명확히 판단한 후 권한있는 상위권자의 승인을 받아 문서화 후 처리하여야 한다. | D51: No | E51: M | F51: 더존 | G51: N/A | H51: 더존 | J51: YES
B52: SD-030-40-10 | C52: 대손충당금은 정확하게 계산되어야 하고, 정확성을 확보할 수 있도록 적절한 검토가 이루어져야 한다. | D52: Yes | E52: M | F52: 더존 | G52: Y | H52: 더존 | J52: YES
B53: SD-040-10-10 | C53: 고객정보변경요청은 변경요청부서에서 내부승인을 거친후 수정권한자에게 전달하여야 한다. | D53: No | E53: M | F53: 더존 | G53: N/A | H53: 더존 | J53: YES
B54: SD-040-10-20 | C54: 고객파일에 대한 접근은 수정권한이 있는 부서로 한정되어 관리되어야 한다. | D54: Yes | E54: M | F54: 더존 | G54: N/A | H54: 더존 | J54: YES
B55: SD-040-50-20 | C55: 임대매출전표는 권한있는 승인권자의 승인을 득한다. | D55: No | E55: M | F55: 더존 | G55: N/A | H55: 더존 | J55: YES
B56: TR-010-10-10 | C56: 입금내역은 적시에 장부에 반영되어야 한다. | D56: Yes | E56: M | F56: 더존 | G56: N/A | H56: 더존 | J56: YES
B57: TR-010-10-20 | C57: 입금내역은 관련 채권과 적절히 상계되고 검토되어야 한다. | D57: Yes | E57: M | F57: 더존 | G57: N/A | H57: 더존 | J57: YES
B58: TR-010-20-10 | C58: 거래처 계좌마스터는 접근이 제한되어 있으며, 변경사항에 대하여 승인권자의 승인을 득하여야 한다. | D58: Yes | E58: M | F58: 더존 | G58: N/A | H58: 더존 | J58: YES
B59: TR-010-20-20 | C59: 자금의 출금은 사전에 승인된 계좌에 대해서만 이루어져야 한다. | D59: Yes | E59: M | F59: 더존 | G59: N/A | H59: 더존 | J59: YES
B60: TR-010-20-30 | C60: 지급 관련하여 인터넷 뱅킹을 사용할 경우, 모든 거래에 대하여 이중승인을 득한 후 이루어진다. | D60: Yes | E60: M | F60: N/A | G60: N/A | H60: N/A | J60: N/A | K60: 시스템관련 통제가 아님에 따라 대상에 해당하지 않음
B61: TR-010-30-10 | C61: 대금지급 내역은 누락없이 회계전표에 기록되어 총계정원장에 반영되어야 한다. | D61: Yes | E61: M | F61: 더존 | G61: N/A | H61: 더존 | J61: YES
B62: TR-010-40-10 | C62: 일자금수지(매일의 현금시재 포함) 는 검토되며, 전결권자의 승인을 득한다. | D62: Yes | E62: M | F62: 더존 | G62: N/A | H62: 더존 | J62: YES
B63: TR-010-50-10 | C63: 통장실물 및 인감 등 회사자산에 대한 접근통제가 이루어진다. | D63: No | E63: M | F63: N/A | G63: N/A | H63: N/A | J63: N/A | K63: 시스템관련 통제가 아님에 따라 대상에 해당하지 않음
B64: TR-010-50-20 | C64: 소액현금은 관리되고 자금일보와 일치한다. | D64: No | E64: M | F64: 더존 | G64: N/A | H64: 더존 | J64: YES
B65: TR-020-10-10 | C65: 투자자산(금융상품 등)의 취득은 사전에 정해진 자금운용 지침에 따라 이루어지며, 상위권자의 승인을 득한다. | D65: Yes | E65: M | F65: 더존 | G65: N/A | H65: 더존 | J65: YES
B66: TR-020-10-20 | C66: 투자자산(금융상품 등)의 처분과 관련한 회계처리는 적시에 이루어지고 전결권자의 승인을 득한다. | D66: Yes | E66: M | F66: 더존 | G66: N/A | H66: 더존 | J66: YES
B67: TR-020-20-10 | C67: 전결권자는 금융상품 매입금액, 이자율, 만기일, 평가 등의 내역을 확인후 이자수익 전표를 승인한다. | D67: Yes | E67: M | F67: 더존 | G67: Y | H67: 더존 | J67: YES
B68: TR-020-30-10 | C68: 전결권자는 금융상품 관련 평가내역의 적절성을 검토한 후 금융상품 평가관련 전표를 승인한다. | D68: Yes | E68: M | F68: 더존 | G68: Y | H68: 더존 | J68: YES
B69: TR-020-40-10 | C69: 전결권자는 금융상품 관련 주석공시사항을 금융상품약정서 및 장부금액 등과 대사하여 적절한지 확인하고 승인한다. | D69: Yes | E69: M | F69: N/A | G69: N/A | H69: N/A | J69: N/A | K69: 시스템관련 통제가 아님에 따라 대상에 해당하지 않음
...

Sheet 3.1 유의한 업무프로세스 정리
B2: 유의한 업무 프로세스 정리
C4: [내부회계관리제도 평가 및 보고 실무사례 44~46]
C6: 유의한 업무프로세스의 파악
C7: 업무프로세스는 자료 입력, 분류 및 합산, 계산, 거래 업데이트, 파일관리, 거래 생성, 취합 및 보고 등의 일련의 업무과정을 포함하며, 시스템에서 수행되는 마스터파일의 생성, 갱신 등의 활동을 포함한다.
C8: 신뢰할 수 있는 재무제표의 작성 및 공시를 위해서는 재무제표 작성 및 보고절차 뿐만 아니라 장부 상에 기록된 개별 거래들이 발생, 승인, 기록 및 처리되는 전체 과정이 중요하기 때문에 경영진은 내부회계관리제도의
C9: 평가 시 회계나 경리 부서 뿐만 아니라 회계처리의 기초가 되는 정보와 관련된 회사의 유의한 업무프로세스를 고려한다.
C11: 유의한 계정과목 및 주석정보, 그리고 이와 관련된 경영자 주장을 파악한 후 경영진은 해당 계정과목 및 주석정보에 영향을 미치는 주요 거래 유형별 유의한 업무프로세스를 파악한다.
C12: 유의한 업무프로세스 및 그 프로세스 내에서 수행되는 일련의 활동인 하위프로세스는 영위하는 사업의 내용이나 환경 등에 따라 회사마다 다를 수 있다.
C13: 예를 들어, 연구개발비 계정과 관련된 업무프로세스는 제조업(특히 첨단산업)의 경우에는 중요할 수 있으나 금융업을 영위하는 회사에서는 상대적으로 중요하지 않을 수도 있다.
C14: 기말재무제표 작성절차는 내부회계관리제도에서 차지하는 중요성으로 인해 항상 유의한 업무프로세스로 식별되어야 한다.
C16: [별도재무제표: 감사대상]
C18: 업무 프로세스 | D18: =+COUNTA(C22:C54) -> 8
C19: 하위 프로세스 | D19: =+COUNTA(E22:E54) -> 33
C21: Process Code | D21: Process Name | E21: Sub Process Code | F21: Sub Process Name
C22: EL | D22: 전사 | E22: EL-010 | F22: 통제환경
E23: EL-020 | F23: 위험평가
E24: EL-030 | F24: 통제활동
E25: EL-040 | F25: 정보및의사소통
E26: EL-050 | F26: 모니터링
C27: SD | D27: 매출관리 | E27: SD-010 | F27: 주문 및 거래관리
E28: SD-020 | F28: 매출기록 및 청구
E29: SD-030 | F29: 채권관리 및 대손상각
E30: SD-040 | F30: 마스터 데이터 관리
E31: SD-050 | F31: 임대매출 기록
C32: TR | D32: 자금관리 | E32: TR-010 | F32: 입출금관리
E33: TR-020 | F33: 투자자산관리
E34: TR-030 | F34: 차입금 관리
C35: HR | D35: 급여 및 인사관리 | E35: HR-010 | F35: 직원의 채용
E36: HR-020 | F36: 급여 계산 및 지급
E37: HR-030 | F37: 인사기록관리
E38: HR-040 | F38: 직원의 퇴사
C39: FA | D39: 고정자산관리 | E39: FA-010 | F39: 취득 관리
E40: FA-020 | F40: 상각비 관리
E41: FA-030 | F41: 처분 관리
E42: FA-040 | F42: 유지보수 관리
E43: FA-050 | F43: 리스관리
E44: FA-060 | F44: 투자부동산 관리
C45: EX | D45: 경비관리 | E45: EX-010 | F45: 일반비용지출
C46: FR | D46: 재무결산과 보고 | E46: FR-010 | F46: 재무결산과 보고절차의 수립
E47: FR-020 | F47: 회계처리절차 및 계정원장관리
...

Sheet Notes
B2: Notes
B4: Note 1 | C4: 중요성의 결정(Determine Materiality)
C5: 다음 Guidance는 Materiality를 결정하기 위해 선택한 benchmark에 적용할 적절한 비율을 결정하기 위한 참조를 제공한다: • 세전계속사업이익의 5 ~ 10% • 매출액의 0.0 ~ 5 % • 총자산의 1 ~ 2 % • 총자본(혹은 순자산)의 3 % 이하 • 총비용의 3 ~ 5 % • 영업활동으로 인한 현금흐름의 3 ~ 5 %
B8: Note 2 | C8: [내부회계관리제도 평가 및 보고 실무사례: 수행 중요성(Performance Materiality) -문단 40]
C9: 유의한 계정과목 등을 식별하기 위한 양적 요소는 계정과목의 금액을 고려하며, 일반적으로 설계·운영 적용기법에서 제시하는 "중요성" 기준과 “수행 중요성(Performance Materiality)" 기준을 활용한다. 경영진은 내부회계관리제도 평가 과정에서 회사에 존재하는 미비점을 발견하지 못할 가능성에 대비하여 보수적으로 중요성 기준의 50~75%를 적용한 수행 중요성 기준으로 유의한 계정과목을 선정한다. 수행 중요성을 적용함에 따라, 유의한 계정이 추가로 선정되어 회사의 내부회계관리제도 평가가 잘못 수행될 위험을 최소화 할 수 있다.
K11: 위험평가
B12: Note 3 | C12: [내부회계관리제도 평가 및 보고 모범규준: 평가 시 필요한 증거자료 결정 -문단 54 ]
C13: 1. 위험평가시 경영진은 중요한 왜곡표시가 발생하기 쉬운 거래, 계정잔액 또는 기타 정보를 포함하는 재무보고 요소를 고려한다. 재무보고 요소에서 중요한 왜곡표시의 발생가능성은 다음을 고려하여 판단한다.
C14: (1) 회계 처리의 복잡성
C15: (2) 계정과목 등의 금액을 결정하는데 필요한 판단의 정도
C16: (3) 부정 발생의 가능성
C17: (4) 계정과목 등을 구성하는 거래의 성격 또는 규모의 변화 정도
C18: (5) 기술적, 경제적 발전과 같은 환경적 변화에 대한 민감도
C21: 2. Significant Risk에 해당되는지 여부를 확인하기 위해 고려한 사항 : 위 Risk 평가항목 중 High항목이 4개 이상인 경우에는 반드시 Significant Risk로 판단하고, 1개 이하인 경우에만 Low Risk로 판단할 수 있음. 다만, 부정 발생의 가능성이 High인 경우에는 Significant Risk로 반드시 구분함.
C23: 3. Risk를 판단한 전반적인 근거를 기재한다.
C24: 예: Risk을 판단하기 위하여 고려하여야 할 요소를 검토한 결과, 시스템으로 대금청구가 자동으로 이루어지며 미청구 금액에 대하여 적정한 관리자가 검토하고 있으므로 그 금액적 효과도 작을 것으로 판단되어 Low risk로 분류함.
B28: Note 4 | C28: [회계감사기준: 경영진 주장 -문단 A124 ] | K28: 위험평가
C29: A124 감사인이 여러 가지 발생가능한 잠재적인 왜곡표시의 유형들을 고려하기 위해 이용하는 경영진주장은 다음의 세 가지 범주로 분류된다.
C31: (a) 감사대상기간의 거래 및 사건의 유형에 대한 경영진주장
C32: (i) 발생사실 –기록된 거래와 사건은 발생되었고 기업에 귀속됨
C33: (ii) 완전성 – 기록되어야 하는 모든 거래와 사건은 기록되었음
C34: (iii) 정확성 – 기록된 거래와 사건에 관련된 금액 및 기타 데이터는 적합하게
C35: 기록되었음
C36: (iv) 기간귀속 –거래와 사건은 해당 보고기간에 기록되었음
C37: (v) 분류 – 거래와 사건은 적절한 계정으로 기록되었음
C39: (b) 보고기간말 계정잔액에 대한 경영진주장
C40: (i) 실재성 – 자산, 부채 및 주주지분은 실재함
C41: (ii) 권리와 의무 – 기업은 자산에 대한 권리를 보유하거나 통제하고 있으며 부채는
C42: 기업의 의무임
... C55: 공시되어 있음
